Workbook

Sheet Units
A1: Notes
A2: UNITS
A3: Breakeven: US$ per MMBtu at Henry Hub (HH = needed wellhead price - basis), pre-tax, at the discount rate on 'Inputs'. Capacity: Bcf/d. Inventory: locations and 1,000 lateral ft.
A5: WHAT THIS IS
A6: APPROXIMATE - built from company disclosures and BEG tiering; breakevens are pre-tax model results, not a vendor curve. Question: what breakeven price does the extra Haynesville supply in gulf_coast_gas_balance.xlsx 'Key question' imply if only COST limited it?
A7: The curve is a COST curve. It is NOT constrained by rigs, crews, sand, takeaway pipelines, leasing or midstream: with H = years to the Key-question date it assumes the whole developable inventory of a tier could be drilled evenly over those years.
A8: NOT modelled: replacement of the base-production decline (maintenance drilling; the last EIA DPR, May 2024, showed legacy Haynesville gas falling 739 MMcf/d in one month on 15.6 Bcf/d), taxes, hedges, midstream returns, well-to-well variance inside a tier, inventory used since 2012, interference between tiers. The marginal prices are therefore LOWER bounds for a net increase in output.
A10: HOW TO READ THE TABS
A11: Chart / Chart - Marginal price: native Excel charts (no borders); their cells are formulas, so editing 'Inputs' redraws them in Excel. Sources: every opened document with value, unit, as-of, publisher, URL and type; then snippet-only claims (never used) and what was not reachable.
A12: Inputs: yellow cells editable and kept on the next run. Block A assumptions (status SOURCED / ASSUMPTION), block B tiers. To use your own (paid) curve overwrite the 'Breakeven override' and 'Capacity override' columns of block B (and rename/add rows by overwriting the tier counts): override cells win over the model.
A13: Profile: decline shape (stretched exponential fitted to BEG's 5- and 10-year recovery anchors), PV factor and the Tier 1 EUR anchor. Curve: live per-tier breakeven, capacity for H = 1..10 years, sorted curve. Capacity over time: Bcf/d build of a programme (live). Mapping: the Key-question increments and the implied marginal breakeven (live) beside Henry Hub. BEG check: BEG's published tiers and the formula run on BEG's own 2015 inputs. Cross-checks: company figures that were NOT used as inputs.
A15: STATUS COUNTS
... A20: Yellow cells on 'Inputs' only. Set the override columns blank to return to the model. Sheets Curve values / Mapping values / Sensitivity values (inventory haircut x Western productivity; NaN = beyond inventory) are the script's own copy of the same arithmetic (used by the PNG charts); after editing in Excel the live tabs and native charts follow, the values tabs do not.

Sheet Chart
A1: APPROXIMATE - built from company disclosures and BEG tiering; breakevens are pre-tax model results, not a vendor curve. Cost curve only: NOT constrained by rigs, crews or takeaway. Step chart data and the editable horizons are on 'Chart data'.

Sheet Chart - Marginal price
A1: APPROXIMATE - built from company disclosures and BEG tiering; breakevens are pre-tax model results, not a vendor curve. Marginal tier = STEO Haynesville growth + extra supply (Gulf 'Key question'), see 'Mapping'.

Sheet Sources
A1: ID | B1: Type | C1: Item | D1: Value | E1: Unit | F1: As-of | G1: Publisher | H1: Document | I1: URL | J1: Status | K1: Used where
A2: B1 | B2: EUR | C2: Average EUR per 4,800-ft well, Tier 1 / 2 / 3 / 4 / 5 / 6 | D2: 7.9 / 5.9 / 4.5 / 3.3 / 2.4 / 1.4 | E2: Bcf per 4,800-ft well | F2: Dec 2015 (wells to 2012) | G2: Bureau of Economic Geology, UT Austin (Browning, Ikonnikova et al.) | H2: Oil & Gas Journal 7 Dec 2015, 'Study forecasts gradual Haynesville production recovery before final decline', Fig. 7 legend | I2: https://www.beg.utexas.edu/files/content/beg/research/shale/Haynesville%20Shale%20Gas%20Play.pdf | J2: OPENED in GitHub Actions 6 Oct 2026 | K2: Inputs (tier productivity ratios), BEG check
A3: B2 | B3: inventory | C3: Remaining potential wells by tier: partly drilled blocks / undrilled blocks / drilled to 2012 | D3: see 'BEG check' (T1 1,700/2,250/450 ... T6 1,170/5,700/180) | E3: wells (4,800-ft) | F3: 2012 well data | G3: Bureau of Economic Geology | H3: OGJ 7 Dec 2015, Fig. 6 stacked bars | I3: https://www.beg.utexas.edu/files/content/beg/research/shale/Haynesville%20Shale%20Gas%20Play.pdf | J3: OPENED in GitHub Actions 6 Oct 2026; value READ OFF A CHART IMAGE (rendered page, approx. +/-3%) | K3: Inputs (tier inventory)
A4: B3 | B4: breakeven | C4: Breakeven Henry Hub price by tier at 0% / 10% / 20% IRR (2011 $) | D4: see 'BEG check' (10% IRR: T1 3.5, T2 4.4, T3 5.4, T4 6.8, T5 9.0, T6 15.2) | E4: $/MMBtu | F4: 2011 $, 2015 study | G4: Bureau of Economic Geology | H4: OGJ 7 Dec 2015, Fig. 8 | I4: https://www.beg.utexas.edu/files/content/beg/research/shale/Haynesville%20Shale%20Gas%20Play.pdf | J4: OPENED in GitHub Actions 6 Oct 2026; value READ OFF A CHART IMAGE (rendered page, approx. +/-3%) | K4: BEG check (validation of the formula)
A5: B4 | B5: well cost | C5: Drilling cost 12,000-ft TVD $10.5 million (20% tangible), related capex 13%, expense $82,500/well/yr +13% overhead, gathering/compression/treatment $0.49/Mcf, royalty 25%, severance 4% (2 yrs exempt), basis HH -$0.07, tax 40.2% | D5: 10.5 / 13% / 82,500 / 0.49 / 25% / -0.07 | E5: mixed | F5: 2015 study | G5: Bureau of Economic Geology | H5: OGJ 7 Dec 2015, Table 1 | I5: https://www.beg.utexas.edu/files/content/beg/research/shale/Haynesville%20Shale%20Gas%20Play.pdf | J5: OPENED in GitHub Actions 6 Oct 2026 | K5: Inputs (royalty, basis, related capex), BEG check
A6: B5 | B6: inventory | C6: Development ceilings: 80% of partly drilled blocks, 40% of undrilled blocks; 20-yr well life; 4,800-ft normalised lateral | D6: 80% / 40% / 20 / 4,800 | E6: % / years / ft | F6: 2015 study | G6: Bureau of Economic Geology | H6: OGJ 7 Dec 2015, Table 2 and text | I6: https://www.beg.utexas.edu/files/content/beg/research/shale/Haynesville%20Shale%20Gas%20Play.pdf | J6: OPENED in GitHub Actions 6 Oct 2026 | K6: Inputs (developable shares, lateral)
A7: B6 | B7: EUR | C7: Share of EUR recovered in first 5 years: >80% (Tier 1: 78%); nearly depleted by year 10 with >90% produced | D7: >80% (78% T1) / >90% | E7: % of EUR | F7: 2015 study | G7: Bureau of Economic Geology | H7: OGJ 7 Dec 2015, 'Well economics' | I7: https://www.beg.utexas.edu/files/content/beg/research/shale/Haynesville%20Shale%20Gas%20Play.pdf | J7: OPENED in GitHub Actions 6 Oct 2026 | K7: Inputs (decline anchors C(5), C(10)) - anchors chosen inside BEG's bounds = ASSUMPTION
A8: B7 | B8: breakeven | C8: 'A substantial portion of the reservoir has breakeven gas prices of $4-6/MMbtu'; remaining technically recoverable resource 177 Tcf; 2,527 wells to 2012 EUR 10.3 Tcf | D8: 4-6 / 177 / 10.3 | E8: $/MMBtu / Tcf | F8: Dec 2015 | G8: Bureau of Economic Geology | H8: OGJ 7 Dec 2015 (also SNL 23 Dec 2015 summary) | I8: https://www.beg.utexas.edu/files/content/beg/research/shale/Haynesville%20Shale%20Gas%20Play.pdf | J8: OPENED in GitHub Actions 6 Oct 2026 | K8: context (2011-15 costs)
A9: C1 | B9: inventory | C9: Legacy Haynesville + Bossier drilling inventory 30 Jun 2026: 1,705 gross / 816 net locations, average lateral 10,153 ft (Haynesville 881, Bossier 824 gross) | D9: 1,705 / 816 / 10,153 | E9: locations / ft | F9: 30 Jun 2026 | G9: Comstock Resources | H9: Investor Presentation October 2026, slide 13 | I9: https://investors.comstockresources.com/static-files/5a596a22-02f6-4b49-a9cc-93ecfe0179c0 | J9: OPENED in GitHub Actions 6 Oct 2026; value READ OFF A CHART IMAGE (rendered page, approx. +/-3%) | K9: Cross-check table (inside BEG's legacy inventory, not added)
A10: C2 | B10: inventory | C10: Western Haynesville operated drilling locations 30 Jun 2026: 3,277 gross / 2,528 net (Haynesville 1,206, Bossier 2,071 gross), average lateral 8,875 ft; assumes 70-90% WI | D10: 3,277 / 2,528 / 8,875 | E10: locations / ft | F10: 30 Jun 2026 | G10: Comstock Resources | H10: Investor Presentation October 2026, slide 14 | I10: https://investors.comstockresources.com/static-files/5a596a22-02f6-4b49-a9cc-93ecfe0179c0 | J10: OPENED in GitHub Actions 6 Oct 2026; value READ OFF A CHART IMAGE (rendered page, approx. +/-3%) | K10: Inputs (Western Haynesville row)
A11: C3 | B11: well cost | C11: Legacy Haynesville D&C cost, laterals >8,500 ft, Q2 2026: drilling $710 + completion $680 per lateral foot | D11: 1,390 | E11: $ per lateral ft | F11: Q2 2026 | G11: Comstock Resources | H11: Investor Presentation October 2026, slide 21 (bar labels) | I11: https://investors.comstockresources.com/static-files/5a596a22-02f6-4b49-a9cc-93ecfe0179c0 | J11: OPENED in GitHub Actions 6 Oct 2026; value READ OFF A CHART IMAGE (rendered page, approx. +/-3%) | K11: Inputs (Legacy tiers $/ft)
A12: C4 | B12: well cost | C12: Western Haynesville D&C cost Q2 2026: drilling $1,738 + completion $1,609 per lateral foot (Q1 2026: 1,534 + 1,537; 2025 Q2: 1,817 + 1,305) | D12: 3,347 | E12: $ per lateral ft | F12: Q2 2026 | G12: Comstock Resources | H12: Investor Presentation October 2026, slide 22 (bar labels) | I12: https://investors.comstockresources.com/static-files/5a596a22-02f6-4b49-a9cc-93ecfe0179c0 | J12: OPENED in GitHub Actions 6 Oct 2026; value READ OFF A CHART IMAGE (rendered page, approx. +/-3%) | K12: Inputs (Western Haynesville $/ft)
... A28: S2 | B28: breakeven (old) | C28: BTU Analytics (Feb 2016): best Haynesville acreage breakeven $1.50-3.00/MMBtu, plenty of areas above $5; only 20% of sub-$2 locations (177 wells) drilled | D28: 1.5-3.0 / >5 | E28: $/MMBtu | F28: 19 Feb 2016 | G28: NGI Shale Daily (via BEG ext-aff copy) | H28: 'Haynesville An Able Price Competitor With Northeast NatGas in Plenty of Areas' | I28: https://www.beg.utexas.edu/files/content/beg/ext-aff/16-02/Haynesville%20An%20Able%20Price%20Competitor%20With%20Northeast%20NatGas%20in%20'Plenty%20of%20Areas'.pdf | J28: OPENED (2016 costs, stale) | K28: not used

Sheet Inputs
A1: Inputs - yellow cells are editable and survive reruns. APPROXIMATE - built from company disclosures and BEG tiering; breakevens are pre-tax model results, not a vendor curve
A2: Block A: assumptions. Block B: tiers (rows can be overwritten with your own curve: use the two override columns).
A4: Assumption | B4: Value | C4: Unit | D4: Status | E4: Source / note
A5: Discount rate for breakeven (pre-tax NPV = 0) | B5: 0.1 | C5: share | D5: ASSUMPTION | E5: BEG and the EIA study quoted by Evaluate Energy use a 10% IRR hurdle; Expand's own breakeven basis is not stated.
A6: Royalty rate | B6: 0.25 | C6: share of revenue | D6: SOURCED | E6: BEG Table 1 (2015). Current lease royalties are not in the opened company documents.
A7: Basis, Henry Hub to wellhead (negative = wellhead below HH) | B7: -0.07 | C7: $/MMBtu | D7: SOURCED | E7: BEG Table 1 (2015); present-day Gulf Coast basis not sourced. Breakeven is quoted at Henry Hub: HH = needed realised price - basis.
A8: Lease operating cost | B8: 0.25 | C8: $/Mcf | D8: SOURCED | E8: Comstock Q2 2026 release (per Mcfe, ~96% gas).
A9: Gathering & transportation | B9: 0.38 | C9: $/Mcf | D9: SOURCED | E9: Comstock Q2 2026 release (company-owned midstream; third-party rates will differ).
A10: Production & other taxes | B10: 0.06 | C10: $/Mcf | D10: SOURCED | E10: Comstock Q2 2026 release (guidance 2026: 0.10-0.15).
A11: Facilities & other capex as share of D&C | B11: 0.13 | C11: share | D11: ASSUMPTION | E11: BEG Table 1 'related capital expenditures 13%' (2015) applied to today's D&C; Comstock's $/ft is drilling + completion only.
A12: Cumulative share of EUR recovered after 5 years | B12: 0.8 | C12: share | D12: ASSUMPTION | E12: BEG text: 'more than 80%' (Tier 1 78%). Anchor for the decline shape.
A13: Cumulative share of EUR recovered after 10 years | B13: 0.92 | C13: share | D13: ASSUMPTION | E13: BEG text: 'more than 90%'. Anchor for the decline shape.
A14: 12-month cumulative production of a modern Tier 1 well | B14: 0.855 | C14: Bcfe per 1,000 lateral ft | D14: SOURCED | E14: Expand 3Q25 deck slide 12: ~855 Mcfe/ft (2026E, company estimate; Mcfe ~ Mcf, Expand is ~92% gas).
A15: D&C cost per lateral foot, Legacy tiers | B15: 1390 | C15: $/ft | D15: SOURCED | E15: Comstock Oct 2026 deck slide 21, Q2 2026: $710 drilling + $680 completion (laterals >8,500 ft). Expand 2026E ~$1,340 (cross-check).
A16: D&C cost per lateral foot, Western Haynesville | B16: 3347 | C16: $/ft | D16: SOURCED | E16: Comstock Oct 2026 deck slide 22, Q2 2026: $1,738 + $1,609.
... A22: Programme length for the 'Capacity over time' tab | B22: 8 | C22: years | D22: ASSUMPTION | E22: Demonstration only; the curve and mapping use H = years to each Key-question date.
A24: Block B: tiers
A25: Tier / block | B25: Basis | C25: Partly drilled / counted locations | D25: Undrilled locations | E25: Developable share of partly/counted | F25: Developable share of undrilled | G25: Lateral per location (1,000 ft) | H25: Relative productivity vs Tier 1 (EUR per ft) | I25: D&C cost ($ per lateral ft) | J25: Breakeven override ($/MMBtu HH; blank = model) | K25: Capacity override (Bcf/d, all horizons; blank = model) | L25: Source / status
A26: Legacy Tier 1 (BEG) | B26: BEG tier, legacy Haynesville | C26: 1700 | D26: 2250 | E26: =Inputs!$B$18*Inputs!$B$20 | F26: =Inputs!$B$19*Inputs!$B$20 | G26: =Inputs!$B$21 | H26: ='BEG check'!$C$6/'BEG check'!$C$6 | I26: =Inputs!$B$15 | L26: Inventory: BEG Fig. 6 (chart-read, 2012 data, wells drilled since 2012 NOT deducted); productivity: BEG EUR ratio x Expand anchor; cost: Comstock Legacy Q2 2026.
A27: Legacy Tier 2 (BEG) | B27: BEG tier, legacy Haynesville | C27: 1470 | D27: 2000 | E27: =Inputs!$B$18*Inputs!$B$20 | F27: =Inputs!$B$19*Inputs!$B$20 | G27: =Inputs!$B$21 | H27: ='BEG check'!$C$7/'BEG check'!$C$6 | I27: =Inputs!$B$15 | L27: Inventory: BEG Fig. 6 (chart-read, 2012 data, wells drilled since 2012 NOT deducted); productivity: BEG EUR ratio x Expand anchor; cost: Comstock Legacy Q2 2026.
A28: Legacy Tier 3 (BEG) | B28: BEG tier, legacy Haynesville | C28: 2550 | D28: 3200 | E28: =Inputs!$B$18*Inputs!$B$20 | F28: =Inputs!$B$19*Inputs!$B$20 | G28: =Inputs!$B$21 | H28: ='BEG check'!$C$8/'BEG check'!$C$6 | I28: =Inputs!$B$15 | L28: Inventory: BEG Fig. 6 (chart-read, 2012 data, wells drilled since 2012 NOT deducted); productivity: BEG EUR ratio x Expand anchor; cost: Comstock Legacy Q2 2026.
A29: Legacy Tier 4 (BEG) | B29: BEG tier, legacy Haynesville | C29: 2050 | D29: 3250 | E29: =Inputs!$B$18*Inputs!$B$20 | F29: =Inputs!$B$19*Inputs!$B$20 | G29: =Inputs!$B$21 | H29: ='BEG check'!$C$9/'BEG check'!$C$6 | I29: =Inputs!$B$15 | L29: Inventory: BEG Fig. 6 (chart-read, 2012 data, wells drilled since 2012 NOT deducted); productivity: BEG EUR ratio x Expand anchor; cost: Comstock Legacy Q2 2026.
A30: Legacy Tier 5 (BEG) | B30: BEG tier, legacy Haynesville | C30: 1900 | D30: 4500 | E30: =Inputs!$B$18*Inputs!$B$20 | F30: =Inputs!$B$19*Inputs!$B$20 | G30: =Inputs!$B$21 | H30: ='BEG check'!$C$10/'BEG check'!$C$6 | I30: =Inputs!$B$15 | L30: Inventory: BEG Fig. 6 (chart-read, 2012 data, wells drilled since 2012 NOT deducted); productivity: BEG EUR ratio x Expand anchor; cost: Comstock Legacy Q2 2026.
A31: Legacy Tier 6 (BEG) | B31: BEG tier, legacy Haynesville | C31: 1170 | D31: 5700 | E31: =Inputs!$B$18*Inputs!$B$20 | F31: =Inputs!$B$19*Inputs!$B$20 | G31: =Inputs!$B$21 | H31: ='BEG check'!$C$11/'BEG check'!$C$6 | I31: =Inputs!$B$15 | L31: Inventory: BEG Fig. 6 (chart-read, 2012 data, wells drilled since 2012 NOT deducted); productivity: BEG EUR ratio x Expand anchor; cost: Comstock Legacy Q2 2026.
A32: Western Haynesville - Comstock operated | B32: Western Haynesville | C32: 3277 | D32: 0 | E32: 1 | F32: 0 | G32: 8.875 | H32: =Inputs!$B$17 | I32: =Inputs!$B$16 | L32: Inventory: Comstock slide 14 (3,277 gross operated locations, 30 Jun 2026; counted inventory, so shares 1/0); productivity ASSUMED; cost: Comstock slide 22.
A33: Western Haynesville - Expand prospective | B33: Western Haynesville | C33: 200 | D33: 0 | E33: 1 | F33: 0 | G33: 10 | H33: =Inputs!$B$17 | I33: =Inputs!$B$16 | L33: Inventory: Expand 3Q25 slide 13 '>200 locations' (10k-ft normalised, prospective acreage, undelineated); productivity and cost as Comstock Western Haynesville (ASSUMED).

Sheet Profile
A1: Per-well production profile (shared by all tiers): cumulative share of EUR C(n) = 1 - exp(-(n/tau)^beta), fitted to the two BEG recovery anchors on 'Inputs'. Live formulas.
A3: beta = ln( ln(1-C10) / ln(1-C5) ) / ln 2 | B3: =LN(LN(1-Inputs!$B$13)/LN(1-Inputs!$B$12))/LN(2)
A4: tau (years) = 5 / (-ln(1-C5))^(1/beta) | B4: =5/(-LN(1-Inputs!$B$12))^(1/B3)
A5: Year-1 share of EUR f(1) | B5: =C9
A6: PV factor: sum f(n)/(1+d)^(n-0.5) (mid-year discounting, capex at t=0) | B6: =SUMPRODUCT(C9:C28/(1+Inputs!$B$5)^(A9:A28-0.5))
A7: Modern Tier 1 EUR (Bcf per 1,000 lateral ft) = 12-month cumulative / f(1) | B7: =Inputs!$B$14/B5
A8: Year n | B8: Cumulative share C(n) | C8: Annual share f(n)
A9: 1 | B9: =1-EXP(-((A9/$B$4)^$B$3)) | C9: =B9
A10: 2 | B10: =1-EXP(-((A10/$B$4)^$B$3)) | C10: =B10-B9
A11: 3 | B11: =1-EXP(-((A11/$B$4)^$B$3)) | C11: =B11-B10
A12: 4 | B12: =1-EXP(-((A12/$B$4)^$B$3)) | C12: =B12-B11
A13: 5 | B13: =1-EXP(-((A13/$B$4)^$B$3)) | C13: =B13-B12
A14: 6 | B14: =1-EXP(-((A14/$B$4)^$B$3)) | C14: =B14-B13
A15: 7 | B15: =1-EXP(-((A15/$B$4)^$B$3)) | C15: =B15-B14
A16: 8 | B16: =1-EXP(-((A16/$B$4)^$B$3)) | C16: =B16-B15
A17: 9 | B17: =1-EXP(-((A17/$B$4)^$B$3)) | C17: =B17-B16
A18: 10 | B18: =1-EXP(-((A18/$B$4)^$B$3)) | C18: =B18-B17
A19: 11 | B19: =1-EXP(-((A19/$B$4)^$B$3)) | C19: =B19-B18
A20: 12 | B20: =1-EXP(-((A20/$B$4)^$B$3)) | C20: =B20-B19
A21: 13 | B21: =1-EXP(-((A21/$B$4)^$B$3)) | C21: =B21-B20
... A28: 20 | B28: =1-EXP(-((A28/$B$4)^$B$3)) | C28: =B28-B27

Sheet Curve
A1: Curve - live per-tier breakeven and capacity (formulas). APPROXIMATE - built from company disclosures and BEG tiering; breakevens are pre-tax model results, not a vendor curve
A2: Breakeven (HH) = ((LOE + gathering + taxes) + capex per 1,000 ft / PV volume per 1,000 ft) / (1 - royalty) - basis, with capex = $/ft x 1,000 x (1 + other capex) and PV volume = EUR x 1e6 Mcf x PV factor. Capacity(H) = developable lateral x EUR x C(H) / H / 365 (Bcf/d in year H of a programme drilling the inventory evenly over H years).
L3: Capacity by horizon H (years) - Bcf/d
A4: Tier / block | B4: Developable lateral (1,000 ft) | C4: EUR (Bcf per 1,000 ft) | D4: Capex per 1,000 ft ($) | E4: PV volume per 1,000 ft (Mcf) | F4: Breakeven, model ($/MMBtu HH) | G4: Breakeven used | H4: Source of breakeven | I4: Rank | J4: Developable EUR (Tcf) | K4: Developable locations | L4: 1 | M4: 2 | N4: 3 | O4: 4 | P4: 5 | Q4: 6 | R4: 7 | S4: 8 | T4: 9 | U4: 10
A5: =Inputs!A26 | B5: =(Inputs!C26*Inputs!E26+Inputs!D26*Inputs!F26)*Inputs!G26 | C5: =Profile!$B$7*Inputs!H26 | D5: =Inputs!I26*1000*(1+Inputs!$B$11) | E5: =C5*1000000*Profile!$B$6 | F5: =((Inputs!$B$8+Inputs!$B$9+Inputs!$B$10)+D5/E5)/(1-Inputs!$B$6)-Inputs!$B$7 | G5: =IF(ISNUMBER(Inputs!J26),Inputs!J26,F5) | H5: =IF(ISNUMBER(Inputs!J26),"OWNER OVERRIDE","MODEL") | I5: =COUNTIF($G$5:$G$12,"<"&G5)+COUNTIF($G$5:G5,G5) | J5: =B5*C5/1000 | K5: =B5/Inputs!G26 | L5: =IF(ISNUMBER(Inputs!$K26),Inputs!$K26,$B5*$C5*INDEX(Profile!$B$9:$B$28,L$4)/L$4/365) | M5: =IF(ISNUMBER(Inputs!$K26),Inputs!$K26,$B5*$C5*INDEX(Profile!$B$9:$B$28,M$4)/M$4/365) | N5: =IF(ISNUMBER(Inputs!$K26),Inputs!$K26,$B5*$C5*INDEX(Profile!$B$9:$B$28,N$4)/N$4/365) | O5: =IF(ISNUMBER(Inputs!$K26),Inputs!$K26,$B5*$C5*INDEX(Profile!$B$9:$B$28,O$4)/O$4/365) | P5: =IF(ISNUMBER(Inputs!$K26),Inputs!$K26,$B5*$C5*INDEX(Profile!$B$9:$B$28,P$4)/P$4/365) | Q5: =IF(ISNUMBER(Inputs!$K26),Inputs!$K26,$B5*$C5*INDEX(Profile!$B$9:$B$28,Q$4)/Q$4/365) | R5: =IF(ISNUMBER(Inputs!$K26),Inputs!$K26,$B5*$C5*INDEX(Profile!$B$9:$B$28,R$4)/R$4/365) | S5: =IF(ISNUMBER(Inputs!$K26),Inputs!$K26,$B5*$C5*INDEX(Profile!$B$9:$B$28,S$4)/S$4/365) | ... U5: =IF(ISNUMBER(Inputs!$K26),Inputs!$K26,$B5*$C5*INDEX(Profile!$B$9:$B$28,U$4)/U$4/365)
A6: =Inputs!A27 | B6: =(Inputs!C27*Inputs!E27+Inputs!D27*Inputs!F27)*Inputs!G27 | C6: =Profile!$B$7*Inputs!H27 | D6: =Inputs!I27*1000*(1+Inputs!$B$11) | E6: =C6*1000000*Profile!$B$6 | F6: =((Inputs!$B$8+Inputs!$B$9+Inputs!$B$10)+D6/E6)/(1-Inputs!$B$6)-Inputs!$B$7 | G6: =IF(ISNUMBER(Inputs!J27),Inputs!J27,F6) | H6: =IF(ISNUMBER(Inputs!J27),"OWNER OVERRIDE","MODEL") | I6: =COUNTIF($G$5:$G$12,"<"&G6)+COUNTIF($G$5:G6,G6) | J6: =B6*C6/1000 | K6: =B6/Inputs!G27 | L6: =IF(ISNUMBER(Inputs!$K27),Inputs!$K27,$B6*$C6*INDEX(Profile!$B$9:$B$28,L$4)/L$4/365) | M6: =IF(ISNUMBER(Inputs!$K27),Inputs!$K27,$B6*$C6*INDEX(Profile!$B$9:$B$28,M$4)/M$4/365) | N6: =IF(ISNUMBER(Inputs!$K27),Inputs!$K27,$B6*$C6*INDEX(Profile!$B$9:$B$28,N$4)/N$4/365) | O6: =IF(ISNUMBER(Inputs!$K27),Inputs!$K27,$B6*$C6*INDEX(Profile!$B$9:$B$28,O$4)/O$4/365) | P6: =IF(ISNUMBER(Inputs!$K27),Inputs!$K27,$B6*$C6*INDEX(Profile!$B$9:$B$28,P$4)/P$4/365) | Q6: =IF(ISNUMBER(Inputs!$K27),Inputs!$K27,$B6*$C6*INDEX(Profile!$B$9:$B$28,Q$4)/Q$4/365) | R6: =IF(ISNUMBER(Inputs!$K27),Inputs!$K27,$B6*$C6*INDEX(Profile!$B$9:$B$28,R$4)/R$4/365) | S6: =IF(ISNUMBER(Inputs!$K27),Inputs!$K27,$B6*$C6*INDEX(Profile!$B$9:$B$28,S$4)/S$4/365) | ... U6: =IF(ISNUMBER(Inputs!$K27),Inputs!$K27,$B6*$C6*INDEX(Profile!$B$9:$B$28,U$4)/U$4/365)
A7: =Inputs!A28 | B7: =(Inputs!C28*Inputs!E28+Inputs!D28*Inputs!F28)*Inputs!G28 | C7: =Profile!$B$7*Inputs!H28 | D7: =Inputs!I28*1000*(1+Inputs!$B$11) | E7: =C7*1000000*Profile!$B$6 | F7: =((Inputs!$B$8+Inputs!$B$9+Inputs!$B$10)+D7/E7)/(1-Inputs!$B$6)-Inputs!$B$7 | G7: =IF(ISNUMBER(Inputs!J28),Inputs!J28,F7) | H7: =IF(ISNUMBER(Inputs!J28),"OWNER OVERRIDE","MODEL") | I7: =COUNTIF($G$5:$G$12,"<"&G7)+COUNTIF($G$5:G7,G7) | J7: =B7*C7/1000 | K7: =B7/Inputs!G28 | L7: =IF(ISNUMBER(Inputs!$K28),Inputs!$K28,$B7*$C7*INDEX(Profile!$B$9:$B$28,L$4)/L$4/365) | M7: =IF(ISNUMBER(Inputs!$K28),Inputs!$K28,$B7*$C7*INDEX(Profile!$B$9:$B$28,M$4)/M$4/365) | N7: =IF(ISNUMBER(Inputs!$K28),Inputs!$K28,$B7*$C7*INDEX(Profile!$B$9:$B$28,N$4)/N$4/365) | O7: =IF(ISNUMBER(Inputs!$K28),Inputs!$K28,$B7*$C7*INDEX(Profile!$B$9:$B$28,O$4)/O$4/365) | P7: =IF(ISNUMBER(Inputs!$K28),Inputs!$K28,$B7*$C7*INDEX(Profile!$B$9:$B$28,P$4)/P$4/365) | Q7: =IF(ISNUMBER(Inputs!$K28),Inputs!$K28,$B7*$C7*INDEX(Profile!$B$9:$B$28,Q$4)/Q$4/365) | R7: =IF(ISNUMBER(Inputs!$K28),Inputs!$K28,$B7*$C7*INDEX(Profile!$B$9:$B$28,R$4)/R$4/365) | S7: =IF(ISNUMBER(Inputs!$K28),Inputs!$K28,$B7*$C7*INDEX(Profile!$B$9:$B$28,S$4)/S$4/365) | ... U7: =IF(ISNUMBER(Inputs!$K28),Inputs!$K28,$B7*$C7*INDEX(Profile!$B$9:$B$28,U$4)/U$4/365)
A8: =Inputs!A29 | B8: =(Inputs!C29*Inputs!E29+Inputs!D29*Inputs!F29)*Inputs!G29 | C8: =Profile!$B$7*Inputs!H29 | D8: =Inputs!I29*1000*(1+Inputs!$B$11) | E8: =C8*1000000*Profile!$B$6 | F8: =((Inputs!$B$8+Inputs!$B$9+Inputs!$B$10)+D8/E8)/(1-Inputs!$B$6)-Inputs!$B$7 | G8: =IF(ISNUMBER(Inputs!J29),Inputs!J29,F8) | H8: =IF(ISNUMBER(Inputs!J29),"OWNER OVERRIDE","MODEL") | I8: =COUNTIF($G$5:$G$12,"<"&G8)+COUNTIF($G$5:G8,G8) | J8: =B8*C8/1000 | K8: =B8/Inputs!G29 | L8: =IF(ISNUMBER(Inputs!$K29),Inputs!$K29,$B8*$C8*INDEX(Profile!$B$9:$B$28,L$4)/L$4/365) | M8: =IF(ISNUMBER(Inputs!$K29),Inputs!$K29,$B8*$C8*INDEX(Profile!$B$9:$B$28,M$4)/M$4/365) | N8: =IF(ISNUMBER(Inputs!$K29),Inputs!$K29,$B8*$C8*INDEX(Profile!$B$9:$B$28,N$4)/N$4/365) | O8: =IF(ISNUMBER(Inputs!$K29),Inputs!$K29,$B8*$C8*INDEX(Profile!$B$9:$B$28,O$4)/O$4/365) | P8: =IF(ISNUMBER(Inputs!$K29),Inputs!$K29,$B8*$C8*INDEX(Profile!$B$9:$B$28,P$4)/P$4/365) | Q8: =IF(ISNUMBER(Inputs!$K29),Inputs!$K29,$B8*$C8*INDEX(Profile!$B$9:$B$28,Q$4)/Q$4/365) | R8: =IF(ISNUMBER(Inputs!$K29),Inputs!$K29,$B8*$C8*INDEX(Profile!$B$9:$B$28,R$4)/R$4/365) | S8: =IF(ISNUMBER(Inputs!$K29),Inputs!$K29,$B8*$C8*INDEX(Profile!$B$9:$B$28,S$4)/S$4/365) | ... U8: =IF(ISNUMBER(Inputs!$K29),Inputs!$K29,$B8*$C8*INDEX(Profile!$B$9:$B$28,U$4)/U$4/365)
A9: =Inputs!A30 | B9: =(Inputs!C30*Inputs!E30+Inputs!D30*Inputs!F30)*Inputs!G30 | C9: =Profile!$B$7*Inputs!H30 | D9: =Inputs!I30*1000*(1+Inputs!$B$11) | E9: =C9*1000000*Profile!$B$6 | F9: =((Inputs!$B$8+Inputs!$B$9+Inputs!$B$10)+D9/E9)/(1-Inputs!$B$6)-Inputs!$B$7 | G9: =IF(ISNUMBER(Inputs!J30),Inputs!J30,F9) | H9: =IF(ISNUMBER(Inputs!J30),"OWNER OVERRIDE","MODEL") | I9: =COUNTIF($G$5:$G$12,"<"&G9)+COUNTIF($G$5:G9,G9) | J9: =B9*C9/1000 | K9: =B9/Inputs!G30 | L9: =IF(ISNUMBER(Inputs!$K30),Inputs!$K30,$B9*$C9*INDEX(Profile!$B$9:$B$28,L$4)/L$4/365) | M9: =IF(ISNUMBER(Inputs!$K30),Inputs!$K30,$B9*$C9*INDEX(Profile!$B$9:$B$28,M$4)/M$4/365) | N9: =IF(ISNUMBER(Inputs!$K30),Inputs!$K30,$B9*$C9*INDEX(Profile!$B$9:$B$28,N$4)/N$4/365) | O9: =IF(ISNUMBER(Inputs!$K30),Inputs!$K30,$B9*$C9*INDEX(Profile!$B$9:$B$28,O$4)/O$4/365) | P9: =IF(ISNUMBER(Inputs!$K30),Inputs!$K30,$B9*$C9*INDEX(Profile!$B$9:$B$28,P$4)/P$4/365) | Q9: =IF(ISNUMBER(Inputs!$K30),Inputs!$K30,$B9*$C9*INDEX(Profile!$B$9:$B$28,Q$4)/Q$4/365) | R9: =IF(ISNUMBER(Inputs!$K30),Inputs!$K30,$B9*$C9*INDEX(Profile!$B$9:$B$28,R$4)/R$4/365) | S9: =IF(ISNUMBER(Inputs!$K30),Inputs!$K30,$B9*$C9*INDEX(Profile!$B$9:$B$28,S$4)/S$4/365) | ... U9: =IF(ISNUMBER(Inputs!$K30),Inputs!$K30,$B9*$C9*INDEX(Profile!$B$9:$B$28,U$4)/U$4/365)
A10: =Inputs!A31 | B10: =(Inputs!C31*Inputs!E31+Inputs!D31*Inputs!F31)*Inputs!G31 | C10: =Profile!$B$7*Inputs!H31 | D10: =Inputs!I31*1000*(1+Inputs!$B$11) | E10: =C10*1000000*Profile!$B$6 | F10: =((Inputs!$B$8+Inputs!$B$9+Inputs!$B$10)+D10/E10)/(1-Inputs!$B$6)-Inputs!$B$7 | G10: =IF(ISNUMBER(Inputs!J31),Inputs!J31,F10) | H10: =IF(ISNUMBER(Inputs!J31),"OWNER OVERRIDE","MODEL") | I10: =COUNTIF($G$5:$G$12,"<"&G10)+COUNTIF($G$5:G10,G10) | J10: =B10*C10/1000 | K10: =B10/Inputs!G31 | L10: =IF(ISNUMBER(Inputs!$K31),Inputs!$K31,$B10*$C10*INDEX(Profile!$B$9:$B$28,L$4)/L$4/365) | M10: =IF(ISNUMBER(Inputs!$K31),Inputs!$K31,$B10*$C10*INDEX(Profile!$B$9:$B$28,M$4)/M$4/365) | N10: =IF(ISNUMBER(Inputs!$K31),Inputs!$K31,$B10*$C10*INDEX(Profile!$B$9:$B$28,N$4)/N$4/365) | O10: =IF(ISNUMBER(Inputs!$K31),Inputs!$K31,$B10*$C10*INDEX(Profile!$B$9:$B$28,O$4)/O$4/365) | P10: =IF(ISNUMBER(Inputs!$K31),Inputs!$K31,$B10*$C10*INDEX(Profile!$B$9:$B$28,P$4)/P$4/365) | Q10: =IF(ISNUMBER(Inputs!$K31),Inputs!$K31,$B10*$C10*INDEX(Profile!$B$9:$B$28,Q$4)/Q$4/365) | R10: =IF(ISNUMBER(Inputs!$K31),Inputs!$K31,$B10*$C10*INDEX(Profile!$B$9:$B$28,R$4)/R$4/365) | S10: =IF(ISNUMBER(Inputs!$K31),Inputs!$K31,$B10*$C10*INDEX(Profile!$B$9:$B$28,S$4)/S$4/365) | ... U10: =IF(ISNUMBER(Inputs!$K31),Inputs!$K31,$B10*$C10*INDEX(Profile!$B$9:$B$28,U$4)/U$4/365)
A11: =Inputs!A32 | B11: =(Inputs!C32*Inputs!E32+Inputs!D32*Inputs!F32)*Inputs!G32 | C11: =Profile!$B$7*Inputs!H32 | D11: =Inputs!I32*1000*(1+Inputs!$B$11) | E11: =C11*1000000*Profile!$B$6 | F11: =((Inputs!$B$8+Inputs!$B$9+Inputs!$B$10)+D11/E11)/(1-Inputs!$B$6)-Inputs!$B$7 | G11: =IF(ISNUMBER(Inputs!J32),Inputs!J32,F11) | H11: =IF(ISNUMBER(Inputs!J32),"OWNER OVERRIDE","MODEL") | I11: =COUNTIF($G$5:$G$12,"<"&G11)+COUNTIF($G$5:G11,G11) | J11: =B11*C11/1000 | K11: =B11/Inputs!G32 | L11: =IF(ISNUMBER(Inputs!$K32),Inputs!$K32,$B11*$C11*INDEX(Profile!$B$9:$B$28,L$4)/L$4/365) | M11: =IF(ISNUMBER(Inputs!$K32),Inputs!$K32,$B11*$C11*INDEX(Profile!$B$9:$B$28,M$4)/M$4/365) | N11: =IF(ISNUMBER(Inputs!$K32),Inputs!$K32,$B11*$C11*INDEX(Profile!$B$9:$B$28,N$4)/N$4/365) | O11: =IF(ISNUMBER(Inputs!$K32),Inputs!$K32,$B11*$C11*INDEX(Profile!$B$9:$B$28,O$4)/O$4/365) | P11: =IF(ISNUMBER(Inputs!$K32),Inputs!$K32,$B11*$C11*INDEX(Profile!$B$9:$B$28,P$4)/P$4/365) | Q11: =IF(ISNUMBER(Inputs!$K32),Inputs!$K32,$B11*$C11*INDEX(Profile!$B$9:$B$28,Q$4)/Q$4/365) | R11: =IF(ISNUMBER(Inputs!$K32),Inputs!$K32,$B11*$C11*INDEX(Profile!$B$9:$B$28,R$4)/R$4/365) | S11: =IF(ISNUMBER(Inputs!$K32),Inputs!$K32,$B11*$C11*INDEX(Profile!$B$9:$B$28,S$4)/S$4/365) | ... U11: =IF(ISNUMBER(Inputs!$K32),Inputs!$K32,$B11*$C11*INDEX(Profile!$B$9:$B$28,U$4)/U$4/365)
A12: =Inputs!A33 | B12: =(Inputs!C33*Inputs!E33+Inputs!D33*Inputs!F33)*Inputs!G33 | C12: =Profile!$B$7*Inputs!H33 | D12: =Inputs!I33*1000*(1+Inputs!$B$11) | E12: =C12*1000000*Profile!$B$6 | F12: =((Inputs!$B$8+Inputs!$B$9+Inputs!$B$10)+D12/E12)/(1-Inputs!$B$6)-Inputs!$B$7 | G12: =IF(ISNUMBER(Inputs!J33),Inputs!J33,F12) | H12: =IF(ISNUMBER(Inputs!J33),"OWNER OVERRIDE","MODEL") | I12: =COUNTIF($G$5:$G$12,"<"&G12)+COUNTIF($G$5:G12,G12) | J12: =B12*C12/1000 | K12: =B12/Inputs!G33 | L12: =IF(ISNUMBER(Inputs!$K33),Inputs!$K33,$B12*$C12*INDEX(Profile!$B$9:$B$28,L$4)/L$4/365) | M12: =IF(ISNUMBER(Inputs!$K33),Inputs!$K33,$B12*$C12*INDEX(Profile!$B$9:$B$28,M$4)/M$4/365) | N12: =IF(ISNUMBER(Inputs!$K33),Inputs!$K33,$B12*$C12*INDEX(Profile!$B$9:$B$28,N$4)/N$4/365) | O12: =IF(ISNUMBER(Inputs!$K33),Inputs!$K33,$B12*$C12*INDEX(Profile!$B$9:$B$28,O$4)/O$4/365) | P12: =IF(ISNUMBER(Inputs!$K33),Inputs!$K33,$B12*$C12*INDEX(Profile!$B$9:$B$28,P$4)/P$4/365) | Q12: =IF(ISNUMBER(Inputs!$K33),Inputs!$K33,$B12*$C12*INDEX(Profile!$B$9:$B$28,Q$4)/Q$4/365) | R12: =IF(ISNUMBER(Inputs!$K33),Inputs!$K33,$B12*$C12*INDEX(Profile!$B$9:$B$28,R$4)/R$4/365) | S12: =IF(ISNUMBER(Inputs!$K33),Inputs!$K33,$B12*$C12*INDEX(Profile!$B$9:$B$28,S$4)/S$4/365) | ... U12: =IF(ISNUMBER(Inputs!$K33),Inputs!$K33,$B12*$C12*INDEX(Profile!$B$9:$B$28,U$4)/U$4/365)
L13: Cumulative capacity, Bcf/d, by horizon H (years)
A14: Sorted curve (cheapest first) - cumulative capacity by horizon H
A15: Rank | B15: Row in table above | C15: Tier / block | D15: Breakeven used ($/MMBtu HH) | E15: Developable lateral (1,000 ft) | F15: Developable EUR (Tcf) | G15: Cumulative locations | L15: 1 | M15: 2 | N15: 3 | O15: 4 | P15: 5 | Q15: 6 | R15: 7 | S15: 8 | T15: 9 | U15: 10
A16: 1 | B16: =MATCH(A16,$I$5:$I$12,0) | C16: =INDEX($A$5:$A$12,B16) | D16: =INDEX($G$5:$G$12,B16) | E16: =INDEX($B$5:$B$12,B16) | F16: =INDEX($J$5:$J$12,B16) | G16: =INDEX($K$5:$K$12,B16) | L16: =INDEX(L$5:L$12,$B16) | M16: =INDEX(M$5:M$12,$B16) | N16: =INDEX(N$5:N$12,$B16) | O16: =INDEX(O$5:O$12,$B16) | P16: =INDEX(P$5:P$12,$B16) | Q16: =INDEX(Q$5:Q$12,$B16) | R16: =INDEX(R$5:R$12,$B16) | S16: =INDEX(S$5:S$12,$B16) | ... U16: =INDEX(U$5:U$12,$B16)
A17: 2 | B17: =MATCH(A17,$I$5:$I$12,0) | C17: =INDEX($A$5:$A$12,B17) | D17: =INDEX($G$5:$G$12,B17) | E17: =INDEX($B$5:$B$12,B17) | F17: =INDEX($J$5:$J$12,B17) | G17: =G16+INDEX($K$5:$K$12,B17) | L17: =L16+INDEX(L$5:L$12,$B17) | M17: =M16+INDEX(M$5:M$12,$B17) | N17: =N16+INDEX(N$5:N$12,$B17) | O17: =O16+INDEX(O$5:O$12,$B17) | P17: =P16+INDEX(P$5:P$12,$B17) | Q17: =Q16+INDEX(Q$5:Q$12,$B17) | R17: =R16+INDEX(R$5:R$12,$B17) | S17: =S16+INDEX(S$5:S$12,$B17) | ... U17: =U16+INDEX(U$5:U$12,$B17)
A18: 3 | B18: =MATCH(A18,$I$5:$I$12,0) | C18: =INDEX($A$5:$A$12,B18) | D18: =INDEX($G$5:$G$12,B18) | E18: =INDEX($B$5:$B$12,B18) | F18: =INDEX($J$5:$J$12,B18) | G18: =G17+INDEX($K$5:$K$12,B18) | L18: =L17+INDEX(L$5:L$12,$B18) | M18: =M17+INDEX(M$5:M$12,$B18) | N18: =N17+INDEX(N$5:N$12,$B18) | O18: =O17+INDEX(O$5:O$12,$B18) | P18: =P17+INDEX(P$5:P$12,$B18) | Q18: =Q17+INDEX(Q$5:Q$12,$B18) | R18: =R17+INDEX(R$5:R$12,$B18) | S18: =S17+INDEX(S$5:S$12,$B18) | ... U18: =U17+INDEX(U$5:U$12,$B18)
A19: 4 | B19: =MATCH(A19,$I$5:$I$12,0) | C19: =INDEX($A$5:$A$12,B19) | D19: =INDEX($G$5:$G$12,B19) | E19: =INDEX($B$5:$B$12,B19) | F19: =INDEX($J$5:$J$12,B19) | G19: =G18+INDEX($K$5:$K$12,B19) | L19: =L18+INDEX(L$5:L$12,$B19) | M19: =M18+INDEX(M$5:M$12,$B19) | N19: =N18+INDEX(N$5:N$12,$B19) | O19: =O18+INDEX(O$5:O$12,$B19) | P19: =P18+INDEX(P$5:P$12,$B19) | Q19: =Q18+INDEX(Q$5:Q$12,$B19) | R19: =R18+INDEX(R$5:R$12,$B19) | S19: =S18+INDEX(S$5:S$12,$B19) | ... U19: =U18+INDEX(U$5:U$12,$B19)
A20: 5 | B20: =MATCH(A20,$I$5:$I$12,0) | C20: =INDEX($A$5:$A$12,B20) | D20: =INDEX($G$5:$G$12,B20) | E20: =INDEX($B$5:$B$12,B20) | F20: =INDEX($J$5:$J$12,B20) | G20: =G19+INDEX($K$5:$K$12,B20) | L20: =L19+INDEX(L$5:L$12,$B20) | M20: =M19+INDEX(M$5:M$12,$B20) | N20: =N19+INDEX(N$5:N$12,$B20) | O20: =O19+INDEX(O$5:O$12,$B20) | P20: =P19+INDEX(P$5:P$12,$B20) | Q20: =Q19+INDEX(Q$5:Q$12,$B20) | R20: =R19+INDEX(R$5:R$12,$B20) | S20: =S19+INDEX(S$5:S$12,$B20) | ... U20: =U19+INDEX(U$5:U$12,$B20)
A21: 6 | B21: =MATCH(A21,$I$5:$I$12,0) | C21: =INDEX($A$5:$A$12,B21) | D21: =INDEX($G$5:$G$12,B21) | E21: =INDEX($B$5:$B$12,B21) | F21: =INDEX($J$5:$J$12,B21) | G21: =G20+INDEX($K$5:$K$12,B21) | L21: =L20+INDEX(L$5:L$12,$B21) | M21: =M20+INDEX(M$5:M$12,$B21) | N21: =N20+INDEX(N$5:N$12,$B21) | O21: =O20+INDEX(O$5:O$12,$B21) | P21: =P20+INDEX(P$5:P$12,$B21) | Q21: =Q20+INDEX(Q$5:Q$12,$B21) | R21: =R20+INDEX(R$5:R$12,$B21) | S21: =S20+INDEX(S$5:S$12,$B21) | ... U21: =U20+INDEX(U$5:U$12,$B21)
A22: 7 | B22: =MATCH(A22,$I$5:$I$12,0) | C22: =INDEX($A$5:$A$12,B22) | D22: =INDEX($G$5:$G$12,B22) | E22: =INDEX($B$5:$B$12,B22) | F22: =INDEX($J$5:$J$12,B22) | G22: =G21+INDEX($K$5:$K$12,B22) | L22: =L21+INDEX(L$5:L$12,$B22) | M22: =M21+INDEX(M$5:M$12,$B22) | N22: =N21+INDEX(N$5:N$12,$B22) | O22: =O21+INDEX(O$5:O$12,$B22) | P22: =P21+INDEX(P$5:P$12,$B22) | Q22: =Q21+INDEX(Q$5:Q$12,$B22) | R22: =R21+INDEX(R$5:R$12,$B22) | S22: =S21+INDEX(S$5:S$12,$B22) | ... U22: =U21+INDEX(U$5:U$12,$B22)
A23: 8 | B23: =MATCH(A23,$I$5:$I$12,0) | C23: =INDEX($A$5:$A$12,B23) | D23: =INDEX($G$5:$G$12,B23) | E23: =INDEX($B$5:$B$12,B23) | F23: =INDEX($J$5:$J$12,B23) | G23: =G22+INDEX($K$5:$K$12,B23) | L23: =L22+INDEX(L$5:L$12,$B23) | M23: =M22+INDEX(M$5:M$12,$B23) | N23: =N22+INDEX(N$5:N$12,$B23) | O23: =O22+INDEX(O$5:O$12,$B23) | P23: =P22+INDEX(P$5:P$12,$B23) | Q23: =Q22+INDEX(Q$5:Q$12,$B23) | R23: =R22+INDEX(R$5:R$12,$B23) | S23: =S22+INDEX(S$5:S$12,$B23) | ... U23: =U22+INDEX(U$5:U$12,$B23)

Sheet Capacity over time
A1: Capacity over time (live): Bcf/d of a programme that drills each tier's developable inventory evenly over H years (H on 'Inputs'), year n = wells x EUR x [C(n) - C(n - min(n, H))] / 365. Cost-only upper bound on speed: no rig, crew or takeaway limit.
A2: Programme length H (years): | B2: =Inputs!$B$22
A4: Year of programme | B4: =Curve!A5 | C4: =Curve!A6 | D4: =Curve!A7 | E4: =Curve!A8 | F4: =Curve!A9 | G4: =Curve!A10 | H4: =Curve!A11 | I4: =Curve!A12 | J4: Total, Bcf/d
A5: 1 | B5: =IF(ISNUMBER(Inputs!$K26),Inputs!$K26,Curve!$B$5*Curve!$C$5*(INDEX(Profile!$B$9:$B$28,$A5)-IF($A5-MIN($A5,$B$2)=0,0,INDEX(Profile!$B$9:$B$28,$A5-MIN($A5,$B$2))))/$B$2/365) | C5: =IF(ISNUMBER(Inputs!$K27),Inputs!$K27,Curve!$B$6*Curve!$C$6*(INDEX(Profile!$B$9:$B$28,$A5)-IF($A5-MIN($A5,$B$2)=0,0,INDEX(Profile!$B$9:$B$28,$A5-MIN($A5,$B$2))))/$B$2/365) | D5: =IF(ISNUMBER(Inputs!$K28),Inputs!$K28,Curve!$B$7*Curve!$C$7*(INDEX(Profile!$B$9:$B$28,$A5)-IF($A5-MIN($A5,$B$2)=0,0,INDEX(Profile!$B$9:$B$28,$A5-MIN($A5,$B$2))))/$B$2/365) | E5: =IF(ISNUMBER(Inputs!$K29),Inputs!$K29,Curve!$B$8*Curve!$C$8*(INDEX(Profile!$B$9:$B$28,$A5)-IF($A5-MIN($A5,$B$2)=0,0,INDEX(Profile!$B$9:$B$28,$A5-MIN($A5,$B$2))))/$B$2/365) | F5: =IF(ISNUMBER(Inputs!$K30),Inputs!$K30,Curve!$B$9*Curve!$C$9*(INDEX(Profile!$B$9:$B$28,$A5)-IF($A5-MIN($A5,$B$2)=0,0,INDEX(Profile!$B$9:$B$28,$A5-MIN($A5,$B$2))))/$B$2/365) | G5: =IF(ISNUMBER(Inputs!$K31),Inputs!$K31,Curve!$B$10*Curve!$C$10*(INDEX(Profile!$B$9:$B$28,$A5)-IF($A5-MIN($A5,$B$2)=0,0,INDEX(Profile!$B$9:$B$28,$A5-MIN($A5,$B$2))))/$B$2/365) | H5: =IF(ISNUMBER(Inputs!$K32),Inputs!$K32,Curve!$B$11*Curve!$C$11*(INDEX(Profile!$B$9:$B$28,$A5)-IF($A5-MIN($A5,$B$2)=0,0,INDEX(Profile!$B$9:$B$28,$A5-MIN($A5,$B$2))))/$B$2/365) | I5: =IF(ISNUMBER(Inputs!$K33),Inputs!$K33,Curve!$B$12*Curve!$C$12*(INDEX(Profile!$B$9:$B$28,$A5)-IF($A5-MIN($A5,$B$2)=0,0,INDEX(Profile!$B$9:$B$28,$A5-MIN($A5,$B$2))))/$B$2/365) | J5: =SUM(B5:I5)
A6: 2 | B6: =IF(ISNUMBER(Inputs!$K26),Inputs!$K26,Curve!$B$5*Curve!$C$5*(INDEX(Profile!$B$9:$B$28,$A6)-IF($A6-MIN($A6,$B$2)=0,0,INDEX(Profile!$B$9:$B$28,$A6-MIN($A6,$B$2))))/$B$2/365) | C6: =IF(ISNUMBER(Inputs!$K27),Inputs!$K27,Curve!$B$6*Curve!$C$6*(INDEX(Profile!$B$9:$B$28,$A6)-IF($A6-MIN($A6,$B$2)=0,0,INDEX(Profile!$B$9:$B$28,$A6-MIN($A6,$B$2))))/$B$2/365) | D6: =IF(ISNUMBER(Inputs!$K28),Inputs!$K28,Curve!$B$7*Curve!$C$7*(INDEX(Profile!$B$9:$B$28,$A6)-IF($A6-MIN($A6,$B$2)=0,0,INDEX(Profile!$B$9:$B$28,$A6-MIN($A6,$B$2))))/$B$2/365) | E6: =IF(ISNUMBER(Inputs!$K29),Inputs!$K29,Curve!$B$8*Curve!$C$8*(INDEX(Profile!$B$9:$B$28,$A6)-IF($A6-MIN($A6,$B$2)=0,0,INDEX(Profile!$B$9:$B$28,$A6-MIN($A6,$B$2))))/$B$2/365) | F6: =IF(ISNUMBER(Inputs!$K30),Inputs!$K30,Curve!$B$9*Curve!$C$9*(INDEX(Profile!$B$9:$B$28,$A6)-IF($A6-MIN($A6,$B$2)=0,0,INDEX(Profile!$B$9:$B$28,$A6-MIN($A6,$B$2))))/$B$2/365) | G6: =IF(ISNUMBER(Inputs!$K31),Inputs!$K31,Curve!$B$10*Curve!$C$10*(INDEX(Profile!$B$9:$B$28,$A6)-IF($A6-MIN($A6,$B$2)=0,0,INDEX(Profile!$B$9:$B$28,$A6-MIN($A6,$B$2))))/$B$2/365) | H6: =IF(ISNUMBER(Inputs!$K32),Inputs!$K32,Curve!$B$11*Curve!$C$11*(INDEX(Profile!$B$9:$B$28,$A6)-IF($A6-MIN($A6,$B$2)=0,0,INDEX(Profile!$B$9:$B$28,$A6-MIN($A6,$B$2))))/$B$2/365) | I6: =IF(ISNUMBER(Inputs!$K33),Inputs!$K33,Curve!$B$12*Curve!$C$12*(INDEX(Profile!$B$9:$B$28,$A6)-IF($A6-MIN($A6,$B$2)=0,0,INDEX(Profile!$B$9:$B$28,$A6-MIN($A6,$B$2))))/$B$2/365) | J6: =SUM(B6:I6)
A7: 3 | B7: =IF(ISNUMBER(Inputs!$K26),Inputs!$K26,Curve!$B$5*Curve!$C$5*(INDEX(Profile!$B$9:$B$28,$A7)-IF($A7-MIN($A7,$B$2)=0,0,INDEX(Profile!$B$9:$B$28,$A7-MIN($A7,$B$2))))/$B$2/365) | C7: =IF(ISNUMBER(Inputs!$K27),Inputs!$K27,Curve!$B$6*Curve!$C$6*(INDEX(Profile!$B$9:$B$28,$A7)-IF($A7-MIN($A7,$B$2)=0,0,INDEX(Profile!$B$9:$B$28,$A7-MIN($A7,$B$2))))/$B$2/365) | D7: =IF(ISNUMBER(Inputs!$K28),Inputs!$K28,Curve!$B$7*Curve!$C$7*(INDEX(Profile!$B$9:$B$28,$A7)-IF($A7-MIN($A7,$B$2)=0,0,INDEX(Profile!$B$9:$B$28,$A7-MIN($A7,$B$2))))/$B$2/365) | E7: =IF(ISNUMBER(Inputs!$K29),Inputs!$K29,Curve!$B$8*Curve!$C$8*(INDEX(Profile!$B$9:$B$28,$A7)-IF($A7-MIN($A7,$B$2)=0,0,INDEX(Profile!$B$9:$B$28,$A7-MIN($A7,$B$2))))/$B$2/365) | F7: =IF(ISNUMBER(Inputs!$K30),Inputs!$K30,Curve!$B$9*Curve!$C$9*(INDEX(Profile!$B$9:$B$28,$A7)-IF($A7-MIN($A7,$B$2)=0,0,INDEX(Profile!$B$9:$B$28,$A7-MIN($A7,$B$2))))/$B$2/365) | G7: =IF(ISNUMBER(Inputs!$K31),Inputs!$K31,Curve!$B$10*Curve!$C$10*(INDEX(Profile!$B$9:$B$28,$A7)-IF($A7-MIN($A7,$B$2)=0,0,INDEX(Profile!$B$9:$B$28,$A7-MIN($A7,$B$2))))/$B$2/365) | H7: =IF(ISNUMBER(Inputs!$K32),Inputs!$K32,Curve!$B$11*Curve!$C$11*(INDEX(Profile!$B$9:$B$28,$A7)-IF($A7-MIN($A7,$B$2)=0,0,INDEX(Profile!$B$9:$B$28,$A7-MIN($A7,$B$2))))/$B$2/365) | I7: =IF(ISNUMBER(Inputs!$K33),Inputs!$K33,Curve!$B$12*Curve!$C$12*(INDEX(Profile!$B$9:$B$28,$A7)-IF($A7-MIN($A7,$B$2)=0,0,INDEX(Profile!$B$9:$B$28,$A7-MIN($A7,$B$2))))/$B$2/365) | J7: =SUM(B7:I7)
A8: 4 | B8: =IF(ISNUMBER(Inputs!$K26),Inputs!$K26,Curve!$B$5*Curve!$C$5*(INDEX(Profile!$B$9:$B$28,$A8)-IF($A8-MIN($A8,$B$2)=0,0,INDEX(Profile!$B$9:$B$28,$A8-MIN($A8,$B$2))))/$B$2/365) | C8: =IF(ISNUMBER(Inputs!$K27),Inputs!$K27,Curve!$B$6*Curve!$C$6*(INDEX(Profile!$B$9:$B$28,$A8)-IF($A8-MIN($A8,$B$2)=0,0,INDEX(Profile!$B$9:$B$28,$A8-MIN($A8,$B$2))))/$B$2/365) | D8: =IF(ISNUMBER(Inputs!$K28),Inputs!$K28,Curve!$B$7*Curve!$C$7*(INDEX(Profile!$B$9:$B$28,$A8)-IF($A8-MIN($A8,$B$2)=0,0,INDEX(Profile!$B$9:$B$28,$A8-MIN($A8,$B$2))))/$B$2/365) | E8: =IF(ISNUMBER(Inputs!$K29),Inputs!$K29,Curve!$B$8*Curve!$C$8*(INDEX(Profile!$B$9:$B$28,$A8)-IF($A8-MIN($A8,$B$2)=0,0,INDEX(Profile!$B$9:$B$28,$A8-MIN($A8,$B$2))))/$B$2/365) | F8: =IF(ISNUMBER(Inputs!$K30),Inputs!$K30,Curve!$B$9*Curve!$C$9*(INDEX(Profile!$B$9:$B$28,$A8)-IF($A8-MIN($A8,$B$2)=0,0,INDEX(Profile!$B$9:$B$28,$A8-MIN($A8,$B$2))))/$B$2/365) | G8: =IF(ISNUMBER(Inputs!$K31),Inputs!$K31,Curve!$B$10*Curve!$C$10*(INDEX(Profile!$B$9:$B$28,$A8)-IF($A8-MIN($A8,$B$2)=0,0,INDEX(Profile!$B$9:$B$28,$A8-MIN($A8,$B$2))))/$B$2/365) | H8: =IF(ISNUMBER(Inputs!$K32),Inputs!$K32,Curve!$B$11*Curve!$C$11*(INDEX(Profile!$B$9:$B$28,$A8)-IF($A8-MIN($A8,$B$2)=0,0,INDEX(Profile!$B$9:$B$28,$A8-MIN($A8,$B$2))))/$B$2/365) | I8: =IF(ISNUMBER(Inputs!$K33),Inputs!$K33,Curve!$B$12*Curve!$C$12*(INDEX(Profile!$B$9:$B$28,$A8)-IF($A8-MIN($A8,$B$2)=0,0,INDEX(Profile!$B$9:$B$28,$A8-MIN($A8,$B$2))))/$B$2/365) | J8: =SUM(B8:I8)
A9: 5 | B9: =IF(ISNUMBER(Inputs!$K26),Inputs!$K26,Curve!$B$5*Curve!$C$5*(INDEX(Profile!$B$9:$B$28,$A9)-IF($A9-MIN($A9,$B$2)=0,0,INDEX(Profile!$B$9:$B$28,$A9-MIN($A9,$B$2))))/$B$2/365) | C9: =IF(ISNUMBER(Inputs!$K27),Inputs!$K27,Curve!$B$6*Curve!$C$6*(INDEX(Profile!$B$9:$B$28,$A9)-IF($A9-MIN($A9,$B$2)=0,0,INDEX(Profile!$B$9:$B$28,$A9-MIN($A9,$B$2))))/$B$2/365) | D9: =IF(ISNUMBER(Inputs!$K28),Inputs!$K28,Curve!$B$7*Curve!$C$7*(INDEX(Profile!$B$9:$B$28,$A9)-IF($A9-MIN($A9,$B$2)=0,0,INDEX(Profile!$B$9:$B$28,$A9-MIN($A9,$B$2))))/$B$2/365) | E9: =IF(ISNUMBER(Inputs!$K29),Inputs!$K29,Curve!$B$8*Curve!$C$8*(INDEX(Profile!$B$9:$B$28,$A9)-IF($A9-MIN($A9,$B$2)=0,0,INDEX(Profile!$B$9:$B$28,$A9-MIN($A9,$B$2))))/$B$2/365) | F9: =IF(ISNUMBER(Inputs!$K30),Inputs!$K30,Curve!$B$9*Curve!$C$9*(INDEX(Profile!$B$9:$B$28,$A9)-IF($A9-MIN($A9,$B$2)=0,0,INDEX(Profile!$B$9:$B$28,$A9-MIN($A9,$B$2))))/$B$2/365) | G9: =IF(ISNUMBER(Inputs!$K31),Inputs!$K31,Curve!$B$10*Curve!$C$10*(INDEX(Profile!$B$9:$B$28,$A9)-IF($A9-MIN($A9,$B$2)=0,0,INDEX(Profile!$B$9:$B$28,$A9-MIN($A9,$B$2))))/$B$2/365) | H9: =IF(ISNUMBER(Inputs!$K32),Inputs!$K32,Curve!$B$11*Curve!$C$11*(INDEX(Profile!$B$9:$B$28,$A9)-IF($A9-MIN($A9,$B$2)=0,0,INDEX(Profile!$B$9:$B$28,$A9-MIN($A9,$B$2))))/$B$2/365) | I9: =IF(ISNUMBER(Inputs!$K33),Inputs!$K33,Curve!$B$12*Curve!$C$12*(INDEX(Profile!$B$9:$B$28,$A9)-IF($A9-MIN($A9,$B$2)=0,0,INDEX(Profile!$B$9:$B$28,$A9-MIN($A9,$B$2))))/$B$2/365) | J9: =SUM(B9:I9)
A10: 6 | B10: =IF(ISNUMBER(Inputs!$K26),Inputs!$K26,Curve!$B$5*Curve!$C$5*(INDEX(Profile!$B$9:$B$28,$A10)-IF($A10-MIN($A10,$B$2)=0,0,INDEX(Profile!$B$9:$B$28,$A10-MIN($A10,$B$2))))/$B$2/365) | C10: =IF(ISNUMBER(Inputs!$K27),Inputs!$K27,Curve!$B$6*Curve!$C$6*(INDEX(Profile!$B$9:$B$28,$A10)-IF($A10-MIN($A10,$B$2)=0,0,INDEX(Profile!$B$9:$B$28,$A10-MIN($A10,$B$2))))/$B$2/365) | D10: =IF(ISNUMBER(Inputs!$K28),Inputs!$K28,Curve!$B$7*Curve!$C$7*(INDEX(Profile!$B$9:$B$28,$A10)-IF($A10-MIN($A10,$B$2)=0,0,INDEX(Profile!$B$9:$B$28,$A10-MIN($A10,$B$2))))/$B$2/365) | E10: =IF(ISNUMBER(Inputs!$K29),Inputs!$K29,Curve!$B$8*Curve!$C$8*(INDEX(Profile!$B$9:$B$28,$A10)-IF($A10-MIN($A10,$B$2)=0,0,INDEX(Profile!$B$9:$B$28,$A10-MIN($A10,$B$2))))/$B$2/365) | F10: =IF(ISNUMBER(Inputs!$K30),Inputs!$K30,Curve!$B$9*Curve!$C$9*(INDEX(Profile!$B$9:$B$28,$A10)-IF($A10-MIN($A10,$B$2)=0,0,INDEX(Profile!$B$9:$B$28,$A10-MIN($A10,$B$2))))/$B$2/365) | G10: =IF(ISNUMBER(Inputs!$K31),Inputs!$K31,Curve!$B$10*Curve!$C$10*(INDEX(Profile!$B$9:$B$28,$A10)-IF($A10-MIN($A10,$B$2)=0,0,INDEX(Profile!$B$9:$B$28,$A10-MIN($A10,$B$2))))/$B$2/365) | H10: =IF(ISNUMBER(Inputs!$K32),Inputs!$K32,Curve!$B$11*Curve!$C$11*(INDEX(Profile!$B$9:$B$28,$A10)-IF($A10-MIN($A10,$B$2)=0,0,INDEX(Profile!$B$9:$B$28,$A10-MIN($A10,$B$2))))/$B$2/365) | I10: =IF(ISNUMBER(Inputs!$K33),Inputs!$K33,Curve!$B$12*Curve!$C$12*(INDEX(Profile!$B$9:$B$28,$A10)-IF($A10-MIN($A10,$B$2)=0,0,INDEX(Profile!$B$9:$B$28,$A10-MIN($A10,$B$2))))/$B$2/365) | J10: =SUM(B10:I10)
A11: 7 | B11: =IF(ISNUMBER(Inputs!$K26),Inputs!$K26,Curve!$B$5*Curve!$C$5*(INDEX(Profile!$B$9:$B$28,$A11)-IF($A11-MIN($A11,$B$2)=0,0,INDEX(Profile!$B$9:$B$28,$A11-MIN($A11,$B$2))))/$B$2/365) | C11: =IF(ISNUMBER(Inputs!$K27),Inputs!$K27,Curve!$B$6*Curve!$C$6*(INDEX(Profile!$B$9:$B$28,$A11)-IF($A11-MIN($A11,$B$2)=0,0,INDEX(Profile!$B$9:$B$28,$A11-MIN($A11,$B$2))))/$B$2/365) | D11: =IF(ISNUMBER(Inputs!$K28),Inputs!$K28,Curve!$B$7*Curve!$C$7*(INDEX(Profile!$B$9:$B$28,$A11)-IF($A11-MIN($A11,$B$2)=0,0,INDEX(Profile!$B$9:$B$28,$A11-MIN($A11,$B$2))))/$B$2/365) | E11: =IF(ISNUMBER(Inputs!$K29),Inputs!$K29,Curve!$B$8*Curve!$C$8*(INDEX(Profile!$B$9:$B$28,$A11)-IF($A11-MIN($A11,$B$2)=0,0,INDEX(Profile!$B$9:$B$28,$A11-MIN($A11,$B$2))))/$B$2/365) | F11: =IF(ISNUMBER(Inputs!$K30),Inputs!$K30,Curve!$B$9*Curve!$C$9*(INDEX(Profile!$B$9:$B$28,$A11)-IF($A11-MIN($A11,$B$2)=0,0,INDEX(Profile!$B$9:$B$28,$A11-MIN($A11,$B$2))))/$B$2/365) | G11: =IF(ISNUMBER(Inputs!$K31),Inputs!$K31,Curve!$B$10*Curve!$C$10*(INDEX(Profile!$B$9:$B$28,$A11)-IF($A11-MIN($A11,$B$2)=0,0,INDEX(Profile!$B$9:$B$28,$A11-MIN($A11,$B$2))))/$B$2/365) | H11: =IF(ISNUMBER(Inputs!$K32),Inputs!$K32,Curve!$B$11*Curve!$C$11*(INDEX(Profile!$B$9:$B$28,$A11)-IF($A11-MIN($A11,$B$2)=0,0,INDEX(Profile!$B$9:$B$28,$A11-MIN($A11,$B$2))))/$B$2/365) | I11: =IF(ISNUMBER(Inputs!$K33),Inputs!$K33,Curve!$B$12*Curve!$C$12*(INDEX(Profile!$B$9:$B$28,$A11)-IF($A11-MIN($A11,$B$2)=0,0,INDEX(Profile!$B$9:$B$28,$A11-MIN($A11,$B$2))))/$B$2/365) | J11: =SUM(B11:I11)
A12: 8 | B12: =IF(ISNUMBER(Inputs!$K26),Inputs!$K26,Curve!$B$5*Curve!$C$5*(INDEX(Profile!$B$9:$B$28,$A12)-IF($A12-MIN($A12,$B$2)=0,0,INDEX(Profile!$B$9:$B$28,$A12-MIN($A12,$B$2))))/$B$2/365) | C12: =IF(ISNUMBER(Inputs!$K27),Inputs!$K27,Curve!$B$6*Curve!$C$6*(INDEX(Profile!$B$9:$B$28,$A12)-IF($A12-MIN($A12,$B$2)=0,0,INDEX(Profile!$B$9:$B$28,$A12-MIN($A12,$B$2))))/$B$2/365) | D12: =IF(ISNUMBER(Inputs!$K28),Inputs!$K28,Curve!$B$7*Curve!$C$7*(INDEX(Profile!$B$9:$B$28,$A12)-IF($A12-MIN($A12,$B$2)=0,0,INDEX(Profile!$B$9:$B$28,$A12-MIN($A12,$B$2))))/$B$2/365) | E12: =IF(ISNUMBER(Inputs!$K29),Inputs!$K29,Curve!$B$8*Curve!$C$8*(INDEX(Profile!$B$9:$B$28,$A12)-IF($A12-MIN($A12,$B$2)=0,0,INDEX(Profile!$B$9:$B$28,$A12-MIN($A12,$B$2))))/$B$2/365) | F12: =IF(ISNUMBER(Inputs!$K30),Inputs!$K30,Curve!$B$9*Curve!$C$9*(INDEX(Profile!$B$9:$B$28,$A12)-IF($A12-MIN($A12,$B$2)=0,0,INDEX(Profile!$B$9:$B$28,$A12-MIN($A12,$B$2))))/$B$2/365) | G12: =IF(ISNUMBER(Inputs!$K31),Inputs!$K31,Curve!$B$10*Curve!$C$10*(INDEX(Profile!$B$9:$B$28,$A12)-IF($A12-MIN($A12,$B$2)=0,0,INDEX(Profile!$B$9:$B$28,$A12-MIN($A12,$B$2))))/$B$2/365) | H12: =IF(ISNUMBER(Inputs!$K32),Inputs!$K32,Curve!$B$11*Curve!$C$11*(INDEX(Profile!$B$9:$B$28,$A12)-IF($A12-MIN($A12,$B$2)=0,0,INDEX(Profile!$B$9:$B$28,$A12-MIN($A12,$B$2))))/$B$2/365) | I12: =IF(ISNUMBER(Inputs!$K33),Inputs!$K33,Curve!$B$12*Curve!$C$12*(INDEX(Profile!$B$9:$B$28,$A12)-IF($A12-MIN($A12,$B$2)=0,0,INDEX(Profile!$B$9:$B$28,$A12-MIN($A12,$B$2))))/$B$2/365) | J12: =SUM(B12:I12)
A13: 9 | B13: =IF(ISNUMBER(Inputs!$K26),Inputs!$K26,Curve!$B$5*Curve!$C$5*(INDEX(Profile!$B$9:$B$28,$A13)-IF($A13-MIN($A13,$B$2)=0,0,INDEX(Profile!$B$9:$B$28,$A13-MIN($A13,$B$2))))/$B$2/365) | C13: =IF(ISNUMBER(Inputs!$K27),Inputs!$K27,Curve!$B$6*Curve!$C$6*(INDEX(Profile!$B$9:$B$28,$A13)-IF($A13-MIN($A13,$B$2)=0,0,INDEX(Profile!$B$9:$B$28,$A13-MIN($A13,$B$2))))/$B$2/365) | D13: =IF(ISNUMBER(Inputs!$K28),Inputs!$K28,Curve!$B$7*Curve!$C$7*(INDEX(Profile!$B$9:$B$28,$A13)-IF($A13-MIN($A13,$B$2)=0,0,INDEX(Profile!$B$9:$B$28,$A13-MIN($A13,$B$2))))/$B$2/365) | E13: =IF(ISNUMBER(Inputs!$K29),Inputs!$K29,Curve!$B$8*Curve!$C$8*(INDEX(Profile!$B$9:$B$28,$A13)-IF($A13-MIN($A13,$B$2)=0,0,INDEX(Profile!$B$9:$B$28,$A13-MIN($A13,$B$2))))/$B$2/365) | F13: =IF(ISNUMBER(Inputs!$K30),Inputs!$K30,Curve!$B$9*Curve!$C$9*(INDEX(Profile!$B$9:$B$28,$A13)-IF($A13-MIN($A13,$B$2)=0,0,INDEX(Profile!$B$9:$B$28,$A13-MIN($A13,$B$2))))/$B$2/365) | G13: =IF(ISNUMBER(Inputs!$K31),Inputs!$K31,Curve!$B$10*Curve!$C$10*(INDEX(Profile!$B$9:$B$28,$A13)-IF($A13-MIN($A13,$B$2)=0,0,INDEX(Profile!$B$9:$B$28,$A13-MIN($A13,$B$2))))/$B$2/365) | H13: =IF(ISNUMBER(Inputs!$K32),Inputs!$K32,Curve!$B$11*Curve!$C$11*(INDEX(Profile!$B$9:$B$28,$A13)-IF($A13-MIN($A13,$B$2)=0,0,INDEX(Profile!$B$9:$B$28,$A13-MIN($A13,$B$2))))/$B$2/365) | I13: =IF(ISNUMBER(Inputs!$K33),Inputs!$K33,Curve!$B$12*Curve!$C$12*(INDEX(Profile!$B$9:$B$28,$A13)-IF($A13-MIN($A13,$B$2)=0,0,INDEX(Profile!$B$9:$B$28,$A13-MIN($A13,$B$2))))/$B$2/365) | J13: =SUM(B13:I13)
A14: 10 | B14: =IF(ISNUMBER(Inputs!$K26),Inputs!$K26,Curve!$B$5*Curve!$C$5*(INDEX(Profile!$B$9:$B$28,$A14)-IF($A14-MIN($A14,$B$2)=0,0,INDEX(Profile!$B$9:$B$28,$A14-MIN($A14,$B$2))))/$B$2/365) | C14: =IF(ISNUMBER(Inputs!$K27),Inputs!$K27,Curve!$B$6*Curve!$C$6*(INDEX(Profile!$B$9:$B$28,$A14)-IF($A14-MIN($A14,$B$2)=0,0,INDEX(Profile!$B$9:$B$28,$A14-MIN($A14,$B$2))))/$B$2/365) | D14: =IF(ISNUMBER(Inputs!$K28),Inputs!$K28,Curve!$B$7*Curve!$C$7*(INDEX(Profile!$B$9:$B$28,$A14)-IF($A14-MIN($A14,$B$2)=0,0,INDEX(Profile!$B$9:$B$28,$A14-MIN($A14,$B$2))))/$B$2/365) | E14: =IF(ISNUMBER(Inputs!$K29),Inputs!$K29,Curve!$B$8*Curve!$C$8*(INDEX(Profile!$B$9:$B$28,$A14)-IF($A14-MIN($A14,$B$2)=0,0,INDEX(Profile!$B$9:$B$28,$A14-MIN($A14,$B$2))))/$B$2/365) | F14: =IF(ISNUMBER(Inputs!$K30),Inputs!$K30,Curve!$B$9*Curve!$C$9*(INDEX(Profile!$B$9:$B$28,$A14)-IF($A14-MIN($A14,$B$2)=0,0,INDEX(Profile!$B$9:$B$28,$A14-MIN($A14,$B$2))))/$B$2/365) | G14: =IF(ISNUMBER(Inputs!$K31),Inputs!$K31,Curve!$B$10*Curve!$C$10*(INDEX(Profile!$B$9:$B$28,$A14)-IF($A14-MIN($A14,$B$2)=0,0,INDEX(Profile!$B$9:$B$28,$A14-MIN($A14,$B$2))))/$B$2/365) | H14: =IF(ISNUMBER(Inputs!$K32),Inputs!$K32,Curve!$B$11*Curve!$C$11*(INDEX(Profile!$B$9:$B$28,$A14)-IF($A14-MIN($A14,$B$2)=0,0,INDEX(Profile!$B$9:$B$28,$A14-MIN($A14,$B$2))))/$B$2/365) | I14: =IF(ISNUMBER(Inputs!$K33),Inputs!$K33,Curve!$B$12*Curve!$C$12*(INDEX(Profile!$B$9:$B$28,$A14)-IF($A14-MIN($A14,$B$2)=0,0,INDEX(Profile!$B$9:$B$28,$A14-MIN($A14,$B$2))))/$B$2/365) | J14: =SUM(B14:I14)
A15: 11 | B15: =IF(ISNUMBER(Inputs!$K26),Inputs!$K26,Curve!$B$5*Curve!$C$5*(INDEX(Profile!$B$9:$B$28,$A15)-IF($A15-MIN($A15,$B$2)=0,0,INDEX(Profile!$B$9:$B$28,$A15-MIN($A15,$B$2))))/$B$2/365) | C15: =IF(ISNUMBER(Inputs!$K27),Inputs!$K27,Curve!$B$6*Curve!$C$6*(INDEX(Profile!$B$9:$B$28,$A15)-IF($A15-MIN($A15,$B$2)=0,0,INDEX(Profile!$B$9:$B$28,$A15-MIN($A15,$B$2))))/$B$2/365) | D15: =IF(ISNUMBER(Inputs!$K28),Inputs!$K28,Curve!$B$7*Curve!$C$7*(INDEX(Profile!$B$9:$B$28,$A15)-IF($A15-MIN($A15,$B$2)=0,0,INDEX(Profile!$B$9:$B$28,$A15-MIN($A15,$B$2))))/$B$2/365) | E15: =IF(ISNUMBER(Inputs!$K29),Inputs!$K29,Curve!$B$8*Curve!$C$8*(INDEX(Profile!$B$9:$B$28,$A15)-IF($A15-MIN($A15,$B$2)=0,0,INDEX(Profile!$B$9:$B$28,$A15-MIN($A15,$B$2))))/$B$2/365) | F15: =IF(ISNUMBER(Inputs!$K30),Inputs!$K30,Curve!$B$9*Curve!$C$9*(INDEX(Profile!$B$9:$B$28,$A15)-IF($A15-MIN($A15,$B$2)=0,0,INDEX(Profile!$B$9:$B$28,$A15-MIN($A15,$B$2))))/$B$2/365) | G15: =IF(ISNUMBER(Inputs!$K31),Inputs!$K31,Curve!$B$10*Curve!$C$10*(INDEX(Profile!$B$9:$B$28,$A15)-IF($A15-MIN($A15,$B$2)=0,0,INDEX(Profile!$B$9:$B$28,$A15-MIN($A15,$B$2))))/$B$2/365) | H15: =IF(ISNUMBER(Inputs!$K32),Inputs!$K32,Curve!$B$11*Curve!$C$11*(INDEX(Profile!$B$9:$B$28,$A15)-IF($A15-MIN($A15,$B$2)=0,0,INDEX(Profile!$B$9:$B$28,$A15-MIN($A15,$B$2))))/$B$2/365) | I15: =IF(ISNUMBER(Inputs!$K33),Inputs!$K33,Curve!$B$12*Curve!$C$12*(INDEX(Profile!$B$9:$B$28,$A15)-IF($A15-MIN($A15,$B$2)=0,0,INDEX(Profile!$B$9:$B$28,$A15-MIN($A15,$B$2))))/$B$2/365) | J15: =SUM(B15:I15)
A16: 12 | B16: =IF(ISNUMBER(Inputs!$K26),Inputs!$K26,Curve!$B$5*Curve!$C$5*(INDEX(Profile!$B$9:$B$28,$A16)-IF($A16-MIN($A16,$B$2)=0,0,INDEX(Profile!$B$9:$B$28,$A16-MIN($A16,$B$2))))/$B$2/365) | C16: =IF(ISNUMBER(Inputs!$K27),Inputs!$K27,Curve!$B$6*Curve!$C$6*(INDEX(Profile!$B$9:$B$28,$A16)-IF($A16-MIN($A16,$B$2)=0,0,INDEX(Profile!$B$9:$B$28,$A16-MIN($A16,$B$2))))/$B$2/365) | D16: =IF(ISNUMBER(Inputs!$K28),Inputs!$K28,Curve!$B$7*Curve!$C$7*(INDEX(Profile!$B$9:$B$28,$A16)-IF($A16-MIN($A16,$B$2)=0,0,INDEX(Profile!$B$9:$B$28,$A16-MIN($A16,$B$2))))/$B$2/365) | E16: =IF(ISNUMBER(Inputs!$K29),Inputs!$K29,Curve!$B$8*Curve!$C$8*(INDEX(Profile!$B$9:$B$28,$A16)-IF($A16-MIN($A16,$B$2)=0,0,INDEX(Profile!$B$9:$B$28,$A16-MIN($A16,$B$2))))/$B$2/365) | F16: =IF(ISNUMBER(Inputs!$K30),Inputs!$K30,Curve!$B$9*Curve!$C$9*(INDEX(Profile!$B$9:$B$28,$A16)-IF($A16-MIN($A16,$B$2)=0,0,INDEX(Profile!$B$9:$B$28,$A16-MIN($A16,$B$2))))/$B$2/365) | G16: =IF(ISNUMBER(Inputs!$K31),Inputs!$K31,Curve!$B$10*Curve!$C$10*(INDEX(Profile!$B$9:$B$28,$A16)-IF($A16-MIN($A16,$B$2)=0,0,INDEX(Profile!$B$9:$B$28,$A16-MIN($A16,$B$2))))/$B$2/365) | H16: =IF(ISNUMBER(Inputs!$K32),Inputs!$K32,Curve!$B$11*Curve!$C$11*(INDEX(Profile!$B$9:$B$28,$A16)-IF($A16-MIN($A16,$B$2)=0,0,INDEX(Profile!$B$9:$B$28,$A16-MIN($A16,$B$2))))/$B$2/365) | I16: =IF(ISNUMBER(Inputs!$K33),Inputs!$K33,Curve!$B$12*Curve!$C$12*(INDEX(Profile!$B$9:$B$28,$A16)-IF($A16-MIN($A16,$B$2)=0,0,INDEX(Profile!$B$9:$B$28,$A16-MIN($A16,$B$2))))/$B$2/365) | J16: =SUM(B16:I16)
A17: 13 | B17: =IF(ISNUMBER(Inputs!$K26),Inputs!$K26,Curve!$B$5*Curve!$C$5*(INDEX(Profile!$B$9:$B$28,$A17)-IF($A17-MIN($A17,$B$2)=0,0,INDEX(Profile!$B$9:$B$28,$A17-MIN($A17,$B$2))))/$B$2/365) | C17: =IF(ISNUMBER(Inputs!$K27),Inputs!$K27,Curve!$B$6*Curve!$C$6*(INDEX(Profile!$B$9:$B$28,$A17)-IF($A17-MIN($A17,$B$2)=0,0,INDEX(Profile!$B$9:$B$28,$A17-MIN($A17,$B$2))))/$B$2/365) | D17: =IF(ISNUMBER(Inputs!$K28),Inputs!$K28,Curve!$B$7*Curve!$C$7*(INDEX(Profile!$B$9:$B$28,$A17)-IF($A17-MIN($A17,$B$2)=0,0,INDEX(Profile!$B$9:$B$28,$A17-MIN($A17,$B$2))))/$B$2/365) | E17: =IF(ISNUMBER(Inputs!$K29),Inputs!$K29,Curve!$B$8*Curve!$C$8*(INDEX(Profile!$B$9:$B$28,$A17)-IF($A17-MIN($A17,$B$2)=0,0,INDEX(Profile!$B$9:$B$28,$A17-MIN($A17,$B$2))))/$B$2/365) | F17: =IF(ISNUMBER(Inputs!$K30),Inputs!$K30,Curve!$B$9*Curve!$C$9*(INDEX(Profile!$B$9:$B$28,$A17)-IF($A17-MIN($A17,$B$2)=0,0,INDEX(Profile!$B$9:$B$28,$A17-MIN($A17,$B$2))))/$B$2/365) | G17: =IF(ISNUMBER(Inputs!$K31),Inputs!$K31,Curve!$B$10*Curve!$C$10*(INDEX(Profile!$B$9:$B$28,$A17)-IF($A17-MIN($A17,$B$2)=0,0,INDEX(Profile!$B$9:$B$28,$A17-MIN($A17,$B$2))))/$B$2/365) | H17: =IF(ISNUMBER(Inputs!$K32),Inputs!$K32,Curve!$B$11*Curve!$C$11*(INDEX(Profile!$B$9:$B$28,$A17)-IF($A17-MIN($A17,$B$2)=0,0,INDEX(Profile!$B$9:$B$28,$A17-MIN($A17,$B$2))))/$B$2/365) | I17: =IF(ISNUMBER(Inputs!$K33),Inputs!$K33,Curve!$B$12*Curve!$C$12*(INDEX(Profile!$B$9:$B$28,$A17)-IF($A17-MIN($A17,$B$2)=0,0,INDEX(Profile!$B$9:$B$28,$A17-MIN($A17,$B$2))))/$B$2/365) | J17: =SUM(B17:I17)
A18: 14 | B18: =IF(ISNUMBER(Inputs!$K26),Inputs!$K26,Curve!$B$5*Curve!$C$5*(INDEX(Profile!$B$9:$B$28,$A18)-IF($A18-MIN($A18,$B$2)=0,0,INDEX(Profile!$B$9:$B$28,$A18-MIN($A18,$B$2))))/$B$2/365) | C18: =IF(ISNUMBER(Inputs!$K27),Inputs!$K27,Curve!$B$6*Curve!$C$6*(INDEX(Profile!$B$9:$B$28,$A18)-IF($A18-MIN($A18,$B$2)=0,0,INDEX(Profile!$B$9:$B$28,$A18-MIN($A18,$B$2))))/$B$2/365) | D18: =IF(ISNUMBER(Inputs!$K28),Inputs!$K28,Curve!$B$7*Curve!$C$7*(INDEX(Profile!$B$9:$B$28,$A18)-IF($A18-MIN($A18,$B$2)=0,0,INDEX(Profile!$B$9:$B$28,$A18-MIN($A18,$B$2))))/$B$2/365) | E18: =IF(ISNUMBER(Inputs!$K29),Inputs!$K29,Curve!$B$8*Curve!$C$8*(INDEX(Profile!$B$9:$B$28,$A18)-IF($A18-MIN($A18,$B$2)=0,0,INDEX(Profile!$B$9:$B$28,$A18-MIN($A18,$B$2))))/$B$2/365) | F18: =IF(ISNUMBER(Inputs!$K30),Inputs!$K30,Curve!$B$9*Curve!$C$9*(INDEX(Profile!$B$9:$B$28,$A18)-IF($A18-MIN($A18,$B$2)=0,0,INDEX(Profile!$B$9:$B$28,$A18-MIN($A18,$B$2))))/$B$2/365) | G18: =IF(ISNUMBER(Inputs!$K31),Inputs!$K31,Curve!$B$10*Curve!$C$10*(INDEX(Profile!$B$9:$B$28,$A18)-IF($A18-MIN($A18,$B$2)=0,0,INDEX(Profile!$B$9:$B$28,$A18-MIN($A18,$B$2))))/$B$2/365) | H18: =IF(ISNUMBER(Inputs!$K32),Inputs!$K32,Curve!$B$11*Curve!$C$11*(INDEX(Profile!$B$9:$B$28,$A18)-IF($A18-MIN($A18,$B$2)=0,0,INDEX(Profile!$B$9:$B$28,$A18-MIN($A18,$B$2))))/$B$2/365) | I18: =IF(ISNUMBER(Inputs!$K33),Inputs!$K33,Curve!$B$12*Curve!$C$12*(INDEX(Profile!$B$9:$B$28,$A18)-IF($A18-MIN($A18,$B$2)=0,0,INDEX(Profile!$B$9:$B$28,$A18-MIN($A18,$B$2))))/$B$2/365) | J18: =SUM(B18:I18)
A19: 15 | B19: =IF(ISNUMBER(Inputs!$K26),Inputs!$K26,Curve!$B$5*Curve!$C$5*(INDEX(Profile!$B$9:$B$28,$A19)-IF($A19-MIN($A19,$B$2)=0,0,INDEX(Profile!$B$9:$B$28,$A19-MIN($A19,$B$2))))/$B$2/365) | C19: =IF(ISNUMBER(Inputs!$K27),Inputs!$K27,Curve!$B$6*Curve!$C$6*(INDEX(Profile!$B$9:$B$28,$A19)-IF($A19-MIN($A19,$B$2)=0,0,INDEX(Profile!$B$9:$B$28,$A19-MIN($A19,$B$2))))/$B$2/365) | D19: =IF(ISNUMBER(Inputs!$K28),Inputs!$K28,Curve!$B$7*Curve!$C$7*(INDEX(Profile!$B$9:$B$28,$A19)-IF($A19-MIN($A19,$B$2)=0,0,INDEX(Profile!$B$9:$B$28,$A19-MIN($A19,$B$2))))/$B$2/365) | E19: =IF(ISNUMBER(Inputs!$K29),Inputs!$K29,Curve!$B$8*Curve!$C$8*(INDEX(Profile!$B$9:$B$28,$A19)-IF($A19-MIN($A19,$B$2)=0,0,INDEX(Profile!$B$9:$B$28,$A19-MIN($A19,$B$2))))/$B$2/365) | F19: =IF(ISNUMBER(Inputs!$K30),Inputs!$K30,Curve!$B$9*Curve!$C$9*(INDEX(Profile!$B$9:$B$28,$A19)-IF($A19-MIN($A19,$B$2)=0,0,INDEX(Profile!$B$9:$B$28,$A19-MIN($A19,$B$2))))/$B$2/365) | G19: =IF(ISNUMBER(Inputs!$K31),Inputs!$K31,Curve!$B$10*Curve!$C$10*(INDEX(Profile!$B$9:$B$28,$A19)-IF($A19-MIN($A19,$B$2)=0,0,INDEX(Profile!$B$9:$B$28,$A19-MIN($A19,$B$2))))/$B$2/365) | H19: =IF(ISNUMBER(Inputs!$K32),Inputs!$K32,Curve!$B$11*Curve!$C$11*(INDEX(Profile!$B$9:$B$28,$A19)-IF($A19-MIN($A19,$B$2)=0,0,INDEX(Profile!$B$9:$B$28,$A19-MIN($A19,$B$2))))/$B$2/365) | I19: =IF(ISNUMBER(Inputs!$K33),Inputs!$K33,Curve!$B$12*Curve!$C$12*(INDEX(Profile!$B$9:$B$28,$A19)-IF($A19-MIN($A19,$B$2)=0,0,INDEX(Profile!$B$9:$B$28,$A19-MIN($A19,$B$2))))/$B$2/365) | J19: =SUM(B19:I19)
A20: 16 | B20: =IF(ISNUMBER(Inputs!$K26),Inputs!$K26,Curve!$B$5*Curve!$C$5*(INDEX(Profile!$B$9:$B$28,$A20)-IF($A20-MIN($A20,$B$2)=0,0,INDEX(Profile!$B$9:$B$28,$A20-MIN($A20,$B$2))))/$B$2/365) | C20: =IF(ISNUMBER(Inputs!$K27),Inputs!$K27,Curve!$B$6*Curve!$C$6*(INDEX(Profile!$B$9:$B$28,$A20)-IF($A20-MIN($A20,$B$2)=0,0,INDEX(Profile!$B$9:$B$28,$A20-MIN($A20,$B$2))))/$B$2/365) | D20: =IF(ISNUMBER(Inputs!$K28),Inputs!$K28,Curve!$B$7*Curve!$C$7*(INDEX(Profile!$B$9:$B$28,$A20)-IF($A20-MIN($A20,$B$2)=0,0,INDEX(Profile!$B$9:$B$28,$A20-MIN($A20,$B$2))))/$B$2/365) | E20: =IF(ISNUMBER(Inputs!$K29),Inputs!$K29,Curve!$B$8*Curve!$C$8*(INDEX(Profile!$B$9:$B$28,$A20)-IF($A20-MIN($A20,$B$2)=0,0,INDEX(Profile!$B$9:$B$28,$A20-MIN($A20,$B$2))))/$B$2/365) | F20: =IF(ISNUMBER(Inputs!$K30),Inputs!$K30,Curve!$B$9*Curve!$C$9*(INDEX(Profile!$B$9:$B$28,$A20)-IF($A20-MIN($A20,$B$2)=0,0,INDEX(Profile!$B$9:$B$28,$A20-MIN($A20,$B$2))))/$B$2/365) | G20: =IF(ISNUMBER(Inputs!$K31),Inputs!$K31,Curve!$B$10*Curve!$C$10*(INDEX(Profile!$B$9:$B$28,$A20)-IF($A20-MIN($A20,$B$2)=0,0,INDEX(Profile!$B$9:$B$28,$A20-MIN($A20,$B$2))))/$B$2/365) | H20: =IF(ISNUMBER(Inputs!$K32),Inputs!$K32,Curve!$B$11*Curve!$C$11*(INDEX(Profile!$B$9:$B$28,$A20)-IF($A20-MIN($A20,$B$2)=0,0,INDEX(Profile!$B$9:$B$28,$A20-MIN($A20,$B$2))))/$B$2/365) | I20: =IF(ISNUMBER(Inputs!$K33),Inputs!$K33,Curve!$B$12*Curve!$C$12*(INDEX(Profile!$B$9:$B$28,$A20)-IF($A20-MIN($A20,$B$2)=0,0,INDEX(Profile!$B$9:$B$28,$A20-MIN($A20,$B$2))))/$B$2/365) | J20: =SUM(B20:I20)
A21: 17 | B21: =IF(ISNUMBER(Inputs!$K26),Inputs!$K26,Curve!$B$5*Curve!$C$5*(INDEX(Profile!$B$9:$B$28,$A21)-IF($A21-MIN($A21,$B$2)=0,0,INDEX(Profile!$B$9:$B$28,$A21-MIN($A21,$B$2))))/$B$2/365) | C21: =IF(ISNUMBER(Inputs!$K27),Inputs!$K27,Curve!$B$6*Curve!$C$6*(INDEX(Profile!$B$9:$B$28,$A21)-IF($A21-MIN($A21,$B$2)=0,0,INDEX(Profile!$B$9:$B$28,$A21-MIN($A21,$B$2))))/$B$2/365) | D21: =IF(ISNUMBER(Inputs!$K28),Inputs!$K28,Curve!$B$7*Curve!$C$7*(INDEX(Profile!$B$9:$B$28,$A21)-IF($A21-MIN($A21,$B$2)=0,0,INDEX(Profile!$B$9:$B$28,$A21-MIN($A21,$B$2))))/$B$2/365) | E21: =IF(ISNUMBER(Inputs!$K29),Inputs!$K29,Curve!$B$8*Curve!$C$8*(INDEX(Profile!$B$9:$B$28,$A21)-IF($A21-MIN($A21,$B$2)=0,0,INDEX(Profile!$B$9:$B$28,$A21-MIN($A21,$B$2))))/$B$2/365) | F21: =IF(ISNUMBER(Inputs!$K30),Inputs!$K30,Curve!$B$9*Curve!$C$9*(INDEX(Profile!$B$9:$B$28,$A21)-IF($A21-MIN($A21,$B$2)=0,0,INDEX(Profile!$B$9:$B$28,$A21-MIN($A21,$B$2))))/$B$2/365) | G21: =IF(ISNUMBER(Inputs!$K31),Inputs!$K31,Curve!$B$10*Curve!$C$10*(INDEX(Profile!$B$9:$B$28,$A21)-IF($A21-MIN($A21,$B$2)=0,0,INDEX(Profile!$B$9:$B$28,$A21-MIN($A21,$B$2))))/$B$2/365) | H21: =IF(ISNUMBER(Inputs!$K32),Inputs!$K32,Curve!$B$11*Curve!$C$11*(INDEX(Profile!$B$9:$B$28,$A21)-IF($A21-MIN($A21,$B$2)=0,0,INDEX(Profile!$B$9:$B$28,$A21-MIN($A21,$B$2))))/$B$2/365) | I21: =IF(ISNUMBER(Inputs!$K33),Inputs!$K33,Curve!$B$12*Curve!$C$12*(INDEX(Profile!$B$9:$B$28,$A21)-IF($A21-MIN($A21,$B$2)=0,0,INDEX(Profile!$B$9:$B$28,$A21-MIN($A21,$B$2))))/$B$2/365) | J21: =SUM(B21:I21)
