Workbook

Sheet Units
A1: Notes
A2: UNITS
A3: Breakeven: US$ per barrel of WTI. Volume: million barrels per day (Mb/d), crude oil production of US shale regions from EIA STEO. Inventory: locations. Well cost: US$ per lateral foot.
A5: WHAT THIS IS
A6: APPROXIMATE - built from company disclosures and the Dallas Fed Energy Survey, US shale only, WTI basis. A 12-month-ahead supply curve at maintenance-only drilling: each basin has a BASE tier (what is left after a year of natural decline, which stays on at the Dallas Fed shut-in breakeven) and a REPLACEMENT tier (the barrels new wells must add to hold output flat, at the Dallas Fed new-well breakeven).
A7: The breakevens are the Dallas Fed Energy Survey's basin averages (executive answers, Q1 2026): public and numeric, but a survey, not an engineering curve. Operator filings give D&C cost per foot, EUR and inventory for single assets only (see 'Sources' and 'Cross-checks'); no operator publishes a basin breakeven curve we could open.
A8: NOT on the curve: growth barrels above maintenance (no public source gives their volume at a price), Gulf of America offshore and conventional onshore oil, Canadian oil, rig or crew or takeaway limits, hedges, taxes. The three main basins use STEO regional CRUDE production (includes a small non-shale part); 'Other shale' = STEO tight oil minus Permian, Bakken and Eagle Ford tight oil.
A9: Dallas Fed basin lines: Bakken has none, so it borrows 'Other U.S. (Shale)' (flagged ASSUMPTION); Eagle Ford rests on 5 responses; the Permian uses 'all responses' (the Midland/Delaware split has no production split in STEO).
A11: HOW TO READ THE TABS
A12: Inputs: assumptions and the tier table (yellow = editable, with override columns for your own or a paid curve). Tiers: live volume and breakeven of the 12 tiers (base, replacement, growth per basin). Curve: tiers sorted by breakeven with cumulative volume. Mapping: which tiers are in the money at spot, the 12-month average, the Brent forward converted to WTI, and +/- the shift. Supply ladder: 12-month output at each WTI price. Cross-checks: operator cost per foot, Dallas Fed vs operator figures, inventory years. Price context: WTI and Brent forward values read from brent_wti_daily.xlsx and brent_forward_curve.xlsx (not edited). Dallas Fed: the survey tables. STEO raw: the EIA series used (volumes read from here by formula).
A14: STATUS
A15: Dallas Fed breakevens SOURCED (7 of 8 tier-breakevens on 3 lines; Bakken line is a MAPPING ASSUMPTION), volumes and declines SOURCED (EIA STEO, EIA API v2 steo, fetched 06 Oct 2026; reference month 2026-08), 'Other shale' decline PROXY, forward-to-WTI spread ASSUMPTION (default 2021-2025 mean).
... A18: Yellow cells on 'Inputs' only. Leave override columns blank to use the Dallas Fed value. 'Curve values', 'Mapping values' and 'Ladder values' are the script's own copy of the arithmetic (used by the PNG charts); after editing in Excel the live tabs and native charts follow, the values tabs do not.

Sheet Chart
A1: APPROXIMATE - built from company disclosures and the Dallas Fed Energy Survey, US shale only, WTI basis. Maintenance-only 12-month view; breakevens are Dallas Fed survey averages. Data and editable inputs: 'Chart data', 'Inputs'.

Sheet Chart - Supply ladder
A1: APPROXIMATE - built from company disclosures and the Dallas Fed Energy Survey, US shale only, WTI basis. Output supported at each WTI price (all tiers with breakeven at or below the price).

Sheet Inputs
A1: Inputs - yellow cells are editable and survive reruns. APPROXIMATE - built from company disclosures and the Dallas Fed Energy Survey, US shale only, WTI basis
A2: Block A: assumptions. Block B: basin tiers (volumes read live from 'STEO raw'; breakevens = Dallas Fed Q1 2026; override columns K-L take your own curve).
A4: Assumption | B4: Value | C4: Unit | D4: Status | E4: Note
A5: STEO reference month (latest month all series have) | B5: 2026-08 | C5: YYYY-MM | D5: DERIVED | E5: Volumes and declines are read for this month from 'STEO raw' (EIA API v2 steo, fetched 06 Oct 2026). Edit to another month present in that tab.
A6: Brent-WTI spread used to convert forward Brent to WTI | B6: 4.22 | C6: USD/bbl | D6: ASSUMPTION | E6: Default = 2021-2025 mean of Brent less WTI (brent_wti_daily.xlsx). The latest-day spread is far wider; see 'Price context' for all options.
A7: Price shift for the +/- columns on 'Mapping' | B7: 10 | C7: USD/bbl | D7: OWNER | E7: Editable.
A8: Decline rate for 'Other shale' (share of production per year) | B8: 0.0689 | C8: share | D8: PROXY | E8: No EIA decline series for these plays: mean of the three basins' decline / production. Replace if you have a better figure.
A9: Months of legacy decline counted as the replacement need | B9: 1 | C9: months | D9: SOURCED at 1 (EIA's series is a monthly flow); >1 = ASSUMPTION | E9: EIA's existing-well change is the DPR-style monthly change in output of wells already producing (about -490 kb/d for the Permian against ~480 kb/d from new wells). 1 = next-month view. Raise it to see more volume exposed to the new-well breakeven (the legacy decline slows as young wells age, so n x monthly overstates).
A10: STEO growth horizon month (YYYY-MM) | B10: 2027-12 | C10: YYYY-MM | D10: DERIVED | E10: Growth tier = STEO crude production at this month less the reference month (STEO base case, EIA's own price path). Must exist in 'STEO raw'.
A11: Price ladder start | B11: 30 | C11: USD/bbl | D11: OWNER | E11: 'Supply ladder' tab.
A12: Block B: basin tiers | B12: 5 | C12: USD/bbl | D12: OWNER | E12: 'Supply ladder' tab.
A13: Basin tier | B13: Dallas Fed line used | C13: Production (Mb/d, STEO) | D13: Base decline (Mb/d per year, STEO existing wells) | E13: Shut-in breakeven (USD/bbl WTI) | F13: New-well breakeven, average (USD/bbl) | G13: New-well min of responses | H13: New-well max of responses | I13: Shut-in, Q1 2025 (prior year) | J13: New-well, Q1 2025 (prior year) | K13: OVERRIDE shut-in breakeven | L13: OVERRIDE new-well breakeven | M13: Remaining locations <$60/bbl (TPL / Enverus) | N13: Wells completed per year (STEO x12) | O13: Inventory at current pace (years) | P13: Breakeven status | Q13: Source IDs | R13: STEO growth to horizon month (Mb/d)
A14: Permian | B14: Permian (all responses) | C14: =SUMIFS('STEO raw'!$E:$E,'STEO raw'!$A:$A,"COPRPM|"&$B$5) | D14: =-SUMIFS('STEO raw'!$E:$E,'STEO raw'!$A:$A,"COEOPPM|"&$B$5)/1000 | E14: 39 | F14: 67 | G14: 50 | H14: 90 | I14: 39 | J14: 65 | M14: 65000 | N14: =SUMIFS('STEO raw'!$E:$E,'STEO raw'!$A:$A,"NWCPM|"&$B$5)*12 | O14: =IF(ISNUMBER(N14),M14/N14,"n/a") | P14: SOURCED | Q14: D1-D10, E1-E3, T1 | R14: =SUMIFS('STEO raw'!$E:$E,'STEO raw'!$A:$A,"COPRPM|"&$B$10)-C14
A15: Bakken | B15: Other U.S. (Shale) | C15: =SUMIFS('STEO raw'!$E:$E,'STEO raw'!$A:$A,"COPRBK|"&$B$5) | D15: =-SUMIFS('STEO raw'!$E:$E,'STEO raw'!$A:$A,"COEOPBK|"&$B$5)/1000 | E15: 44.12 | F15: 62.38 | G15: 35 | H15: 85 | I15: 40.81 | J15: 63 | M15: 5000 | N15: =SUMIFS('STEO raw'!$E:$E,'STEO raw'!$A:$A,"NWCBK|"&$B$5)*12 | O15: =IF(ISNUMBER(N15),M15/N15,"n/a") | P15: ASSUMPTION (mapping: Dallas publishes no Bakken line) | Q15: D1-D10, E1-E3, T1 | R15: =SUMIFS('STEO raw'!$E:$E,'STEO raw'!$A:$A,"COPRBK|"&$B$10)-C15
A16: Eagle Ford | B16: Eagle Ford | C16: =SUMIFS('STEO raw'!$E:$E,'STEO raw'!$A:$A,"COPREF|"&$B$5) | D16: =-SUMIFS('STEO raw'!$E:$E,'STEO raw'!$A:$A,"COEOPEF|"&$B$5)/1000 | E16: 40 | F16: 63 | G16: 50 | H16: 70 | I16: 25.83 | J16: 61.67 | M16: 13000 | N16: =SUMIFS('STEO raw'!$E:$E,'STEO raw'!$A:$A,"NWCEF|"&$B$5)*12 | O16: =IF(ISNUMBER(N16),M16/N16,"n/a") | P16: SOURCED (5 responses) | Q16: D1-D10, E1-E3, T1 | R16: =SUMIFS('STEO raw'!$E:$E,'STEO raw'!$A:$A,"COPREF|"&$B$10)-C16
A17: Other shale (Niobrara, Anadarko, Austin Chalk, other) | B17: Other U.S. (Shale) | C17: =SUMIFS('STEO raw'!$E:$E,'STEO raw'!$A:$A,"TOPRL48|"&$B$5)-SUMIFS('STEO raw'!$E:$E,'STEO raw'!$A:$A,"TOPRPM|"&$B$5)-SUMIFS('STEO raw'!$E:$E,'STEO raw'!$A:$A,"TOPRBK|"&$B$5)-SUMIFS('STEO raw'!$E:$E,'STEO raw'!$A:$A,"TOPREF|"&$B$5) | D17: =$B$8*C17 | E17: 44.12 | F17: 62.38 | G17: 35 | H17: 85 | I17: 40.81 | J17: 63 | M17: 6000 | N17: n/a | O17: =IF(ISNUMBER(N17),M17/N17,"n/a") | P17: SOURCED (17 responses) | Q17: D1-D10, E1-E3, T1 | R17: 0
A19: Other shale (no STEO forecast of its own, so growth = 0 here): production = TOPRL48 - TOPRPM - TOPRBK - TOPREF (STEO tight oil); decline = proxy rate x production (PROXY); locations = Anadarko ~3,000 + DJ ~3,000 only (Niobrara etc. not itemised by TPL).
A20: Bakken uses the Dallas Fed 'Other U.S. (Shale)' line (ASSUMPTION: no Bakken line is published). Permian uses 'Permian (all responses)'. Inventory years = TPL/Enverus <$60 locations / STEO completions: below-$60 locations only, so a floor.

Sheet Tiers
A1: Tiers (live): three tiers per basin (base, replacement, growth). APPROXIMATE - built from company disclosures and the Dallas Fed Energy Survey, US shale only, WTI basis
A3: Tier | B3: Kind | C3: Basin | D3: Volume (Mb/d) | E3: Breakeven used (USD/bbl WTI) | F3: Sort key | G3: Rank
A4: =LEFT(Inputs!$A$14,FIND(" (",Inputs!$A$14&" (")-1)&" - base (existing wells after the decline)" | B4: Base | C4: =Inputs!$A$14 | D4: =Inputs!$C$14-Inputs!$B$9*Inputs!$D$14 | E4: =IF(ISNUMBER(Inputs!$K$14),Inputs!$K$14,Inputs!$E$14) | F4: =E4+ROW()/1000000 | G4: =RANK(F4,$F$4:$F$15,1)
A5: =LEFT(Inputs!$A$14,FIND(" (",Inputs!$A$14&" (")-1)&" - replacement (new wells to offset the decline)" | B5: Replacement | C5: =Inputs!$A$14 | D5: =Inputs!$B$9*Inputs!$D$14 | E5: =IF(ISNUMBER(Inputs!$L$14),Inputs!$L$14,Inputs!$F$14) | F5: =E5+ROW()/1000000 | G5: =RANK(F5,$F$4:$F$15,1)
A6: =LEFT(Inputs!$A$14,FIND(" (",Inputs!$A$14&" (")-1)&" - growth (STEO base case to horizon)" | B6: Growth | C6: =Inputs!$A$14 | D6: =Inputs!$R$14 | E6: =IF(ISNUMBER(Inputs!$L$14),Inputs!$L$14,Inputs!$F$14) | F6: =E6+ROW()/1000000 | G6: =RANK(F6,$F$4:$F$15,1)
A7: =LEFT(Inputs!$A$15,FIND(" (",Inputs!$A$15&" (")-1)&" - base (existing wells after the decline)" | B7: Base | C7: =Inputs!$A$15 | D7: =Inputs!$C$15-Inputs!$B$9*Inputs!$D$15 | E7: =IF(ISNUMBER(Inputs!$K$15),Inputs!$K$15,Inputs!$E$15) | F7: =E7+ROW()/1000000 | G7: =RANK(F7,$F$4:$F$15,1)
A8: =LEFT(Inputs!$A$15,FIND(" (",Inputs!$A$15&" (")-1)&" - replacement (new wells to offset the decline)" | B8: Replacement | C8: =Inputs!$A$15 | D8: =Inputs!$B$9*Inputs!$D$15 | E8: =IF(ISNUMBER(Inputs!$L$15),Inputs!$L$15,Inputs!$F$15) | F8: =E8+ROW()/1000000 | G8: =RANK(F8,$F$4:$F$15,1)
A9: =LEFT(Inputs!$A$15,FIND(" (",Inputs!$A$15&" (")-1)&" - growth (STEO base case to horizon)" | B9: Growth | C9: =Inputs!$A$15 | D9: =Inputs!$R$15 | E9: =IF(ISNUMBER(Inputs!$L$15),Inputs!$L$15,Inputs!$F$15) | F9: =E9+ROW()/1000000 | G9: =RANK(F9,$F$4:$F$15,1)
A10: =LEFT(Inputs!$A$16,FIND(" (",Inputs!$A$16&" (")-1)&" - base (existing wells after the decline)" | B10: Base | C10: =Inputs!$A$16 | D10: =Inputs!$C$16-Inputs!$B$9*Inputs!$D$16 | E10: =IF(ISNUMBER(Inputs!$K$16),Inputs!$K$16,Inputs!$E$16) | F10: =E10+ROW()/1000000 | G10: =RANK(F10,$F$4:$F$15,1)
A11: =LEFT(Inputs!$A$16,FIND(" (",Inputs!$A$16&" (")-1)&" - replacement (new wells to offset the decline)" | B11: Replacement | C11: =Inputs!$A$16 | D11: =Inputs!$B$9*Inputs!$D$16 | E11: =IF(ISNUMBER(Inputs!$L$16),Inputs!$L$16,Inputs!$F$16) | F11: =E11+ROW()/1000000 | G11: =RANK(F11,$F$4:$F$15,1)
A12: =LEFT(Inputs!$A$16,FIND(" (",Inputs!$A$16&" (")-1)&" - growth (STEO base case to horizon)" | B12: Growth | C12: =Inputs!$A$16 | D12: =Inputs!$R$16 | E12: =IF(ISNUMBER(Inputs!$L$16),Inputs!$L$16,Inputs!$F$16) | F12: =E12+ROW()/1000000 | G12: =RANK(F12,$F$4:$F$15,1)
A13: =LEFT(Inputs!$A$17,FIND(" (",Inputs!$A$17&" (")-1)&" - base (existing wells after the decline)" | B13: Base | C13: =Inputs!$A$17 | D13: =Inputs!$C$17-Inputs!$B$9*Inputs!$D$17 | E13: =IF(ISNUMBER(Inputs!$K$17),Inputs!$K$17,Inputs!$E$17) | F13: =E13+ROW()/1000000 | G13: =RANK(F13,$F$4:$F$15,1)
A14: =LEFT(Inputs!$A$17,FIND(" (",Inputs!$A$17&" (")-1)&" - replacement (new wells to offset the decline)" | B14: Replacement | C14: =Inputs!$A$17 | D14: =Inputs!$B$9*Inputs!$D$17 | E14: =IF(ISNUMBER(Inputs!$L$17),Inputs!$L$17,Inputs!$F$17) | F14: =E14+ROW()/1000000 | G14: =RANK(F14,$F$4:$F$15,1)
A15: =LEFT(Inputs!$A$17,FIND(" (",Inputs!$A$17&" (")-1)&" - growth (STEO base case to horizon)" | B15: Growth | C15: =Inputs!$A$17 | D15: =Inputs!$R$17 | E15: =IF(ISNUMBER(Inputs!$L$17),Inputs!$L$17,Inputs!$F$17) | F15: =E15+ROW()/1000000 | G15: =RANK(F15,$F$4:$F$15,1)
A17: Total volume (Mb/d): production + STEO growth | D17: =SUM(D4:D15)

Sheet Curve
A1: Curve (live): tiers sorted by breakeven. APPROXIMATE - built from company disclosures and the Dallas Fed Energy Survey, US shale only, WTI basis
A4: Rank | B4: Tier | C4: Kind | D4: Volume (Mb/d) | E4: Breakeven (USD/bbl WTI) | F4: Cumulative volume (Mb/d) | G4: Prior-year breakeven (Dallas Q1 2025, same tier)
A5: 1 | B5: =INDEX(Tiers!$A$4:$A$15,MATCH($A5,Tiers!$G$4:$G$15,0)) | C5: =INDEX(Tiers!$B$4:$B$15,MATCH($A5,Tiers!$G$4:$G$15,0)) | D5: =INDEX(Tiers!$D$4:$D$15,MATCH($A5,Tiers!$G$4:$G$15,0)) | E5: =INDEX(Tiers!$E$4:$E$15,MATCH($A5,Tiers!$G$4:$G$15,0)) | F5: =D5 | G5: =IF(C5="Base",INDEX(Inputs!$I$14:$I$17,INT((MATCH($A5,Tiers!$G$4:$G$15,0)-1)/3)+1),INDEX(Inputs!$J$14:$J$17,INT((MATCH($A5,Tiers!$G$4:$G$15,0)-1)/3)+1))
A6: 2 | B6: =INDEX(Tiers!$A$4:$A$15,MATCH($A6,Tiers!$G$4:$G$15,0)) | C6: =INDEX(Tiers!$B$4:$B$15,MATCH($A6,Tiers!$G$4:$G$15,0)) | D6: =INDEX(Tiers!$D$4:$D$15,MATCH($A6,Tiers!$G$4:$G$15,0)) | E6: =INDEX(Tiers!$E$4:$E$15,MATCH($A6,Tiers!$G$4:$G$15,0)) | F6: =F5+D6 | G6: =IF(C6="Base",INDEX(Inputs!$I$14:$I$17,INT((MATCH($A6,Tiers!$G$4:$G$15,0)-1)/3)+1),INDEX(Inputs!$J$14:$J$17,INT((MATCH($A6,Tiers!$G$4:$G$15,0)-1)/3)+1))
A7: 3 | B7: =INDEX(Tiers!$A$4:$A$15,MATCH($A7,Tiers!$G$4:$G$15,0)) | C7: =INDEX(Tiers!$B$4:$B$15,MATCH($A7,Tiers!$G$4:$G$15,0)) | D7: =INDEX(Tiers!$D$4:$D$15,MATCH($A7,Tiers!$G$4:$G$15,0)) | E7: =INDEX(Tiers!$E$4:$E$15,MATCH($A7,Tiers!$G$4:$G$15,0)) | F7: =F6+D7 | G7: =IF(C7="Base",INDEX(Inputs!$I$14:$I$17,INT((MATCH($A7,Tiers!$G$4:$G$15,0)-1)/3)+1),INDEX(Inputs!$J$14:$J$17,INT((MATCH($A7,Tiers!$G$4:$G$15,0)-1)/3)+1))
A8: 4 | B8: =INDEX(Tiers!$A$4:$A$15,MATCH($A8,Tiers!$G$4:$G$15,0)) | C8: =INDEX(Tiers!$B$4:$B$15,MATCH($A8,Tiers!$G$4:$G$15,0)) | D8: =INDEX(Tiers!$D$4:$D$15,MATCH($A8,Tiers!$G$4:$G$15,0)) | E8: =INDEX(Tiers!$E$4:$E$15,MATCH($A8,Tiers!$G$4:$G$15,0)) | F8: =F7+D8 | G8: =IF(C8="Base",INDEX(Inputs!$I$14:$I$17,INT((MATCH($A8,Tiers!$G$4:$G$15,0)-1)/3)+1),INDEX(Inputs!$J$14:$J$17,INT((MATCH($A8,Tiers!$G$4:$G$15,0)-1)/3)+1))
A9: 5 | B9: =INDEX(Tiers!$A$4:$A$15,MATCH($A9,Tiers!$G$4:$G$15,0)) | C9: =INDEX(Tiers!$B$4:$B$15,MATCH($A9,Tiers!$G$4:$G$15,0)) | D9: =INDEX(Tiers!$D$4:$D$15,MATCH($A9,Tiers!$G$4:$G$15,0)) | E9: =INDEX(Tiers!$E$4:$E$15,MATCH($A9,Tiers!$G$4:$G$15,0)) | F9: =F8+D9 | G9: =IF(C9="Base",INDEX(Inputs!$I$14:$I$17,INT((MATCH($A9,Tiers!$G$4:$G$15,0)-1)/3)+1),INDEX(Inputs!$J$14:$J$17,INT((MATCH($A9,Tiers!$G$4:$G$15,0)-1)/3)+1))
A10: 6 | B10: =INDEX(Tiers!$A$4:$A$15,MATCH($A10,Tiers!$G$4:$G$15,0)) | C10: =INDEX(Tiers!$B$4:$B$15,MATCH($A10,Tiers!$G$4:$G$15,0)) | D10: =INDEX(Tiers!$D$4:$D$15,MATCH($A10,Tiers!$G$4:$G$15,0)) | E10: =INDEX(Tiers!$E$4:$E$15,MATCH($A10,Tiers!$G$4:$G$15,0)) | F10: =F9+D10 | G10: =IF(C10="Base",INDEX(Inputs!$I$14:$I$17,INT((MATCH($A10,Tiers!$G$4:$G$15,0)-1)/3)+1),INDEX(Inputs!$J$14:$J$17,INT((MATCH($A10,Tiers!$G$4:$G$15,0)-1)/3)+1))
A11: 7 | B11: =INDEX(Tiers!$A$4:$A$15,MATCH($A11,Tiers!$G$4:$G$15,0)) | C11: =INDEX(Tiers!$B$4:$B$15,MATCH($A11,Tiers!$G$4:$G$15,0)) | D11: =INDEX(Tiers!$D$4:$D$15,MATCH($A11,Tiers!$G$4:$G$15,0)) | E11: =INDEX(Tiers!$E$4:$E$15,MATCH($A11,Tiers!$G$4:$G$15,0)) | F11: =F10+D11 | G11: =IF(C11="Base",INDEX(Inputs!$I$14:$I$17,INT((MATCH($A11,Tiers!$G$4:$G$15,0)-1)/3)+1),INDEX(Inputs!$J$14:$J$17,INT((MATCH($A11,Tiers!$G$4:$G$15,0)-1)/3)+1))
A12: 8 | B12: =INDEX(Tiers!$A$4:$A$15,MATCH($A12,Tiers!$G$4:$G$15,0)) | C12: =INDEX(Tiers!$B$4:$B$15,MATCH($A12,Tiers!$G$4:$G$15,0)) | D12: =INDEX(Tiers!$D$4:$D$15,MATCH($A12,Tiers!$G$4:$G$15,0)) | E12: =INDEX(Tiers!$E$4:$E$15,MATCH($A12,Tiers!$G$4:$G$15,0)) | F12: =F11+D12 | G12: =IF(C12="Base",INDEX(Inputs!$I$14:$I$17,INT((MATCH($A12,Tiers!$G$4:$G$15,0)-1)/3)+1),INDEX(Inputs!$J$14:$J$17,INT((MATCH($A12,Tiers!$G$4:$G$15,0)-1)/3)+1))
A13: 9 | B13: =INDEX(Tiers!$A$4:$A$15,MATCH($A13,Tiers!$G$4:$G$15,0)) | C13: =INDEX(Tiers!$B$4:$B$15,MATCH($A13,Tiers!$G$4:$G$15,0)) | D13: =INDEX(Tiers!$D$4:$D$15,MATCH($A13,Tiers!$G$4:$G$15,0)) | E13: =INDEX(Tiers!$E$4:$E$15,MATCH($A13,Tiers!$G$4:$G$15,0)) | F13: =F12+D13 | G13: =IF(C13="Base",INDEX(Inputs!$I$14:$I$17,INT((MATCH($A13,Tiers!$G$4:$G$15,0)-1)/3)+1),INDEX(Inputs!$J$14:$J$17,INT((MATCH($A13,Tiers!$G$4:$G$15,0)-1)/3)+1))
A14: 10 | B14: =INDEX(Tiers!$A$4:$A$15,MATCH($A14,Tiers!$G$4:$G$15,0)) | C14: =INDEX(Tiers!$B$4:$B$15,MATCH($A14,Tiers!$G$4:$G$15,0)) | D14: =INDEX(Tiers!$D$4:$D$15,MATCH($A14,Tiers!$G$4:$G$15,0)) | E14: =INDEX(Tiers!$E$4:$E$15,MATCH($A14,Tiers!$G$4:$G$15,0)) | F14: =F13+D14 | G14: =IF(C14="Base",INDEX(Inputs!$I$14:$I$17,INT((MATCH($A14,Tiers!$G$4:$G$15,0)-1)/3)+1),INDEX(Inputs!$J$14:$J$17,INT((MATCH($A14,Tiers!$G$4:$G$15,0)-1)/3)+1))
A15: 11 | B15: =INDEX(Tiers!$A$4:$A$15,MATCH($A15,Tiers!$G$4:$G$15,0)) | C15: =INDEX(Tiers!$B$4:$B$15,MATCH($A15,Tiers!$G$4:$G$15,0)) | D15: =INDEX(Tiers!$D$4:$D$15,MATCH($A15,Tiers!$G$4:$G$15,0)) | E15: =INDEX(Tiers!$E$4:$E$15,MATCH($A15,Tiers!$G$4:$G$15,0)) | F15: =F14+D15 | G15: =IF(C15="Base",INDEX(Inputs!$I$14:$I$17,INT((MATCH($A15,Tiers!$G$4:$G$15,0)-1)/3)+1),INDEX(Inputs!$J$14:$J$17,INT((MATCH($A15,Tiers!$G$4:$G$15,0)-1)/3)+1))
A16: 12 | B16: =INDEX(Tiers!$A$4:$A$15,MATCH($A16,Tiers!$G$4:$G$15,0)) | C16: =INDEX(Tiers!$B$4:$B$15,MATCH($A16,Tiers!$G$4:$G$15,0)) | D16: =INDEX(Tiers!$D$4:$D$15,MATCH($A16,Tiers!$G$4:$G$15,0)) | E16: =INDEX(Tiers!$E$4:$E$15,MATCH($A16,Tiers!$G$4:$G$15,0)) | F16: =F15+D16 | G16: =IF(C16="Base",INDEX(Inputs!$I$14:$I$17,INT((MATCH($A16,Tiers!$G$4:$G$15,0)-1)/3)+1),INDEX(Inputs!$J$14:$J$17,INT((MATCH($A16,Tiers!$G$4:$G$15,0)-1)/3)+1))
A18: Prior-year column follows the sorted order of the current curve (volumes identical); it is the Dallas Fed Q1 2025 average for the same tier.

Sheet Mapping
A1: Mapping (live): which tiers are in the money (WTI price >= tier breakeven). APPROXIMATE - built from company disclosures and the Dallas Fed Energy Survey, US shale only, WTI basis
A2: Prices: spot and 12-month mean WTI and the Brent forward (converted to WTI with the spread on Inputs) from 'Price context' / 'Price forwards'; shift on Inputs.
A4: Scenario | B4: WTI price (USD/bbl) | C4: =Curve!$B$5 | D4: =Curve!$B$6 | E4: =Curve!$B$7 | F4: =Curve!$B$8 | G4: =Curve!$B$9 | H4: =Curve!$B$10 | I4: =Curve!$B$11 | J4: =Curve!$B$12 | K4: =Curve!$B$13 | L4: =Curve!$B$14 | M4: =Curve!$B$15 | N4: =Curve!$B$16 | O4: Volume in the money (Mb/d) | P4: Share of total volume | Q4: Tiers in the money (of 12) | R4: Marginal in-the-money breakeven (USD/bbl) | S4: Cushion over the highest breakeven (USD/bbl)
A5: Tier breakeven (USD/bbl) | C5: =Curve!$E$5 | D5: =Curve!$E$6 | E5: =Curve!$E$7 | F5: =Curve!$E$8 | G5: =Curve!$E$9 | H5: =Curve!$E$10 | I5: =Curve!$E$11 | J5: =Curve!$E$12 | K5: =Curve!$E$13 | L5: =Curve!$E$14 | M5: =Curve!$E$15 | N5: =Curve!$E$16
A6: Tier volume (Mb/d) | C6: =Curve!$D$5 | D6: =Curve!$D$6 | E6: =Curve!$D$7 | F6: =Curve!$D$8 | G6: =Curve!$D$9 | H6: =Curve!$D$10 | I6: =Curve!$D$11 | J6: =Curve!$D$12 | K6: =Curve!$D$13 | L6: =Curve!$D$14 | M6: =Curve!$D$15 | N6: =Curve!$D$16
A7: WTI spot | B7: ='Price context'!$B$2 | C7: =IF($B7>=C$5,"in","out") | D7: =IF($B7>=D$5,"in","out") | E7: =IF($B7>=E$5,"in","out") | F7: =IF($B7>=F$5,"in","out") | G7: =IF($B7>=G$5,"in","out") | H7: =IF($B7>=H$5,"in","out") | I7: =IF($B7>=I$5,"in","out") | J7: =IF($B7>=J$5,"in","out") | ... N7: =IF($B7>=N$5,"in","out") | O7: =SUMPRODUCT(($B7>=C$5:N$5)*C$6:N$6) | P7: =O7/SUM(C$6:N$6) | Q7: =COUNTIF(C7:N7,"in") | R7: =IF(Q7=0,"none",SUMPRODUCT(MAX(($B7>=C$5:N$5)*C$5:N$5))) | S7: =$B7-MAX(C$5:N$5)
A8: WTI spot minus shift | B8: ='Price context'!$B$2-Inputs!$B$7 | C8: =IF($B8>=C$5,"in","out") | D8: =IF($B8>=D$5,"in","out") | E8: =IF($B8>=E$5,"in","out") | F8: =IF($B8>=F$5,"in","out") | G8: =IF($B8>=G$5,"in","out") | H8: =IF($B8>=H$5,"in","out") | I8: =IF($B8>=I$5,"in","out") | J8: =IF($B8>=J$5,"in","out") | ... N8: =IF($B8>=N$5,"in","out") | O8: =SUMPRODUCT(($B8>=C$5:N$5)*C$6:N$6) | P8: =O8/SUM(C$6:N$6) | Q8: =COUNTIF(C8:N8,"in") | R8: =IF(Q8=0,"none",SUMPRODUCT(MAX(($B8>=C$5:N$5)*C$5:N$5))) | S8: =$B8-MAX(C$5:N$5)
A9: WTI spot plus shift | B9: ='Price context'!$B$2+Inputs!$B$7 | C9: =IF($B9>=C$5,"in","out") | D9: =IF($B9>=D$5,"in","out") | E9: =IF($B9>=E$5,"in","out") | F9: =IF($B9>=F$5,"in","out") | G9: =IF($B9>=G$5,"in","out") | H9: =IF($B9>=H$5,"in","out") | I9: =IF($B9>=I$5,"in","out") | J9: =IF($B9>=J$5,"in","out") | ... N9: =IF($B9>=N$5,"in","out") | O9: =SUMPRODUCT(($B9>=C$5:N$5)*C$6:N$6) | P9: =O9/SUM(C$6:N$6) | Q9: =COUNTIF(C9:N9,"in") | R9: =IF(Q9=0,"none",SUMPRODUCT(MAX(($B9>=C$5:N$5)*C$5:N$5))) | S9: =$B9-MAX(C$5:N$5)
A10: WTI, last 12 months mean | B10: ='Price context'!$B$4 | C10: =IF($B10>=C$5,"in","out") | D10: =IF($B10>=D$5,"in","out") | E10: =IF($B10>=E$5,"in","out") | F10: =IF($B10>=F$5,"in","out") | G10: =IF($B10>=G$5,"in","out") | H10: =IF($B10>=H$5,"in","out") | I10: =IF($B10>=I$5,"in","out") | J10: =IF($B10>=J$5,"in","out") | ... N10: =IF($B10>=N$5,"in","out") | O10: =SUMPRODUCT(($B10>=C$5:N$5)*C$6:N$6) | P10: =O10/SUM(C$6:N$6) | Q10: =COUNTIF(C10:N10,"in") | R10: =IF(Q10=0,"none",SUMPRODUCT(MAX(($B10>=C$5:N$5)*C$5:N$5))) | S10: =$B10-MAX(C$5:N$5)
A11: WTI, last 12 months mean minus shift | B11: ='Price context'!$B$4-Inputs!$B$7 | C11: =IF($B11>=C$5,"in","out") | D11: =IF($B11>=D$5,"in","out") | E11: =IF($B11>=E$5,"in","out") | F11: =IF($B11>=F$5,"in","out") | G11: =IF($B11>=G$5,"in","out") | H11: =IF($B11>=H$5,"in","out") | I11: =IF($B11>=I$5,"in","out") | J11: =IF($B11>=J$5,"in","out") | ... N11: =IF($B11>=N$5,"in","out") | O11: =SUMPRODUCT(($B11>=C$5:N$5)*C$6:N$6) | P11: =O11/SUM(C$6:N$6) | Q11: =COUNTIF(C11:N11,"in") | R11: =IF(Q11=0,"none",SUMPRODUCT(MAX(($B11>=C$5:N$5)*C$5:N$5))) | S11: =$B11-MAX(C$5:N$5)
A12: WTI, last 12 months mean plus shift | B12: ='Price context'!$B$4+Inputs!$B$7 | C12: =IF($B12>=C$5,"in","out") | D12: =IF($B12>=D$5,"in","out") | E12: =IF($B12>=E$5,"in","out") | F12: =IF($B12>=F$5,"in","out") | G12: =IF($B12>=G$5,"in","out") | H12: =IF($B12>=H$5,"in","out") | I12: =IF($B12>=I$5,"in","out") | J12: =IF($B12>=J$5,"in","out") | ... N12: =IF($B12>=N$5,"in","out") | O12: =SUMPRODUCT(($B12>=C$5:N$5)*C$6:N$6) | P12: =O12/SUM(C$6:N$6) | Q12: =COUNTIF(C12:N12,"in") | R12: =IF(Q12=0,"none",SUMPRODUCT(MAX(($B12>=C$5:N$5)*C$5:N$5))) | S12: =$B12-MAX(C$5:N$5)
A13: Brent forward M12 less spread (WTI-equivalent) | B13: ='Price forwards'!$B$5-Inputs!$B$6 | C13: =IF($B13>=C$5,"in","out") | D13: =IF($B13>=D$5,"in","out") | E13: =IF($B13>=E$5,"in","out") | F13: =IF($B13>=F$5,"in","out") | G13: =IF($B13>=G$5,"in","out") | H13: =IF($B13>=H$5,"in","out") | I13: =IF($B13>=I$5,"in","out") | J13: =IF($B13>=J$5,"in","out") | ... N13: =IF($B13>=N$5,"in","out") | O13: =SUMPRODUCT(($B13>=C$5:N$5)*C$6:N$6) | P13: =O13/SUM(C$6:N$6) | Q13: =COUNTIF(C13:N13,"in") | R13: =IF(Q13=0,"none",SUMPRODUCT(MAX(($B13>=C$5:N$5)*C$5:N$5))) | S13: =$B13-MAX(C$5:N$5)
A14: Brent forward M12 less spread (WTI-equivalent) minus shift | B14: ='Price forwards'!$B$5-Inputs!$B$6-Inputs!$B$7 | C14: =IF($B14>=C$5,"in","out") | D14: =IF($B14>=D$5,"in","out") | E14: =IF($B14>=E$5,"in","out") | F14: =IF($B14>=F$5,"in","out") | G14: =IF($B14>=G$5,"in","out") | H14: =IF($B14>=H$5,"in","out") | I14: =IF($B14>=I$5,"in","out") | J14: =IF($B14>=J$5,"in","out") | ... N14: =IF($B14>=N$5,"in","out") | O14: =SUMPRODUCT(($B14>=C$5:N$5)*C$6:N$6) | P14: =O14/SUM(C$6:N$6) | Q14: =COUNTIF(C14:N14,"in") | R14: =IF(Q14=0,"none",SUMPRODUCT(MAX(($B14>=C$5:N$5)*C$5:N$5))) | S14: =$B14-MAX(C$5:N$5)
A15: Brent forward M12 less spread (WTI-equivalent) plus shift | B15: ='Price forwards'!$B$5-Inputs!$B$6+Inputs!$B$7 | C15: =IF($B15>=C$5,"in","out") | D15: =IF($B15>=D$5,"in","out") | E15: =IF($B15>=E$5,"in","out") | F15: =IF($B15>=F$5,"in","out") | G15: =IF($B15>=G$5,"in","out") | H15: =IF($B15>=H$5,"in","out") | I15: =IF($B15>=I$5,"in","out") | J15: =IF($B15>=J$5,"in","out") | ... N15: =IF($B15>=N$5,"in","out") | O15: =SUMPRODUCT(($B15>=C$5:N$5)*C$6:N$6) | P15: =O15/SUM(C$6:N$6) | Q15: =COUNTIF(C15:N15,"in") | R15: =IF(Q15=0,"none",SUMPRODUCT(MAX(($B15>=C$5:N$5)*C$5:N$5))) | S15: =$B15-MAX(C$5:N$5)
A16: Brent forward M24 less spread (WTI-equivalent) | B16: ='Price forwards'!$B$7-Inputs!$B$6 | C16: =IF($B16>=C$5,"in","out") | D16: =IF($B16>=D$5,"in","out") | E16: =IF($B16>=E$5,"in","out") | F16: =IF($B16>=F$5,"in","out") | G16: =IF($B16>=G$5,"in","out") | H16: =IF($B16>=H$5,"in","out") | I16: =IF($B16>=I$5,"in","out") | J16: =IF($B16>=J$5,"in","out") | ... N16: =IF($B16>=N$5,"in","out") | O16: =SUMPRODUCT(($B16>=C$5:N$5)*C$6:N$6) | P16: =O16/SUM(C$6:N$6) | Q16: =COUNTIF(C16:N16,"in") | R16: =IF(Q16=0,"none",SUMPRODUCT(MAX(($B16>=C$5:N$5)*C$5:N$5))) | S16: =$B16-MAX(C$5:N$5)
A17: Brent forward M24 less spread (WTI-equivalent) minus shift | B17: ='Price forwards'!$B$7-Inputs!$B$6-Inputs!$B$7 | C17: =IF($B17>=C$5,"in","out") | D17: =IF($B17>=D$5,"in","out") | E17: =IF($B17>=E$5,"in","out") | F17: =IF($B17>=F$5,"in","out") | G17: =IF($B17>=G$5,"in","out") | H17: =IF($B17>=H$5,"in","out") | I17: =IF($B17>=I$5,"in","out") | J17: =IF($B17>=J$5,"in","out") | ... N17: =IF($B17>=N$5,"in","out") | O17: =SUMPRODUCT(($B17>=C$5:N$5)*C$6:N$6) | P17: =O17/SUM(C$6:N$6) | Q17: =COUNTIF(C17:N17,"in") | R17: =IF(Q17=0,"none",SUMPRODUCT(MAX(($B17>=C$5:N$5)*C$5:N$5))) | S17: =$B17-MAX(C$5:N$5)
A18: Brent forward M24 less spread (WTI-equivalent) plus shift | B18: ='Price forwards'!$B$7-Inputs!$B$6+Inputs!$B$7 | C18: =IF($B18>=C$5,"in","out") | D18: =IF($B18>=D$5,"in","out") | E18: =IF($B18>=E$5,"in","out") | F18: =IF($B18>=F$5,"in","out") | G18: =IF($B18>=G$5,"in","out") | H18: =IF($B18>=H$5,"in","out") | I18: =IF($B18>=I$5,"in","out") | J18: =IF($B18>=J$5,"in","out") | ... N18: =IF($B18>=N$5,"in","out") | O18: =SUMPRODUCT(($B18>=C$5:N$5)*C$6:N$6) | P18: =O18/SUM(C$6:N$6) | Q18: =COUNTIF(C18:N18,"in") | R18: =IF(Q18=0,"none",SUMPRODUCT(MAX(($B18>=C$5:N$5)*C$5:N$5))) | S18: =$B18-MAX(C$5:N$5)
A20: 'in' = the tier's breakeven is at or below the price, so the volume is supported for the next 12 months at maintenance drilling. A price below the new-well breakevens but above shut-in keeps the base tiers but loses the replacement tiers (output falls by the decline).

Sheet Supply ladder
A1: Supply ladder (live): output 12 months ahead at maintenance-only drilling, by WTI price. APPROXIMATE - built from company disclosures and the Dallas Fed Energy Survey, US shale only, WTI basis
A3: WTI (USD/bbl) | B3: Supported volume (Mb/d) | C3: Share of current production
A4: =Inputs!$B$11+0*Inputs!$B$12 | B4: =SUMPRODUCT((A4>=Curve!$E$5:$E$16)*Curve!$D$5:$D$16) | C4: =B4/SUM(Curve!$D$5:$D$16)
A5: =Inputs!$B$11+1*Inputs!$B$12 | B5: =SUMPRODUCT((A5>=Curve!$E$5:$E$16)*Curve!$D$5:$D$16) | C5: =B5/SUM(Curve!$D$5:$D$16)
A6: =Inputs!$B$11+2*Inputs!$B$12 | B6: =SUMPRODUCT((A6>=Curve!$E$5:$E$16)*Curve!$D$5:$D$16) | C6: =B6/SUM(Curve!$D$5:$D$16)
A7: =Inputs!$B$11+3*Inputs!$B$12 | B7: =SUMPRODUCT((A7>=Curve!$E$5:$E$16)*Curve!$D$5:$D$16) | C7: =B7/SUM(Curve!$D$5:$D$16)
A8: =Inputs!$B$11+4*Inputs!$B$12 | B8: =SUMPRODUCT((A8>=Curve!$E$5:$E$16)*Curve!$D$5:$D$16) | C8: =B8/SUM(Curve!$D$5:$D$16)
A9: =Inputs!$B$11+5*Inputs!$B$12 | B9: =SUMPRODUCT((A9>=Curve!$E$5:$E$16)*Curve!$D$5:$D$16) | C9: =B9/SUM(Curve!$D$5:$D$16)
A10: =Inputs!$B$11+6*Inputs!$B$12 | B10: =SUMPRODUCT((A10>=Curve!$E$5:$E$16)*Curve!$D$5:$D$16) | C10: =B10/SUM(Curve!$D$5:$D$16)
A11: =Inputs!$B$11+7*Inputs!$B$12 | B11: =SUMPRODUCT((A11>=Curve!$E$5:$E$16)*Curve!$D$5:$D$16) | C11: =B11/SUM(Curve!$D$5:$D$16)
A12: =Inputs!$B$11+8*Inputs!$B$12 | B12: =SUMPRODUCT((A12>=Curve!$E$5:$E$16)*Curve!$D$5:$D$16) | C12: =B12/SUM(Curve!$D$5:$D$16)
A13: =Inputs!$B$11+9*Inputs!$B$12 | B13: =SUMPRODUCT((A13>=Curve!$E$5:$E$16)*Curve!$D$5:$D$16) | C13: =B13/SUM(Curve!$D$5:$D$16)
A14: =Inputs!$B$11+10*Inputs!$B$12 | B14: =SUMPRODUCT((A14>=Curve!$E$5:$E$16)*Curve!$D$5:$D$16) | C14: =B14/SUM(Curve!$D$5:$D$16)
A15: =Inputs!$B$11+11*Inputs!$B$12 | B15: =SUMPRODUCT((A15>=Curve!$E$5:$E$16)*Curve!$D$5:$D$16) | C15: =B15/SUM(Curve!$D$5:$D$16)
A16: =Inputs!$B$11+12*Inputs!$B$12 | B16: =SUMPRODUCT((A16>=Curve!$E$5:$E$16)*Curve!$D$5:$D$16) | C16: =B16/SUM(Curve!$D$5:$D$16)
A17: =Inputs!$B$11+13*Inputs!$B$12 | B17: =SUMPRODUCT((A17>=Curve!$E$5:$E$16)*Curve!$D$5:$D$16) | C17: =B17/SUM(Curve!$D$5:$D$16)
A18: =Inputs!$B$11+14*Inputs!$B$12 | B18: =SUMPRODUCT((A18>=Curve!$E$5:$E$16)*Curve!$D$5:$D$16) | C18: =B18/SUM(Curve!$D$5:$D$16)
A19: =Inputs!$B$11+15*Inputs!$B$12 | B19: =SUMPRODUCT((A19>=Curve!$E$5:$E$16)*Curve!$D$5:$D$16) | C19: =B19/SUM(Curve!$D$5:$D$16)
A20: =Inputs!$B$11+16*Inputs!$B$12 | B20: =SUMPRODUCT((A20>=Curve!$E$5:$E$16)*Curve!$D$5:$D$16) | C20: =B20/SUM(Curve!$D$5:$D$16)
A21: =Inputs!$B$11+17*Inputs!$B$12 | B21: =SUMPRODUCT((A21>=Curve!$E$5:$E$16)*Curve!$D$5:$D$16) | C21: =B21/SUM(Curve!$D$5:$D$16)
A22: =Inputs!$B$11+18*Inputs!$B$12 | B22: =SUMPRODUCT((A22>=Curve!$E$5:$E$16)*Curve!$D$5:$D$16) | C22: =B22/SUM(Curve!$D$5:$D$16)

Sheet Cross-checks
A1: Cross-checks: figures NOT used as curve inputs. APPROXIMATE - built from company disclosures and the Dallas Fed Energy Survey, US shale only, WTI basis
A3: A. Dallas Fed new-well breakeven vs operator-disclosed economics
A4: Item | B4: Value | C4: Unit | D4: Source ID
A5: Dallas Fed Q1 2026, large firms (>=10,000 b/d) / small firms new-well breakeven | B5: 59 / 68 | C5: USD/bbl WTI | D5: D7
A6: Dallas Fed Q1 2026, all responses new-well / shut-in breakeven | B6: 66 / 43 | C6: USD/bbl WTI | D6: D7, D8
A7: Permian Resources D&C cost per lateral foot, Q1 2026 | B7: 685 | C7: USD/ft | D7: O1
A8: Matador full-year 2026 D&C per completed lateral foot (midpoint of 785-805) | B8: 795 | C8: USD/ft | D8: O3
A9: Diamondback Barnett (not core) lowest well cost to date | B9: <400 | C9: USD/ft | D9: O4
A10: Chord Bakken 2-/3-/4-mile D&C per foot | B10: 710 / 568 / 532 | C10: USD/ft | D10: O5
A11: Chord Bakken 2-/3-/4-mile oil EUR | B11: 450 / 675 / 855 | C11: Mbbl | D11: O5
A12: TPL / Enverus remaining Permian locations <$60 breakeven | B12: 65000 | C12: locations | D12: T1
A13: NOG Duvernay (Canada, excluded) average breakeven | B13: <50 | C13: USD/bbl WTI | D13: O6
A16: B. Volume cross-check: STEO Permian crude production (Mb/d) at the reference month vs TPL's 4Q 2025 Permian figure (6.7)
A17: STEO Permian crude production, reference month | B17: =Inputs!$C$14
A18: TPL (EIA) Permian crude, 4Q 2025 average | B18: 6.7
A20: C. Inventory at the current pace (TPL <$60 locations / STEO completions)
A21: Basin | B21: Locations <$60 | C21: Wells completed per year | D21: Years
A22: =Inputs!$A$14 | B22: =Inputs!$M$14 | C22: =Inputs!$N$14 | D22: =Inputs!$O$14
A23: =Inputs!$A$15 | B23: =Inputs!$M$15 | C23: =Inputs!$N$15 | D23: =Inputs!$O$15
A24: =Inputs!$A$16 | B24: =Inputs!$M$16 | C24: =Inputs!$N$16 | D24: =Inputs!$O$16
A26: Caveat: the Dallas Fed averages (about $63-67 new-well) sit ABOVE TPL's $60 inventory cut-off, so most future locations need a price above the survey average only if they are weaker than the <$60 set; the two are different bases and are not combined.

Sheet Chart data
A1: Chart data (live): cost curve steps, price lines and the supply ladder. APPROXIMATE - built from company disclosures and the Dallas Fed Energy Survey, US shale only, WTI basis
A3: WTI spot | B3: ='Price context'!$B$2
A4: WTI 12-month mean | B4: ='Price context'!$B$4
A5: Brent forward M12 as WTI | B5: ='Price forwards'!$B$5-Inputs!$B$6
E6: Cost curve (Dallas Fed Q1 2026 breakevens) | G6: Same tiers, Dallas Fed Q1 2025 (prior year) | I6: WTI spot | J6: WTI, 12-month mean | K6: Brent forward M12 less spread
D7: x: cumulative volume (Mb/d) | E7: y: breakeven (Dallas Fed Q1 2026) | F7: x prior | G7: y: same tiers, Dallas Fed Q1 2025 | H7: x line | I7: y WTI spot | J7: y WTI 12-month mean | K7: y Brent M12 as WTI
D8: =0 | E8: =Curve!$E$5 | F8: =0 | G8: =Curve!$G$5 | H8: 0 | I8: =$B$3 | J8: =$B$4 | K8: =$B$5
D9: =Curve!$F$5 | E9: =Curve!$E$5 | F9: =Curve!$F$5 | G9: =Curve!$G$5 | H9: =D31 | I9: =$B$3 | J9: =$B$4 | K9: =$B$5
D10: =Curve!$F$5 | E10: =Curve!$E$6 | F10: =Curve!$F$5 | G10: =Curve!$G$6
D11: =Curve!$F$6 | E11: =Curve!$E$6 | F11: =Curve!$F$6 | G11: =Curve!$G$6
D12: =Curve!$F$6 | E12: =Curve!$E$7 | F12: =Curve!$F$6 | G12: =Curve!$G$7
D13: =Curve!$F$7 | E13: =Curve!$E$7 | F13: =Curve!$F$7 | G13: =Curve!$G$7
D14: =Curve!$F$7 | E14: =Curve!$E$8 | F14: =Curve!$F$7 | G14: =Curve!$G$8
D15: =Curve!$F$8 | E15: =Curve!$E$8 | F15: =Curve!$F$8 | G15: =Curve!$G$8
D16: =Curve!$F$8 | E16: =Curve!$E$9 | F16: =Curve!$F$8 | G16: =Curve!$G$9
D17: =Curve!$F$9 | E17: =Curve!$E$9 | F17: =Curve!$F$9 | G17: =Curve!$G$9
D18: =Curve!$F$9 | E18: =Curve!$E$10 | F18: =Curve!$F$9 | G18: =Curve!$G$10
D19: =Curve!$F$10 | E19: =Curve!$E$10 | F19: =Curve!$F$10 | G19: =Curve!$G$10
D20: =Curve!$F$10 | E20: =Curve!$E$11 | F20: =Curve!$F$10 | G20: =Curve!$G$11
D21: =Curve!$F$11 | E21: =Curve!$E$11 | F21: =Curve!$F$11 | G21: =Curve!$G$11
D22: =Curve!$F$11 | E22: =Curve!$E$12 | F22: =Curve!$F$11 | G22: =Curve!$G$12
D23: =Curve!$F$12 | E23: =Curve!$E$12 | F23: =Curve!$F$12 | G23: =Curve!$G$12
D24: =Curve!$F$12 | E24: =Curve!$E$13 | F24: =Curve!$F$12 | G24: =Curve!$G$13
D25: =Curve!$F$13 | E25: =Curve!$E$13 | F25: =Curve!$F$13 | G25: =Curve!$G$13
D26: =Curve!$F$13 | E26: =Curve!$E$14 | F26: =Curve!$F$13 | G26: =Curve!$G$14
D27: =Curve!$F$14 | E27: =Curve!$E$14 | F27: =Curve!$F$14 | G27: =Curve!$G$14
D28: =Curve!$F$14 | E28: =Curve!$E$15 | F28: =Curve!$F$14 | G28: =Curve!$G$15
D29: =Curve!$F$15 | E29: =Curve!$E$15 | F29: =Curve!$F$15 | G29: =Curve!$G$15
D30: =Curve!$F$15 | E30: =Curve!$E$16 | F30: =Curve!$F$15 | G30: =Curve!$G$16
D31: =Curve!$F$16 | E31: =Curve!$E$16 | F31: =Curve!$F$16 | G31: =Curve!$G$16
A34: Supply ladder
A35: WTI (USD/bbl) | B35: Supported volume (Mb/d)
A36: ='Supply ladder'!A4 | B36: ='Supply ladder'!B4
A37: ='Supply ladder'!A5 | B37: ='Supply ladder'!B5
A38: ='Supply ladder'!A6 | B38: ='Supply ladder'!B6
A39: ='Supply ladder'!A7 | B39: ='Supply ladder'!B7
A40: ='Supply ladder'!A8 | B40: ='Supply ladder'!B8
A41: ='Supply ladder'!A9 | B41: ='Supply ladder'!B9
A42: ='Supply ladder'!A10 | B42: ='Supply ladder'!B10
A43: ='Supply ladder'!A11 | B43: ='Supply ladder'!B11
...

Sheet Sources
A1: ID | B1: Type | C1: Item | D1: Value | E1: Unit | F1: As-of | G1: Publisher | H1: Document | I1: URL | J1: Status | K1: Used where
A2: D1 | B2: breakeven | C2: New-well breakeven, Permian Basin - Midland (average of responses) | D2: 68.57 | E2: USD/bbl WTI | F2: Q1 2026 | G2: Federal Reserve Bank of Dallas | H2: Dallas Fed Energy Survey, Q1 2026, special questions (fielded 11-19 Mar 2026, 130 firms); 14 responses | I2: https://www.dallasfed.org/-/media/Documents/research/surveys/DES/2026/2601/des26q1_charts.xlsx | J2: SOURCED | K2: Inputs (Permian average uses 'Permian all responses')
A3: D2 | B3: breakeven | C3: New-well breakeven, Permian Basin - Delaware | D3: 63.21 | E3: USD/bbl WTI | F3: Q1 2026 | G3: Federal Reserve Bank of Dallas | H3: Dallas Fed Energy Survey, Q1 2026, special questions (fielded 11-19 Mar 2026, 130 firms); 19 responses | I3: https://www.dallasfed.org/-/media/Documents/research/surveys/DES/2026/2601/des26q1_charts.xlsx | J3: SOURCED | K3: memo (range)
A4: D3 | B4: breakeven | C4: New-well breakeven, Permian Basin - Other | D4: 70 | E4: USD/bbl WTI | F4: Q1 2026 | G4: Federal Reserve Bank of Dallas | H4: Dallas Fed Energy Survey, Q1 2026, special questions (fielded 11-19 Mar 2026, 130 firms); 12 responses | I4: https://www.dallasfed.org/-/media/Documents/research/surveys/DES/2026/2601/des26q1_charts.xlsx | J4: SOURCED | K4: memo (range)
A5: D4 | B5: breakeven | C5: New-well breakeven, Permian (all responses) | D5: 67 | E5: USD/bbl WTI | F5: Q1 2026 | G5: Federal Reserve Bank of Dallas | H5: Break-even prices for U.S. oil producers - major shale plays, 'New Wells' sheet, update 25 Mar 2026 | I5: https://www.dallasfed.org/-/media/documents/research/surveys/des/documents/breakeven.xlsx | J5: SOURCED | K5: Inputs: Permian new-well breakeven
A6: D5 | B6: breakeven | C6: New-well breakeven, Eagle Ford | D6: 63 | E6: USD/bbl WTI | F6: Q1 2026 | G6: Federal Reserve Bank of Dallas | H6: Dallas Fed Energy Survey, Q1 2026, special questions (fielded 11-19 Mar 2026, 130 firms); 5 responses (small sample) | I6: https://www.dallasfed.org/-/media/Documents/research/surveys/DES/2026/2601/des26q1_charts.xlsx | J6: SOURCED | K6: Inputs: Eagle Ford
A7: D6 | B7: breakeven | C7: New-well breakeven, Other U.S. (shale) | D7: 62.38 | E7: USD/bbl WTI | F7: Q1 2026 | G7: Federal Reserve Bank of Dallas | H7: Dallas Fed Energy Survey, Q1 2026, special questions (fielded 11-19 Mar 2026, 130 firms); 17 responses | I7: https://www.dallasfed.org/-/media/Documents/research/surveys/DES/2026/2601/des26q1_charts.xlsx | J7: SOURCED | K7: Inputs: Bakken (MAPPING ASSUMPTION - no Bakken line published) and Other shale
A8: D7 | B8: breakeven | C8: New-well breakeven, all responses / large firms (>=10,000 b/d) / small firms | D8: 66 / 59 / 68 | E8: USD/bbl WTI | F8: Q1 2026 | G8: Federal Reserve Bank of Dallas | H8: Break-even page, 'New Wells' sheet | I8: https://www.dallasfed.org/-/media/documents/research/surveys/des/documents/breakeven.xlsx | J8: SOURCED | K8: Cross-checks
A9: D8 | B9: breakeven | C9: Shut-in (operating cost) breakeven: Permian all 39, Eagle Ford 40, Other shale 44.12, Midland 41.54, Delaware 33.82 | D9: 39 / 40 / 44.12 | E9: USD/bbl WTI | F9: Q1 2026 | G9: Federal Reserve Bank of Dallas | H9: Break-even page, 'Existing Wells' sheet (WTI needed to cover operating expenses for existing wells) | I9: https://www.dallasfed.org/-/media/documents/research/surveys/des/documents/breakeven.xlsx | J9: SOURCED | K9: Inputs: shut-in breakevens
A10: D9 | B10: breakeven | C10: New-well breakeven range of responses (min-max): Midland 50-90, Delaware 50-85, Permian other 50-85, Eagle Ford 50-70, Other shale 35-85 | D10: see item | E10: USD/bbl WTI | F10: Q1 2026 | G10: Federal Reserve Bank of Dallas | H10: Dallas Fed Energy Survey, Q1 2026, special questions (fielded 11-19 Mar 2026, 130 firms), 'Special Question 2' | I10: https://www.dallasfed.org/-/media/Documents/research/surveys/DES/2026/2601/des26q1_charts.xlsx | J10: SOURCED | K10: Inputs: min / max
A11: D10 | B11: breakeven | C11: Prior-year survey (Q1 2025) new-well breakeven: Permian all 65, Eagle Ford 61.67, Other shale 63; shut-in Permian all 39, Eagle Ford 25.83, Other shale 40.81 | D11: see item | E11: USD/bbl WTI | F11: Q1 2025 | G11: Federal Reserve Bank of Dallas | H11: Break-even page, history table | I11: https://www.dallasfed.org/-/media/documents/research/surveys/des/documents/breakeven.xlsx | J11: SOURCED | K11: Inputs: prior-year series
A12: D11 | B12: price expectation | C12: Dallas Fed Q3 2026 survey: respondents expect WTI $88 at year-end 2026, $79 in two years, $82 in five years (range $70-126 for year-end 2026); WTI spot averaged $98.70 during collection (16-24 Sep 2026). No breakeven question this quarter (special questions: SPR, Persian Gulf exports, fuel spreads, FCF allocation, theft) | D12: 88 / 79 / 82 | E12: USD/bbl WTI | F12: Q3 2026 | G12: Federal Reserve Bank of Dallas | H12: Dallas Fed Energy Survey, Q3 2026 | I12: https://www.dallasfed.org/research/surveys/des/2026/2603 | J12: SOURCED | K12: context only
A13: E1 | B13: volume | C13: STEO crude oil production by region: Permian, Bakken, Eagle Ford, Rest of Lower 48 (monthly, Mb/d); tight oil by formation (TOPR*) | D13: see 'STEO raw' | E13: Mb/d | F13: STEO, run date | G13: US EIA | H13: Short-Term Energy Outlook, regional oil production series (COPRPM/BK/EF/R48, TOPR*) | I13: https://api.eia.gov/v2/steo/data (EIA Short-Term Energy Outlook, regional series) | J13: SOURCED | K13: Inputs: production
A14: E2 | B14: decline | C14: STEO 'Existing Oil Production Change, One-year Trend': Permian COEOPPM, Bakken COEOPBK, Eagle Ford COEOPEF (kb/d, negative = base decline) | D14: see 'STEO raw' | E14: kb/d per year | F14: STEO, run date | G14: US EIA | H14: Short-Term Energy Outlook, regional series | I14: https://api.eia.gov/v2/steo/data (EIA Short-Term Energy Outlook, regional series) | J14: SOURCED | K14: Inputs: base decline = replacement barrels
A15: E3 | B15: activity | C15: STEO new wells completed per month (NWCPM/NWCBK/NWCEF) and new-well oil production (CONW*) | D15: see 'STEO raw' | E15: wells / month; kb/d | F15: STEO, run date | G15: US EIA | H15: Short-Term Energy Outlook, regional series | I15: https://api.eia.gov/v2/steo/data (EIA Short-Term Energy Outlook, regional series) | J15: SOURCED | K15: Inputs: inventory years
A16: T1 | B16: inventory | C16: Estimated remaining well locations with <$60/bbl breakeven economics: Permian ~65,000 (Midland + Delaware), Eagle Ford ~13,000, Williston ~5,000, Anadarko ~3,000, DJ ~3,000 (Montney ~34,000, Canada, not used); Enverus-based chart label | D16: 65,000 / 13,000 / 5,000 / 3,000 / 3,000 | E16: locations | F16: 30 Jun 2026 (deck 2Q26) | G16: Texas Pacific Land (citing Enverus, EIA, company data) | H16: 2Q 2026 TPL Investor Presentation, slide 9 (deck page 8 of text extract); also 8-K ex99.2 5 Aug 2026 | I16: https://d1io3yog0oux5.cloudfront.net/_44c0a1327e37db57b36e014028684610/texaspacific/db/706/6716/pdf/2Q+2026+TPL+Investor+Presentation+vF.pdf | J16: SOURCED (third-party chart label) | K16: Inputs: inventory locations
A17: T2 | B17: volume | C17: Permian crude production 6.7 MMb/d (4Q 2025 average) per TPL / EIA | D17: 6.7 | E17: Mb/d | F17: 4Q 2025 | G17: Texas Pacific Land (citing EIA) | H17: 2Q 2026 TPL Investor Presentation | I17: https://d1io3yog0oux5.cloudfront.net/_44c0a1327e37db57b36e014028684610/texaspacific/db/706/6716/pdf/2Q+2026+TPL+Investor+Presentation+vF.pdf | J17: SOURCED | K17: Cross-check of STEO Permian
A18: O1 | B18: well cost | C18: Permian Resources D&C cost per lateral foot, Q1 2026 (Q4 2025 ~$700, -14% vs 2024) | D18: 685 | E18: USD per lateral ft | F18: Q1 2026 | G18: Permian Resources | H18: Q1 2026 earnings release (8-K ex99.1, 6 May 2026) | I18: https://www.sec.gov/Archives/edgar/data/1658566/000165856626000069/ex991prq12026earningsrelea.htm | J18: SOURCED | K18: Cross-checks
A19: O2 | B19: guidance | C19: Permian Resources Q2 2026 average daily oil production | D19: 198071 | E19: bbl/d | F19: Q2 2026 | G19: Permian Resources | H19: Q2 2026 earnings release (8-K ex99.1, 5 Aug 2026) | I19: https://www.sec.gov/Archives/edgar/data/1658566/000165856626000094/ex991prq22026earningsrelea.htm | J19: SOURCED | K19: Cross-checks
A20: O3 | B20: well cost | C20: Matador full-year 2026 D&C cost estimate $785-805 per completed lateral foot ($795 midpoint); Q3 adjacent assets as low as $640 per foot; total 2026 capex midpoint $1.675 bn | D20: 785-805 | E20: USD per completed lateral ft | F20: Q2 2026 | G20: Matador Resources | H20: Q2 2026 earnings release (8-K ex99.1, 5 Aug 2026) | I20: https://www.sec.gov/Archives/edgar/data/1520006/000152000626000036/a20260630mtdr8ker-ex991.htm | J20: SOURCED | K20: Cross-checks
A21: O4 | B21: well cost | C21: Diamondback: lowest Barnett well cost to date under $400 per lateral foot (Barnett; not the Wolfcamp core); 2026 total capex raised to ~$3.9 bn (from ~$3.75 bn), operated D&C ~$3.31 bn, average lateral ~12,900 ft | D21: <400 | E21: USD per lateral ft | F21: Q1 / Q2 2026 | G21: Diamondback Energy | H21: Q1 2026 (8-K ex99.2, 4 May 2026) and Q2 2026 (8-K ex99.1, 3 Aug 2026) releases | I21: https://www.sec.gov/Archives/edgar/data/1539838/000153983826000073/diamondbackex992-5x4x26.htm | J21: SOURCED | K21: Cross-checks
A22: O5 | B22: EUR / well cost | C22: Chord (Bakken, Western Extension case study, Feb 2026 capital assumptions): 2-/3-/4-mile well cost $7.1 / $8.5 / $10.7 MM ($710 / $568 / $532 per ft); oil EUR 450 / 675 / 855 Mbbl (45 / 45 / 43 bbl per ft); F&D $15.78 / $12.62 / $12.46 per bbl. Chord also says 10+ years of low-breakeven inventory (no number) and a >10% improvement in weighted-average inventory breakeven in 2025 | D22: see item | E22: USD; Mbbl | F22: Aug 2026 deck | G22: Chord Energy | H22: 2Q26 Earnings Presentation, 5 Aug 2026 (slides 13-15, 4-mile program) | I22: https://ir.chordenergy.com/image/CHRD-2Q26-Earnings-Presentation.pdf | J22: SOURCED | K22: Cross-checks
A23: O6 | B23: breakeven | C23: Northern Oil & Gas: ~500 gross Duvernay locations with average breakevens below $50 WTI (ALBERTA, Canada - NOT US shale, excluded from the curve) | D23: <50 | E23: USD/bbl WTI | F23: 26 May 2026 | G23: Northern Oil and Gas | H23: 8-K ex99.1, acquisition release | I23: https://www.sec.gov/Archives/edgar/data/1104485/000119312526237800/d11850dex991.htm | J23: SOURCED (excluded) | K23: none
A24: X1 | B24: well cost | C24: EIA 'Trends in U.S. Oil and Natural Gas Upstream Costs' (IHS study): well costs by play 2006-2015, forecast to 2018 | D24: n/a | E24: USD | F24: Mar 2016 | G24: US EIA / IHS | H24: Upstream cost study | I24: https://www.eia.gov/analysis/studies/drilling/pdf/upstream.pdf | J24: OPENED - too old | K24: not used (a decade old; costs and well design have changed)

Sheet Not reachable
A1: Source | B1: What happened (Actions, 6 Oct 2026)
A2: Operator decks with a numeric breakeven (Diamondback, Devon, Occidental, EOG, Coterra, Civitas, Ovintiv, Chevron, ExxonMobil, APA, SM, Crescent, HighPeak, Vital) | B2: Opened their SEC 10-K / 10-Q / 2026 8-K exhibits (keyword windows in discovery_archive/results/oil/): no numeric new-well breakeven in the text. Most give breakevens only in investor-deck charts or footnotes: IR pages for Diamondback, Devon, Permian Resources, Coterra, Matador (hosts did not resolve or no PDF link found), Civitas, SM, Crescent, Magnolia, NOG (DNS failure from Actions), Ovintiv, Chevron, Exxon (404), Occidental and HighPeak (page opens, no deck link found). EOG's only deck link found is Feb 2024 (stale). Not read: numbers in chart images.
A3: Permian Resources, Devon, EOG tier-1 inventory in years | B3: Press releases and 10-Ks opened; inventory life is stated qualitatively, not as locations plus years, in the text extracted.
A4: Kansas City Fed Energy Survey | B4: Page opened (kansascityfed.org/surveys/energy-survey/); quarterly activity indices and price expectations only, no breakeven question found.
A5: EIA AEO supply module notes (OGSM) | B5: Opened (eia.gov OGSM_Assumptions.pdf): methodology for well economics (IP, decline, discount) but no breakeven table by basin.
A6: IEA Oil 2026, OPEC World Oil Outlook, Rystad, Enverus public pages | B6: IEA and OPEC pages did not return a document from Actions; Rystad news page and Enverus blog opened with navigation text only, no breakeven figures. Paid curves (Rystad, Enverus) are not public: paste your own into the override columns on 'Inputs'.
A7: Dallas Fed Energy Survey by operator | B7: The survey is anonymous: basin averages, min and max only; no per-company breakevens.

Sheet Snippets (unused)
A1: Status | B1: Claim seen | C1: Why not used
A2: SNIPPET - unopened | B2: Diamondback 2026 production guidance 500-510 MBO/d (web search result, Feb 2026 release not opened) | C2: Not used
A3: SNIPPET - unopened | B3: Permian Resources year-to-date acquisitions struck at a weighted-average front-month WTI of $72.50 per barrel (web search summary) | C3: Not used
A4: SNIPPET - unopened | B4: Devon Q2 2026: 1,359 MBoe/d total and 503 kb/d oil at the top of guidance (web search summary; press release PDF not opened) | C4: Not used

Sheet Dallas Fed
A1: Dallas Fed basin (USD/bbl WTI, average of responses) | B1: Shut-in breakeven Q1 2026 | C1: Shut-in breakeven Q1 2025 | D1: New-well breakeven Q1 2026 | E1: New-well breakeven Q1 2025
A2: Permian Basin - Midland | B2: 41.54 | C2: 35.44 | D2: 68.57 | E2: 60.56
A3: Permian Basin - Delaware | B3: 33.82 | C3: 33.03 | D3: 63.21 | E3: 62.22
A4: Permian Basin - Other | B4: 43.63 | C4: 45.15 | D4: 70 | E4: 69.75
A5: Permian (all responses) | B5: 39 | C5: 39 | D5: 67 | E5: 65
A6: Eagle Ford | B6: 40 | C6: 25.83 | D6: 63 | E6: 61.67
A7: Other U.S. (Shale) | B7: 44.12 | C7: 40.81 | D7: 62.38 | E7: 63
A8: Other U.S. (Nonshale) | B8: 47 | C8: 44.62 | D8: 67.82 | E8: 65.77
A9: All responses | B9: 43 | C9: 41 | D9: 66 | E9: 65
A10: Large firms (>=10,000 b/d) | B10: 32 | C10: 31 | D10: 59 | E10: 61
A11: Small firms (<10,000 b/d) | B11: 46 | C11: 44 | D11: 68 | E11: 66

Sheet Dallas Fed history
A1: New-well breakeven by Q1 survey (USD/bbl WTI) | B1: 2017:Q1 | C1: 2018:Q1 | D1: 2019:Q1 | E1: 2020:Q1 | F1: 2021:Q1 | G1: 2022:Q1 | H1: 2023:Q1 | I1: 2024:Q1 | J1: 2025:Q1 | K1: 2026:Q1
A2: Permian Basin - Midland | B2: 46 | C2: 47.33 | D2: 47.5 | E2: 45.57 | F2: 45.8 | G2: 51.29 | H2: 58.33 | I2: 61.61 | J2: 60.56 | K2: 68.57
A3: Permian Basin - Delaware | B3: 48 | C3: 48.92 | D3: 48.69 | E3: 51.56 | F3: 49.25 | G3: 49.74 | H3: 60.71 | I3: 63.81 | J3: 62.22 | K3: 63.21
A4: Eagle Ford | B4: 47.5 | D4: 51.27 | E4: 46 | F4: 46.25 | G4: 48 | H4: 56.43 | J4: 61.67 | K4: 63
A5: Other U.S. (Shale) | B5: 55.25 | C5: 53.57 | D5: 48.5 | E5: 51 | F5: 58.06 | G5: 68.7 | H5: 60.91 | I5: 59.41 | J5: 63 | K5: 62.38
A6: Permian (all responses) | B6: 48 | C6: 50 | D6: 50 | E6: 49 | F6: 50 | G6: 52 | H6: 61 | I6: 65 | J6: 65 | K6: 67
A7: All responses | B7: 50 | C7: 52 | D7: 50 | E7: 49 | F7: 52 | G7: 56 | H7: 62 | I7: 64 | J7: 65 | K7: 66

Sheet STEO raw
A1: key | B1: id | C1: period | D1: value | E1: description | F1: unit
A2: COEOPBK|2025-01 | B2: COEOPBK | C2: 2025-01 | D2: -66.22617992 | E2: Bakken Existing Oil Production Change, One-year Trend | F2: thousand barrels per day
A3: COEOPBK|2025-02 | B3: COEOPBK | C3: 2025-02 | D3: -64.31499151 | E3: Bakken Existing Oil Production Change, One-year Trend | F3: thousand barrels per day
A4: COEOPBK|2025-03 | B4: COEOPBK | C4: 2025-03 | D4: -61.90378453 | E4: Bakken Existing Oil Production Change, One-year Trend | F4: thousand barrels per day
A5: COEOPBK|2025-04 | B5: COEOPBK | C5: 2025-04 | D5: -60.84300047 | E5: Bakken Existing Oil Production Change, One-year Trend | F5: thousand barrels per day
A6: COEOPBK|2025-05 | B6: COEOPBK | C6: 2025-05 | D6: -61.65699664 | E6: Bakken Existing Oil Production Change, One-year Trend | F6: thousand barrels per day
A7: COEOPBK|2025-06 | B7: COEOPBK | C7: 2025-06 | D7: -63.24702789 | E7: Bakken Existing Oil Production Change, One-year Trend | F7: thousand barrels per day
A8: COEOPBK|2025-07 | B8: COEOPBK | C8: 2025-07 | D8: -65.00153383 | E8: Bakken Existing Oil Production Change, One-year Trend | F8: thousand barrels per day
A9: COEOPBK|2025-08 | B9: COEOPBK | C9: 2025-08 | D9: -68.09203165 | E9: Bakken Existing Oil Production Change, One-year Trend | F9: thousand barrels per day
A10: COEOPBK|2025-09 | B10: COEOPBK | C10: 2025-09 | D10: -70.30650167 | E10: Bakken Existing Oil Production Change, One-year Trend | F10: thousand barrels per day
A11: COEOPBK|2025-10 | B11: COEOPBK | C11: 2025-10 | D11: -71.16792535 | E11: Bakken Existing Oil Production Change, One-year Trend | F11: thousand barrels per day
A12: COEOPBK|2025-11 | B12: COEOPBK | C12: 2025-11 | D12: -71.25007571 | E12: Bakken Existing Oil Production Change, One-year Trend | F12: thousand barrels per day
... A265: COPRR48|2027-12 | B265: COPRR48 | C265: 2027-12 | D265: 2.15894052 | E265: Crude Oil Production: Rest of Lower 48 States | F265: million barrels per day
A266: NWCBK|2025-01 | B266: NWCBK | C266: 2025-01 | D266: 40 | E266: Bakken New Wells Completed
A267: NWCBK|2025-02 | B267: NWCBK | C267: 2025-02 | D267: 37 | E267: Bakken New Wells Completed
A268: NWCBK|2025-03 | B268: NWCBK | C268: 2025-03 | D268: 69 | E268: Bakken New Wells Completed
A269: NWCBK|2025-04 | B269: NWCBK | C269: 2025-04 | D269: 83 | E269: Bakken New Wells Completed
A270: NWCBK|2025-05 | B270: NWCBK | C270: 2025-05 | D270: 73 | E270: Bakken New Wells Completed
A271: NWCBK|2025-06 | B271: NWCBK | C271: 2025-06 | D271: 84 | E271: Bakken New Wells Completed
A272: NWCBK|2025-07 | B272: NWCBK | C272: 2025-07 | D272: 72 | E272: Bakken New Wells Completed
A273: NWCBK|2025-08 | B273: NWCBK | C273: 2025-08 | D273: 67 | E273: Bakken New Wells Completed
A274: NWCBK|2025-09 | B274: NWCBK | C274: 2025-09 | D274: 80 | E274: Bakken New Wells Completed
A275: NWCBK|2025-10 | B275: NWCBK | C275: 2025-10 | D275: 75 | E275: Bakken New Wells Completed
A276: NWCBK|2025-11 | B276: NWCBK | C276: 2025-11 | D276: 63 | E276: Bakken New Wells Completed
A277: NWCBK|2025-12 | B277: NWCBK | C277: 2025-12 | D277: 62 | E277: Bakken New Wells Completed
... A385: RIGSPM|2026-08 | B385: RIGSPM | C385: 2026-08 | D385: 265.5 | E385: Permian Active Rigs
A386: TOPRAC|2025-01 | B386: TOPRAC | C386: 2025-01 | D386: .119 | E386: Tight oil production from Austin Chalk formation | F386: million barrels per day
A387: TOPRAC|2025-02 | B387: TOPRAC | C387: 2025-02 | D387: .118 | E387: Tight oil production from Austin Chalk formation | F387: million barrels per day
A388: TOPRAC|2025-03 | B388: TOPRAC | C388: 2025-03 | D388: .12 | E388: Tight oil production from Austin Chalk formation | F388: million barrels per day
A389: TOPRAC|2025-04 | B389: TOPRAC | C389: 2025-04 | D389: .126 | E389: Tight oil production from Austin Chalk formation | F389: million barrels per day
A390: TOPRAC|2025-05 | B390: TOPRAC | C390: 2025-05 | D390: .119 | E390: Tight oil production from Austin Chalk formation | F390: million barrels per day
A391: TOPRAC|2025-06 | B391: TOPRAC | C391: 2025-06 | D391: .114 | E391: Tight oil production from Austin Chalk formation | F391: million barrels per day
A392: TOPRAC|2025-07 | B392: TOPRAC | C392: 2025-07 | D392: .113 | E392: Tight oil production from Austin Chalk formation | F392: million barrels per day
A393: TOPRAC|2025-08 | B393: TOPRAC | C393: 2025-08 | D393: .116 | E393: Tight oil production from Austin Chalk formation | F393: million barrels per day
A394: TOPRAC|2025-09 | B394: TOPRAC | C394: 2025-09 | D394: .125 | E394: Tight oil production from Austin Chalk formation | F394: million barrels per day
A395: TOPRAC|2025-10 | B395: TOPRAC | C395: 2025-10 | D395: .128 | E395: Tight oil production from Austin Chalk formation | F395: million barrels per day
A396: TOPRAC|2025-11 | B396: TOPRAC | C396: 2025-11 | D396: .127 | E396: Tight oil production from Austin Chalk formation | F396: million barrels per day
A397: TOPRAC|2025-12 | B397: TOPRAC | C397: 2025-12 | D397: .125 | E397: Tight oil production from Austin Chalk formation | F397: million barrels per day
... A565: TOPRWF|2026-08 | B565: TOPRWF | C565: 2026-08 | D565: .08 | E565: Tight oil production from Woodford formation | F565: million barrels per day

Sheet Price context
B1: Value
A2: WTI spot, last (USD/bbl) | B2: 96.16
A3: Last date | B3: 2026-09-29
A4: WTI last 12 months mean | B4: 78.733574
A5: WTI last 12 months min | B5: 55.44
A6: WTI last 12 months max | B6: 114.58
A7: Brent-WTI spread used (Inputs) | B7: 4.22
A8: Brent forward M12 as WTI | B8: 79.28
A9: Brent forward M24 as WTI | B9: 71.47

Sheet Price forwards
A1: Contract | B1: Brent forward USD/bbl | C1: As of trade date
A2: M1 | B2: 100.32 | C2: 2026-10-05
A3: M3 | B3: 95.360001 | C3: 2026-10-05
A4: M6 | B4: 90.589996 | C4: 2026-10-05
A5: M12 | B5: 83.5 | C5: 2026-10-05
A6: M18 | B6: 78.52 | C6: 2026-10-02
A7: M24 | B7: 75.69 | C7: 2026-10-02

Sheet Spread options
B1: Brent less WTI (USD/bbl)
A2: Latest day | B2: 17.8
A3: Last 12 months mean | B3: 7.3906122
A4: 2021-2025 mean | B4: 4.2204505
A5: 2015-2025 mean | B5: 4.0428205
A6: 2015-2025 median | B6: 3.725

Sheet Curve values
A1: Rank | B1: Tier (sorted by breakeven) | C1: Kind | D1: Basin | E1: Volume (Mb/d) | F1: Breakeven (USD/bbl WTI) | G1: Cumulative volume (Mb/d) | H1: Prior-year breakeven (Dallas Q1 2025)
A2: 1 | B2: Permian - base (existing wells after the decline) | C2: Base | D2: Permian | E2: 6.299099 | F2: 39 | G2: 6.299099 | H2: 39
A3: 2 | B3: Eagle Ford - base (existing wells after the decline) | C3: Base | D3: Eagle Ford | E3: 1.061648 | F3: 40 | G3: 7.3607469 | H3: 25.83
A4: 3 | B4: Bakken - base (existing wells after the decline) | C4: Base | D4: Bakken | E4: 1.1304195 | F4: 44.12 | G4: 8.4911664 | H4: 40.81
A5: 4 | B5: Other shale - base (existing wells after the decline) | C5: Base | D5: Other shale (Niobrara, Anadarko, Austin Chalk, other) | E5: 1.0381765 | F5: 44.12 | G5: 9.5293429 | H5: 40.81
A6: 5 | B6: Bakken - replacement (new wells to offset the decline) | C6: Replacement | D6: Bakken | E6: 0.071793975 | F6: 62.38 | G6: 9.6011369 | H6: 63
A7: 6 | B7: Bakken - growth (STEO base case to horizon) | C7: Growth | D7: Bakken | E7: 0.024692327 | F7: 62.38 | G7: 9.6258292 | H7: 63
A8: 7 | B8: Other shale - replacement (new wells to offset the decline) | C8: Replacement | D8: Other shale (Niobrara, Anadarko, Austin Chalk, other) | E8: 0.0768235 | F8: 62.38 | G8: 9.7026527 | H8: 63
A9: 8 | B9: Other shale - growth (STEO base case to horizon) | C9: Growth | D9: Other shale (Niobrara, Anadarko, Austin Chalk, other) | E9: 0 | F9: 62.38 | G9: 9.7026527 | H9: 63
A10: 9 | B10: Eagle Ford - replacement (new wells to offset the decline) | C10: Replacement | D10: Eagle Ford | E10: 0.085572812 | F10: 63 | G10: 9.7882255 | H10: 61.67
A11: 10 | B11: Eagle Ford - growth (STEO base case to horizon) | C11: Growth | D11: Eagle Ford | E11: 0.07778224 | F11: 63 | G11: 9.8660078 | H11: 61.67
A12: 11 | B12: Permian - replacement (new wells to offset the decline) | C12: Replacement | D12: Permian | E12: 0.4909138 | F12: 67 | G12: 10.356922 | H12: 65
A13: 12 | B13: Permian - growth (STEO base case to horizon) | C13: Growth | D13: Permian | E13: 0.44582581 | F13: 67 | G13: 10.802747 | H13: 65

Sheet Mapping values
A1: scenario | B1: price | C1: vol_in | D1: n_in | E1: share | F1: marginal | G1: cushion
A2: Spot WTI (29 Sep 2026) | B2: 96.16 | C2: 10.802747 | D2: 12 | E2: 1 | F2: 67 | G2: 29.16
A3: Spot WTI (29 Sep 2026) - 10 | B3: 86.16 | C3: 10.802747 | D3: 12 | E3: 1 | F3: 67 | G3: 19.16
A4: Spot WTI (29 Sep 2026) + 10 | B4: 106.16 | C4: 10.802747 | D4: 12 | E4: 1 | F4: 67 | G4: 39.16
A5: WTI, 12-month average | B5: 78.733574 | C5: 10.802747 | D5: 12 | E5: 1 | F5: 67 | G5: 11.733574
A6: WTI, 12-month average - 10 | B6: 68.733574 | C6: 10.802747 | D6: 12 | E6: 1 | F6: 67 | G6: 1.7335743
A7: WTI, 12-month average + 10 | B7: 88.733574 | C7: 10.802747 | D7: 12 | E7: 1 | F7: 67 | G7: 21.733574
A8: Brent forward M12 less spread | B8: 79.28 | C8: 10.802747 | D8: 12 | E8: 1 | F8: 67 | G8: 12.28
A9: Brent forward M12 less spread - 10 | B9: 69.28 | C9: 10.802747 | D9: 12 | E9: 1 | F9: 67 | G9: 2.28
A10: Brent forward M12 less spread + 10 | B10: 89.28 | C10: 10.802747 | D10: 12 | E10: 1 | F10: 67 | G10: 22.28
A11: Brent forward M24 less spread | B11: 71.47 | C11: 10.802747 | D11: 12 | E11: 1 | F11: 67 | G11: 4.47
A12: Brent forward M24 less spread - 10 | B12: 61.47 | C12: 9.5293429 | D12: 4 | E12: 0.88212217 | F12: 44.12 | G12: -5.53
A13: Brent forward M24 less spread + 10 | B13: 81.47 | C13: 10.802747 | D13: 12 | E13: 1 | F13: 67 | G13: 14.47

Sheet Ladder values
A1: WTI | B1: supply
A2: 30 | B2: 0
A3: 35 | B3: 0
A4: 40 | B4: 7.3607469
A5: 45 | B5: 9.5293429
A6: 50 | B6: 9.5293429
A7: 55 | B7: 9.5293429
A8: 60 | B8: 9.5293429
A9: 65 | B9: 9.8660078
A10: 70 | B10: 10.802747
A11: 75 | B11: 10.802747
A12: 80 | B12: 10.802747
A13: 85 | B13: 10.802747
... A20: 120 | B20: 10.802747
