Workbook

Sheet Units
A1: Notes
A2: UNITS
A3: All flow sheets are in Bcf/d (billion cubic feet per day) = EIA monthly MMcf / days in the month / 1000. 'Raw MMcf' holds EIA's own monthly volumes (the history store).
A5: SOURCE
A6: EIA Natural Gas Monthly via EIA API v2 (https://api.eia.gov/v2/natural-gas/): cons/sum (consumption by sector, area STX), prod/sum, stor/sum, move/poe2 (exports by port of exit).
A7: https://www.eia.gov/dnav/ng/ng_cons_sum_dcu_STX_m.htm | https://www.eia.gov/dnav/ng/ng_move_poe2_a_EPG0_ENP_Mmcf_m.htm
A9: COVERAGE AND LAG
A10: Latest month by source: consumption Jul 2026, production Jul 2026, storage Jul 2026, Mexico pipeline exports Jul 2026, LNG exports Jul 2026. EIA's state consumption lags about 2-3 months; the latest months are revised.
A11: Each run refetches only months after the last saved one, minus a 3-month revision window.
A13: WITHHELD SERIES
A14: EIA publishes no Texas lease and plant fuel (VGL), pipeline and distribution use (VGP) or total consumption (VC0): those columns are blank. 'Reported total' is EIA's
A15: Delivered to Consumers (VGT) = electric power + industrial + residential + commercial + vehicle fuel.
... A37: Demand incl. LNG = EIA consumption by sector (electric power, industrial, residential, commercial, vehicle fuel) + LNG feedgas; Mexico pipeline exports are separate.

Sheet Chart
A1: Date | B1: Electric power | C1: Industrial | D1: Residential | E1: Commercial | F1: Vehicle fuel | G1: LNG feedgas (exports x 1.09) | H1: Total incl. LNG, LNG delayed 6 months | I1: Pipeline exports to Mexico (not in stack)
A2: 44197 | B2: ='Forecast'!S6 | C2: ='Forecast'!T6 | D2: ='Forecast'!U6 | E2: ='Forecast'!V6 | F2: ='Forecast'!W6 | G2: ='Forecast'!I6 | H2: ='Forecast'!AA6 | I2: ='Forecast'!Y6
A3: 44228 | B3: ='Forecast'!S7 | C3: ='Forecast'!T7 | D3: ='Forecast'!U7 | E3: ='Forecast'!V7 | F3: ='Forecast'!W7 | G3: ='Forecast'!I7 | H3: ='Forecast'!AA7 | I3: ='Forecast'!Y7
A4: 44256 | B4: ='Forecast'!S8 | C4: ='Forecast'!T8 | D4: ='Forecast'!U8 | E4: ='Forecast'!V8 | F4: ='Forecast'!W8 | G4: ='Forecast'!I8 | H4: ='Forecast'!AA8 | I4: ='Forecast'!Y8
A5: 44287 | B5: ='Forecast'!S9 | C5: ='Forecast'!T9 | D5: ='Forecast'!U9 | E5: ='Forecast'!V9 | F5: ='Forecast'!W9 | G5: ='Forecast'!I9 | H5: ='Forecast'!AA9 | I5: ='Forecast'!Y9
A6: 44317 | B6: ='Forecast'!S10 | C6: ='Forecast'!T10 | D6: ='Forecast'!U10 | E6: ='Forecast'!V10 | F6: ='Forecast'!W10 | G6: ='Forecast'!I10 | H6: ='Forecast'!AA10 | I6: ='Forecast'!Y10
A7: 44348 | B7: ='Forecast'!S11 | C7: ='Forecast'!T11 | D7: ='Forecast'!U11 | E7: ='Forecast'!V11 | F7: ='Forecast'!W11 | G7: ='Forecast'!I11 | H7: ='Forecast'!AA11 | I7: ='Forecast'!Y11
A8: 44378 | B8: ='Forecast'!S12 | C8: ='Forecast'!T12 | D8: ='Forecast'!U12 | E8: ='Forecast'!V12 | F8: ='Forecast'!W12 | G8: ='Forecast'!I12 | H8: ='Forecast'!AA12 | I8: ='Forecast'!Y12
A9: 44409 | B9: ='Forecast'!S13 | C9: ='Forecast'!T13 | D9: ='Forecast'!U13 | E9: ='Forecast'!V13 | F9: ='Forecast'!W13 | G9: ='Forecast'!I13 | H9: ='Forecast'!AA13 | I9: ='Forecast'!Y13
A10: 44440 | B10: ='Forecast'!S14 | C10: ='Forecast'!T14 | D10: ='Forecast'!U14 | E10: ='Forecast'!V14 | F10: ='Forecast'!W14 | G10: ='Forecast'!I14 | H10: ='Forecast'!AA14 | I10: ='Forecast'!Y14
A11: 44470 | B11: ='Forecast'!S15 | C11: ='Forecast'!T15 | D11: ='Forecast'!U15 | E11: ='Forecast'!V15 | F11: ='Forecast'!W15 | G11: ='Forecast'!I15 | H11: ='Forecast'!AA15 | I11: ='Forecast'!Y15
A12: 44501 | B12: ='Forecast'!S16 | C12: ='Forecast'!T16 | D12: ='Forecast'!U16 | E12: ='Forecast'!V16 | F12: ='Forecast'!W16 | G12: ='Forecast'!I16 | H12: ='Forecast'!AA16 | I12: ='Forecast'!Y16
A13: 44531 | B13: ='Forecast'!S17 | C13: ='Forecast'!T17 | D13: ='Forecast'!U17 | E13: ='Forecast'!V17 | F13: ='Forecast'!W17 | G13: ='Forecast'!I17 | H13: ='Forecast'!AA17 | I13: ='Forecast'!Y17
... A97: 47088 | B97: ='Forecast'!S101 | C97: ='Forecast'!T101 | D97: ='Forecast'!U101 | E97: ='Forecast'!V101 | F97: ='Forecast'!W101 | G97: ='Forecast'!I101 | H97: ='Forecast'!AA101 | I97: ='Forecast'!Y101

Sheet Chart - LNG forecast
A1: Date | B1: History (EIA exports x 1.09) | C1: Base forecast | D1: Delayed forecast (+6 months)
A2: 44197 | B2: ='Forecast'!I6
A3: 44228 | B3: ='Forecast'!I7
A4: 44256 | B4: ='Forecast'!I8
A5: 44287 | B5: ='Forecast'!I9
A6: 44317 | B6: ='Forecast'!I10
A7: 44348 | B7: ='Forecast'!I11
A8: 44378 | B8: ='Forecast'!I12
A9: 44409 | B9: ='Forecast'!I13
A10: 44440 | B10: ='Forecast'!I14
A11: 44470 | B11: ='Forecast'!I15
A12: 44501 | B12: ='Forecast'!I16
A13: 44531 | B13: ='Forecast'!I17
... A67: 46174 | B67: ='Forecast'!I71
A68: 46204 | B68: ='Forecast'!I72 | C68: ='Forecast'!I72 | D68: ='Forecast'!P72
A69: 46235 | C69: ='Forecast'!I73 | D69: ='Forecast'!P73
A70: 46266 | C70: ='Forecast'!I74 | D70: ='Forecast'!P74
A71: 46296 | C71: ='Forecast'!I75 | D71: ='Forecast'!P75
A72: 46327 | C72: ='Forecast'!I76 | D72: ='Forecast'!P76
A73: 46357 | C73: ='Forecast'!I77 | D73: ='Forecast'!P77
A74: 46388 | C74: ='Forecast'!I78 | D74: ='Forecast'!P78
A75: 46419 | C75: ='Forecast'!I79 | D75: ='Forecast'!P79
A76: 46447 | C76: ='Forecast'!I80 | D76: ='Forecast'!P80
A77: 46478 | C77: ='Forecast'!I81 | D77: ='Forecast'!P81
A78: 46508 | C78: ='Forecast'!I82 | D78: ='Forecast'!P82
A79: 46539 | C79: ='Forecast'!I83 | D79: ='Forecast'!P83
A80: 46569 | C80: ='Forecast'!I84 | D80: ='Forecast'!P84
... A97: 47088 | C97: ='Forecast'!I101 | D97: ='Forecast'!P101

Sheet Chart - Consumption
A1: Date | B1: Electric power | C1: Industrial | D1: Residential | E1: Commercial | F1: Vehicle fuel
A2: 44197 | B2: 3.6716129 | C2: 5.7480968 | D2: 1.4571935 | E2: 0.79477419 | F2: 0.0025806452
A3: 44228 | B3: 4.4955 | C3: 4.7495714 | D3: 1.7995 | E3: 0.92478571 | F3: 0.0025714286
A4: 44256 | B4: 2.8735806 | C4: 4.8493871 | D4: 0.85125806 | E4: 0.54774194 | F4: 0.0025806452
A5: 44287 | B5: 3.7462333 | C5: 5.2871667 | D5: 0.41103333 | E5: 0.47443333 | F5: 0.0025666667
A6: 44317 | B6: 3.8437742 | C6: 5.2347742 | D6: 0.28316129 | E6: 0.35129032 | F6: 0.0025806452
A7: 44348 | B7: 5.7511667 | C7: 5.2962667 | D7: 0.2299 | E7: 0.3627 | F7: 0.0025666667
A8: 44378 | B8: 6.234871 | C8: 5.4228387 | D8: 0.21525806 | E8: 0.37116129 | F8: 0.0025806452
A9: 44409 | B9: 6.3270968 | C9: 5.4585161 | D9: 0.19941935 | E9: 0.36603226 | F9: 0.0025806452
A10: 44440 | B10: 5.2986667 | C10: 5.5180667 | D10: 0.20026667 | E10: 0.37056667 | F10: 0.0025666667
A11: 44470 | B11: 4.4126129 | C11: 5.2626774 | D11: 0.25693548 | E11: 0.38735484 | F11: 0.0025806452
A12: 44501 | B12: 3.4576 | C12: 5.6497 | D12: 0.53843333 | E12: 0.51293333 | F12: 0.0025666667
A13: 44531 | B13: 3.3782903 | C13: 5.7833226 | D13: 0.58916129 | E13: 0.53209677 | F13: 0.0025806452
... A68: 46204 | B68: 7.6218065 | C68: 5.5193548 | D68: 0.21764516 | E68: 0.37412903 | F68: 0.0061935484

Sheet Chart - Exports
A1: Date | B1: Pipeline to Mexico | C1: Corpus Christi LNG | D1: El Paso LNG | E1: Freeport LNG | F1: Golden Pass LNG | G1: Laredo LNG
A2: 44197 | B2: 2.5524839 | C2: 1.8456774 | E2: 1.9710645 | G2: 0.002483871
A3: 44228 | B3: 2.2524286 | C3: 1.1903571 | E3: 1.08825 | G3: 0.0019642857
A4: 44256 | B4: 2.6439355 | C4: 2.0190645 | E4: 2.0524194 | G4: 0.00029032258
A5: 44287 | B5: 2.6702333 | C5: 1.9953667 | E5: 2.0208333 | G5: 0.0004
A6: 44317 | B6: 2.7663226 | C6: 1.8957419 | E6: 2.0391613 | G6: 0.00087096774
A7: 44348 | B7: 2.9299333 | C7: 2.0512 | E7: 1.9513 | G7: 0.0029
A8: 44378 | B8: 2.8761935 | C8: 1.950871 | E8: 1.9645484 | G8: 0.0025483871
A9: 44409 | B9: 2.8028065 | C9: 1.9919032 | E9: 2.1169677 | G9: 0.0041290323
A10: 44440 | B10: 2.6138 | C10: 2.1464 | E10: 1.6184 | G10: 0.0045
A11: 44470 | B11: 2.767871 | C11: 2.0914516 | E11: 1.9367097 | G11: 0.0053870968
A12: 44501 | B12: 2.5575667 | C12: 2.1165 | E12: 1.4647 | G12: 0.0049666667
A13: 44531 | B13: 2.4057419 | C13: 2.0637097 | E13: 2.1697742 | G13: 0.0044193548
... A19: 44713 | B19: 2.6740667 | C19: 2.1240333 | E19: 0.57743333 | G19: 0.0032666667
A20: 44743 | B20: 2.8176774 | C20: 2.034871 | G20: 0.0022258065
A21: 44774 | B21: 2.7909032 | C21: 2.0454194 | G21: 0.0028387097
A22: 44805 | B22: 2.7599333 | C22: 1.9937 | G22: 0.0031333333
A23: 44835 | B23: 2.7406774 | C23: 2.1543871 | G23: 0.0056129032
A24: 44866 | B24: 2.7509667 | C24: 1.9009333 | G24: 0.005
A25: 44896 | B25: 2.5235161 | C25: 2.0683548 | D25: 3.2258065e-05 | G25: 0.0051612903
A26: 44927 | B26: 2.7077419 | C26: 2.0183226 | G26: 0.0042903226
A27: 44958 | B27: 2.7075714 | C27: 2.2897857 | D27: 3.5714286e-05 | E27: 0.41271429 | G27: 0.00375
A28: 44986 | B28: 2.8560645 | C28: 2.165871 | E28: 0.93487097 | G28: 0.0030967742
A29: 45017 | B29: 2.7527667 | C29: 1.8517 | E29: 2.0839333 | G29: 0.0019333333
A30: 45047 | B30: 2.9399677 | C30: 1.8625806 | E30: 2.2066452 | G30: 0.00083870968
A31: 45078 | B31: 3.368 | C31: 2.0816667 | E31: 2.1095667 | G31: 0.0011333333
A32: 45108 | B32: 3.1230968 | C32: 1.8915806 | E32: 1.9200645 | G32: 0.00080645161
A33: 45139 | B33: 3.1732258 | C33: 2.014 | E33: 1.9818065 | G33: 0.00061290323
A34: 45170 | B34: 3.1247333 | C34: 1.9786333 | E34: 1.8007 | G34: 0.0011666667
A35: 45200 | B35: 3.0543871 | C35: 2.0446774 | E35: 2.0629677 | G35: 0.00087096774
A36: 45231 | B36: 2.9087667 | C36: 2.1484333 | E36: 2.0033667 | G36: 0.00086666667
A37: 45261 | B37: 2.7341613 | C37: 2.0706129 | E37: 2.2975484 | G37: 0.00064516129
A38: 45292 | B38: 3.0452903 | C38: 1.9702581 | E38: 1.702129 | G38: 0.00067741935
A39: 45323 | B39: 2.8811379 | C39: 1.9224828 | E39: 1.4302069 | G39: 0.00048275862
... A46: 45536 | B46: 3.0912 | C46: 2.1548 | E46: 2.0992667 | G46: 0.00013333333
A47: 45566 | B47: 2.8693871 | C47: 2.1541935 | E47: 2.2268065
A48: 45597 | B48: 2.7428 | C48: 2.1831667 | E48: 1.8538333 | G48: 3.3333333e-05
A49: 45627 | B49: 2.6976452 | C49: 2.1697742 | E49: 2.1968387
A50: 45658 | B50: 3.1295806 | C50: 2.0044839 | E50: 1.8067742
A51: 45689 | B51: 3.0378571 | C51: 2.3688214 | E51: 2.2053571
...

Sheet Chart - Mexico crossings
A1: Date | B1: Rio Grande | C1: Brownsville | D1: Laredo
A2: 44197 | B2: 1.5715806 | C2: 0.74780645 | D2: 0.23309677
A3: 44228 | B3: 1.3087143 | C3: 0.72789286 | D3: 0.21582143
A4: 44256 | B4: 1.6089355 | C4: 0.81658065 | D4: 0.21841935
A5: 44287 | B5: 1.4521 | C5: 0.95716667 | D5: 0.26096667
A6: 44317 | B6: 1.5069677 | C6: 0.95203226 | D6: 0.30732258
A7: 44348 | B7: 1.5201 | C7: 1.0591667 | D7: 0.35066667
A8: 44378 | B8: 1.5293871 | C8: 1.0112903 | D8: 0.33551613
A9: 44409 | B9: 1.4706774 | C9: 1.0063548 | D9: 0.32577419
A10: 44440 | B10: 1.4215 | C10: 0.8623 | D10: 0.33
A11: 44470 | B11: 1.523871 | C11: 0.95032258 | D11: 0.29367742
A12: 44501 | B12: 1.4210667 | C12: 0.87673333 | D12: 0.25976667
A13: 44531 | B13: 1.4466774 | C13: 0.73829032 | D13: 0.22077419
... A68: 46204 | B68: 1.7624839 | C68: 1.1220323 | D68: 0.35225806

Sheet Chart - Balance
A1: Date | B1: Dry production | C1: Consumption | D1: Exports (Mexico pipeline + LNG) | E1: Residual (net interstate outflow + withheld fuel)
A2: 44197 | B2: 22.103839 | C2: 11.67429 | D2: 6.3717097 | E2: 6.0982258
A3: 44228 | B3: 18.401 | C3: 11.971964 | D3: 4.533 | E3: 5.0366786
A4: 44256 | B4: 22.992581 | C4: 9.1245161 | D4: 6.7157097 | E4: 6.5343226
A5: 44287 | B5: 23.712233 | C5: 9.9214333 | D5: 6.6868333 | E5: 6.3118333
A6: 44317 | B6: 23.58771 | C6: 9.7155484 | D6: 6.7020968 | E6: 5.4806129
A7: 44348 | B7: 23.521167 | C7: 11.6426 | D7: 6.9353333 | E7: 5.142
A8: 44378 | B8: 23.997032 | C8: 12.246742 | D8: 6.7941613 | E8: 5.2732903
A9: 44409 | B9: 24.04129 | C9: 12.353613 | D9: 6.9158065 | E9: 5.4181935
A10: 44440 | B10: 24.821433 | C10: 11.390133 | D10: 6.3831 | E10: 5.5626667
A11: 44470 | B11: 24.748484 | C11: 10.322161 | D11: 6.8014194 | E11: 6.0601613
A12: 44501 | B12: 24.641967 | C12: 10.1612 | D12: 6.1437333 | E12: 8.1575333
A13: 44531 | B13: 24.995 | C13: 10.285452 | D13: 6.6436452 | E13: 8.0454516
... A68: 46204 | B68: 31.235564 | C68: 13.739194 | D68: 8.2665806 | E68: 9.1492741

Sheet Assump - LNG
A1: LNG assumptions (yellow cells are editable; the Forecast tab recalculates in Excel)
A2: Feedgas = LNG exports x ratio. First-LNG month is a real date (type e.g. 2027-04-01). Trains already started keep their date in the delayed scenario.
A4: Delayed scenario: months of delay | B4: 6 | C4: applied to trains that have not started yet
A5: Feedgas / export ratio | B5: 1.09 | C5: liquefaction fuel and shrink (~9%), as lng_feedgas_daily.xlsx
A6: First forecast month | B6: 46235 | C6: set by the script: the month after the last EIA actual (do not edit)
A10: New and ramping trains (one row per train; spare rows below can be filled)
A11: Plant | B11: Train | C11: Nameplate feedgas Bcf/d | D11: First-LNG month | E11: Ramp months | F11: Ramp-start utilisation | G11: Steady utilisation | H11: Date status | I11: Source / status note
A12: Corpus Christi | B12: Midscale Train 8 | C12: 0.215 | D12: 46905 | E12: 4 | F12: 0.3 | G12: 1 | H12: unverified (month assumed) | I12: Cheniere: Midscale Trains 8-9 substantial completion 2H 2028 (earlier repo research); steady 1.00 as the plant runs at nameplate
A13: Corpus Christi | B13: Midscale Train 9 | C13: 0.215 | D13: 46997 | E13: 4 | F13: 0.3 | G13: 1 | H13: unverified (month assumed) | I13: As Train 8. Not included: Corpus Christi Stage 4 (pre-FID; FERC draft EIS 18 Sep 2026), Texas LNG Brownsville (no FID verified), Freeport Train 4 (shelved)
A14: Golden Pass | B14: Train 1 | C14: 0.865 | D14: 45962 | E14: 24 | F14: 0.1 | G14: 0.9 | H14: actual (first LNG Nov 2025) | I14: Started Nov 2025 (lng_feedgas_daily Train start-ups); slow ramp: 0.12-0.24 Bcf/d of exports Apr-Jul 2026, 0.33 Bcf/d metered Sep 2026
A15: Golden Pass | B15: Train 2 | C15: 0.865 | D15: 46357 | E15: 12 | F15: 0.15 | G15: 0.9 | H15: conflicting statements | I15: FERC approved Train 2 commissioning Jun 2026 (Argus); EIA: start-up 2H 2026; ExxonMobil/McDermott: first LNG 1H 2027. Dec 2026 chosen; the 6-month delay case = Jun 2027
A16: Golden Pass | B16: Train 3 | C16: 0.865 | D16: 46569 | E16: 12 | F16: 0.15 | G16: 0.9 | H16: unverified | I16: Mechanical completion targeted 2Q 2027 (earlier repo research, not re-verified); EIA has it exporting in 2027
A17: Rio Grande | B17: Train 1 | C17: 0.841 | D17: 46478 | E17: 8 | F17: 0.15 | G17: 0.95 | H17: company guidance (month assumed) | I17: NextDecade Q2 2026 update (30 Jul 2026): first gas later in 2026, first LNG from Train 1 in 1H 2027; Trains 1-2 74% complete, ahead of the guaranteed EPC schedule
A18: Rio Grande | B18: Train 2 | C18: 0.841 | D18: 46661 | E18: 8 | F18: 0.15 | G18: 0.95 | H18: unverified | I18: Month estimated: EIA has Trains 1-2 exporting in 2027; NextDecade gives no month for Train 2
A19: Rio Grande | B19: Train 3 | C19: 0.841 | D19: 46935 | E19: 8 | F19: 0.15 | G19: 0.95 | H19: unverified | I19: Month estimated ~9 months after Train 2; Train 3 more than 50% complete (Jun 2026)
A20: Rio Grande | B20: Train 4 | C20: 0.841 | D20: 47665 | E20: 8 | F20: 0.15 | G20: 0.95 | H20: unverified | I20: FID Sep 2025, 15.5% complete (Jun 2026); beyond the forecast horizon
A21: Rio Grande | B21: Train 5 | C21: 0.841 | D21: 47849 | E21: 8 | F21: 0.15 | G21: 0.95 | H21: unverified | I21: FID Oct 2025, 9.4% complete (Jun 2026); beyond the forecast horizon
A22: Port Arthur | B22: Train 1 | C22: 0.932 | D22: 46447 | E22: 8 | F22: 0.15 | G22: 0.95 | H22: unverified (month assumed) | I22: Sempra: Train 1 commercial operations 2027; Argus (2026): commissioning steps under way, ramp-up could begin in Q4 2026. First LNG month assumed
A23: Port Arthur | B23: Train 2 | C23: 0.932 | D23: 46784 | E23: 8 | F23: 0.15 | G23: 0.95 | H23: unverified (month assumed) | I23: Sempra: Train 2 commercial operations 2028
A24: Port Arthur | B24: Train 3 | C24: 0.968 | D24: 47727 | E24: 8 | F24: 0.15 | G24: 0.95 | H24: unverified | I24: Phase 2 FID Sep 2025, completion 2030-31 (Sempra); beyond the horizon
A33: Existing plants: nameplate feedgas (Corpus Christi trains 1-3 + midscale 1-7; Freeport trains 1-3) and monthly utilisation
B34: Corpus Christi | C34: Freeport
A35: Nameplate feedgas Bcf/d | B35: 3.586 | C35: 2.151 | D35: FERC feed-gas letters (lng_feedgas_daily.xlsx Train start-ups); EIA exports x ratio can exceed it (plants run above nameplate)
A36: Profiles: mean of the same calendar month over the last 36 EIA months (utilisation = feedgas / nameplate in operation, smoothed 1-2-1 across neighbouring months; outages, summer derate and maintenance are inside it). Type a number in an override column to replace one month.
A37: Month | B37: CC utilisation (computed) | C37: CC override | D37: CC used | E37: Freeport utilisation (computed) | F37: Freeport override | G37: Freeport used | H37: New-build seasonal index (computed, mean 1) | I37: New-build override | J37: New-build used
A38: 1 | B38: 1.0133933 | D38: =IF(C38="",B38,C38) | E38: 1.0016498 | G38: =IF(F38="",E38,F38) | H38: 1.0175214 | J38: =IF(I38="",H38,I38)
A39: 2 | B39: 1.0199085 | D39: =IF(C39="",B39,C39) | E39: 0.94914609 | G39: =IF(F39="",E39,F39) | H39: 1.0017763 | J39: =IF(I39="",H39,I39)
A40: 3 | B40: 1.0041479 | D40: =IF(C40="",B40,C40) | E40: 0.89400938 | G40: =IF(F40="",E40,F40) | H40: 0.97099416 | J40: =IF(I40="",H40,I40)
A41: 4 | B41: 0.96094548 | D41: =IF(C41="",B41,C41) | E41: 0.8784911 | G41: =IF(F41="",E41,F41) | H41: 0.93789399 | J41: =IF(I41="",H41,I41)
A42: 5 | B42: 0.95667328 | D42: =IF(C42="",B42,C42) | E42: 0.96209679 | G42: =IF(F42="",E42,F42) | H42: 0.96681272 | J42: =IF(I42="",H42,I42)
A43: 6 | B43: 0.9694487 | D43: =IF(C43="",B43,C43) | E43: 0.96720529 | G43: =IF(F43="",E43,F43) | H43: 0.97679725 | J43: =IF(I43="",H43,I43)
A44: 7 | B44: 0.97140821 | D44: =IF(C44="",B44,C44) | E44: 0.8943258 | G44: =IF(F44="",E44,F44) | H44: 0.95047635 | J44: =IF(I44="",H44,I44)
A45: 8 | B45: 0.98422814 | D45: =IF(C45="",B45,C45) | E45: 0.93948002 | G45: =IF(F45="",E45,F45) | H45: 0.97563042 | J45: =IF(I45="",H45,I45)
A46: 9 | B46: 1.0052237 | D46: =IF(C46="",B46,C46) | E46: 1.0266665 | G46: =IF(F46="",E46,F46) | H46: 1.0218306 | J46: =IF(I46="",H46,I46)
A47: 10 | B47: 1.0328329 | D47: =IF(C47="",B47,C47) | E47: 1.0549586 | G47: =IF(F47="",E47,F47) | H47: 1.0499315 | J47: =IF(I47="",H47,I47)
A48: 11 | B48: 1.061405 | D48: =IF(C48="",B48,C48) | E48: 1.0666562 | G48: =IF(F48="",E48,F48) | H48: 1.0723648 | J48: =IF(I48="",H48,I48)
A49: 12 | B49: 1.0448875 | D49: =IF(C49="",B49,C49) | E49: 1.0561235 | G49: =IF(F49="",E49,F49) | H49: 1.0579705 | J49: =IF(I49="",H49,I49)

Sheet Forecast
A1: Texas gas demand incl. LNG, to Dec 2028, Bcf/d - LNG columns are live formulas driven by 'Assump - LNG'
A2: Actual months are EIA (values); forecast months: LNG = formulas, consumption sectors and Mexico = script values (seasonal-trend base: last 3 years' monthly profile x last-12-month level x damped trend).
A5: Month | B5: Actual / forecast | C5: LNG feedgas Corpus Christi - base | D5: LNG feedgas Freeport - base | E5: LNG feedgas Golden Pass - base | F5: LNG feedgas Rio Grande - base | G5: LNG feedgas Port Arthur - base | H5: LNG feedgas other new plants - base | I5: LNG feedgas total - base | J5: LNG feedgas Corpus Christi - delayed | K5: LNG feedgas Freeport - delayed | L5: LNG feedgas Golden Pass - delayed | M5: LNG feedgas Rio Grande - delayed | N5: LNG feedgas Port Arthur - delayed | O5: LNG feedgas other new plants - delayed | P5: LNG feedgas total - delayed | Q5: LNG exports (plain, = feedgas / ratio) - base | R5: LNG exports (plain) - delayed | S5: Electric power | T5: Industrial | U5: Residential | V5: Commercial | W5: Vehicle fuel | X5: Consumption, published sectors | Y5: Pipeline exports to Mexico | Z5: Total demand incl. LNG feedgas - base | AA5: Total demand incl. LNG feedgas - delayed | AB5: EIA LNG exports Corpus Christi | AC5: EIA LNG exports Freeport | AD5: EIA LNG exports Golden Pass
A6: 44197 | B6: Actual | C6: =N(AB6)*'Assump - LNG'!$B$5 | D6: =N(AC6)*'Assump - LNG'!$B$5 | E6: =N(AD6)*'Assump - LNG'!$B$5 | F6: 0 | G6: 0 | H6: 0 | I6: =SUM(C6:H6) | J6: =C6 | K6: =D6 | L6: =E6 | M6: =F6 | N6: =G6 | O6: =H6 | P6: =SUM(J6:O6) | Q6: =I6/'Assump - LNG'!$B$5 | R6: =P6/'Assump - LNG'!$B$5 | S6: 3.6716129 | T6: 5.7480968 | U6: 1.4571935 | V6: 0.79477419 | W6: 0.0025806452 | X6: =SUM(S6:W6) | Y6: 2.5524839 | Z6: =X6+I6 | AA6: =X6+P6 | AB6: 1.8456774 | AC6: 1.9710645
A7: 44228 | B7: Actual | C7: =N(AB7)*'Assump - LNG'!$B$5 | D7: =N(AC7)*'Assump - LNG'!$B$5 | E7: =N(AD7)*'Assump - LNG'!$B$5 | F7: 0 | G7: 0 | H7: 0 | I7: =SUM(C7:H7) | J7: =C7 | K7: =D7 | L7: =E7 | M7: =F7 | N7: =G7 | O7: =H7 | P7: =SUM(J7:O7) | Q7: =I7/'Assump - LNG'!$B$5 | R7: =P7/'Assump - LNG'!$B$5 | S7: 4.4955 | T7: 4.7495714 | U7: 1.7995 | V7: 0.92478571 | W7: 0.0025714286 | X7: =SUM(S7:W7) | Y7: 2.2524286 | Z7: =X7+I7 | AA7: =X7+P7 | AB7: 1.1903571 | AC7: 1.08825
A8: 44256 | B8: Actual | C8: =N(AB8)*'Assump - LNG'!$B$5 | D8: =N(AC8)*'Assump - LNG'!$B$5 | E8: =N(AD8)*'Assump - LNG'!$B$5 | F8: 0 | G8: 0 | H8: 0 | I8: =SUM(C8:H8) | J8: =C8 | K8: =D8 | L8: =E8 | M8: =F8 | N8: =G8 | O8: =H8 | P8: =SUM(J8:O8) | Q8: =I8/'Assump - LNG'!$B$5 | R8: =P8/'Assump - LNG'!$B$5 | S8: 2.8735806 | T8: 4.8493871 | U8: 0.85125806 | V8: 0.54774194 | W8: 0.0025806452 | X8: =SUM(S8:W8) | Y8: 2.6439355 | Z8: =X8+I8 | AA8: =X8+P8 | AB8: 2.0190645 | AC8: 2.0524194
A9: 44287 | B9: Actual | C9: =N(AB9)*'Assump - LNG'!$B$5 | D9: =N(AC9)*'Assump - LNG'!$B$5 | E9: =N(AD9)*'Assump - LNG'!$B$5 | F9: 0 | G9: 0 | H9: 0 | I9: =SUM(C9:H9) | J9: =C9 | K9: =D9 | L9: =E9 | M9: =F9 | N9: =G9 | O9: =H9 | P9: =SUM(J9:O9) | Q9: =I9/'Assump - LNG'!$B$5 | R9: =P9/'Assump - LNG'!$B$5 | S9: 3.7462333 | T9: 5.2871667 | U9: 0.41103333 | V9: 0.47443333 | W9: 0.0025666667 | X9: =SUM(S9:W9) | Y9: 2.6702333 | Z9: =X9+I9 | AA9: =X9+P9 | AB9: 1.9953667 | AC9: 2.0208333
A10: 44317 | B10: Actual | C10: =N(AB10)*'Assump - LNG'!$B$5 | D10: =N(AC10)*'Assump - LNG'!$B$5 | E10: =N(AD10)*'Assump - LNG'!$B$5 | F10: 0 | G10: 0 | H10: 0 | I10: =SUM(C10:H10) | J10: =C10 | K10: =D10 | L10: =E10 | M10: =F10 | N10: =G10 | O10: =H10 | P10: =SUM(J10:O10) | Q10: =I10/'Assump - LNG'!$B$5 | R10: =P10/'Assump - LNG'!$B$5 | S10: 3.8437742 | T10: 5.2347742 | U10: 0.28316129 | V10: 0.35129032 | W10: 0.0025806452 | X10: =SUM(S10:W10) | Y10: 2.7663226 | Z10: =X10+I10 | AA10: =X10+P10 | AB10: 1.8957419 | AC10: 2.0391613
A11: 44348 | B11: Actual | C11: =N(AB11)*'Assump - LNG'!$B$5 | D11: =N(AC11)*'Assump - LNG'!$B$5 | E11: =N(AD11)*'Assump - LNG'!$B$5 | F11: 0 | G11: 0 | H11: 0 | I11: =SUM(C11:H11) | J11: =C11 | K11: =D11 | L11: =E11 | M11: =F11 | N11: =G11 | O11: =H11 | P11: =SUM(J11:O11) | Q11: =I11/'Assump - LNG'!$B$5 | R11: =P11/'Assump - LNG'!$B$5 | S11: 5.7511667 | T11: 5.2962667 | U11: 0.2299 | V11: 0.3627 | W11: 0.0025666667 | X11: =SUM(S11:W11) | Y11: 2.9299333 | Z11: =X11+I11 | AA11: =X11+P11 | AB11: 2.0512 | AC11: 1.9513
A12: 44378 | B12: Actual | C12: =N(AB12)*'Assump - LNG'!$B$5 | D12: =N(AC12)*'Assump - LNG'!$B$5 | E12: =N(AD12)*'Assump - LNG'!$B$5 | F12: 0 | G12: 0 | H12: 0 | I12: =SUM(C12:H12) | J12: =C12 | K12: =D12 | L12: =E12 | M12: =F12 | N12: =G12 | O12: =H12 | P12: =SUM(J12:O12) | Q12: =I12/'Assump - LNG'!$B$5 | R12: =P12/'Assump - LNG'!$B$5 | S12: 6.234871 | T12: 5.4228387 | U12: 0.21525806 | V12: 0.37116129 | W12: 0.0025806452 | X12: =SUM(S12:W12) | Y12: 2.8761935 | Z12: =X12+I12 | AA12: =X12+P12 | AB12: 1.950871 | AC12: 1.9645484
A13: 44409 | B13: Actual | C13: =N(AB13)*'Assump - LNG'!$B$5 | D13: =N(AC13)*'Assump - LNG'!$B$5 | E13: =N(AD13)*'Assump - LNG'!$B$5 | F13: 0 | G13: 0 | H13: 0 | I13: =SUM(C13:H13) | J13: =C13 | K13: =D13 | L13: =E13 | M13: =F13 | N13: =G13 | O13: =H13 | P13: =SUM(J13:O13) | Q13: =I13/'Assump - LNG'!$B$5 | R13: =P13/'Assump - LNG'!$B$5 | S13: 6.3270968 | T13: 5.4585161 | U13: 0.19941935 | V13: 0.36603226 | W13: 0.0025806452 | X13: =SUM(S13:W13) | Y13: 2.8028065 | Z13: =X13+I13 | AA13: =X13+P13 | AB13: 1.9919032 | AC13: 2.1169677
A14: 44440 | B14: Actual | C14: =N(AB14)*'Assump - LNG'!$B$5 | D14: =N(AC14)*'Assump - LNG'!$B$5 | E14: =N(AD14)*'Assump - LNG'!$B$5 | F14: 0 | G14: 0 | H14: 0 | I14: =SUM(C14:H14) | J14: =C14 | K14: =D14 | L14: =E14 | M14: =F14 | N14: =G14 | O14: =H14 | P14: =SUM(J14:O14) | Q14: =I14/'Assump - LNG'!$B$5 | R14: =P14/'Assump - LNG'!$B$5 | S14: 5.2986667 | T14: 5.5180667 | U14: 0.20026667 | V14: 0.37056667 | W14: 0.0025666667 | X14: =SUM(S14:W14) | Y14: 2.6138 | Z14: =X14+I14 | AA14: =X14+P14 | AB14: 2.1464 | AC14: 1.6184
A15: 44470 | B15: Actual | C15: =N(AB15)*'Assump - LNG'!$B$5 | D15: =N(AC15)*'Assump - LNG'!$B$5 | E15: =N(AD15)*'Assump - LNG'!$B$5 | F15: 0 | G15: 0 | H15: 0 | I15: =SUM(C15:H15) | J15: =C15 | K15: =D15 | L15: =E15 | M15: =F15 | N15: =G15 | O15: =H15 | P15: =SUM(J15:O15) | Q15: =I15/'Assump - LNG'!$B$5 | R15: =P15/'Assump - LNG'!$B$5 | S15: 4.4126129 | T15: 5.2626774 | U15: 0.25693548 | V15: 0.38735484 | W15: 0.0025806452 | X15: =SUM(S15:W15) | Y15: 2.767871 | Z15: =X15+I15 | AA15: =X15+P15 | AB15: 2.0914516 | AC15: 1.9367097
A16: 44501 | B16: Actual | C16: =N(AB16)*'Assump - LNG'!$B$5 | D16: =N(AC16)*'Assump - LNG'!$B$5 | E16: =N(AD16)*'Assump - LNG'!$B$5 | F16: 0 | G16: 0 | H16: 0 | I16: =SUM(C16:H16) | J16: =C16 | K16: =D16 | L16: =E16 | M16: =F16 | N16: =G16 | O16: =H16 | P16: =SUM(J16:O16) | Q16: =I16/'Assump - LNG'!$B$5 | R16: =P16/'Assump - LNG'!$B$5 | S16: 3.4576 | T16: 5.6497 | U16: 0.53843333 | V16: 0.51293333 | W16: 0.0025666667 | X16: =SUM(S16:W16) | Y16: 2.5575667 | Z16: =X16+I16 | AA16: =X16+P16 | AB16: 2.1165 | AC16: 1.4647
A17: 44531 | B17: Actual | C17: =N(AB17)*'Assump - LNG'!$B$5 | D17: =N(AC17)*'Assump - LNG'!$B$5 | E17: =N(AD17)*'Assump - LNG'!$B$5 | F17: 0 | G17: 0 | H17: 0 | I17: =SUM(C17:H17) | J17: =C17 | K17: =D17 | L17: =E17 | M17: =F17 | N17: =G17 | O17: =H17 | P17: =SUM(J17:O17) | Q17: =I17/'Assump - LNG'!$B$5 | R17: =P17/'Assump - LNG'!$B$5 | S17: 3.3782903 | T17: 5.7833226 | U17: 0.58916129 | V17: 0.53209677 | W17: 0.0025806452 | X17: =SUM(S17:W17) | Y17: 2.4057419 | Z17: =X17+I17 | AA17: =X17+P17 | AB17: 2.0637097 | AC17: 2.1697742
... A23: 44713 | B23: Actual | C23: =N(AB23)*'Assump - LNG'!$B$5 | D23: =N(AC23)*'Assump - LNG'!$B$5 | E23: =N(AD23)*'Assump - LNG'!$B$5 | F23: 0 | G23: 0 | H23: 0 | I23: =SUM(C23:H23) | J23: =C23 | K23: =D23 | L23: =E23 | M23: =F23 | N23: =G23 | O23: =H23 | P23: =SUM(J23:O23) | Q23: =I23/'Assump - LNG'!$B$5 | R23: =P23/'Assump - LNG'!$B$5 | S23: 6.1464 | T23: 5.3999333 | U23: 0.2081 | V23: 0.37693333 | W23: 0.0035 | X23: =SUM(S23:W23) | Y23: 2.6740667 | Z23: =X23+I23 | AA23: =X23+P23 | AB23: 2.1240333 | AC23: 0.57743333
A24: 44743 | B24: Actual | C24: =N(AB24)*'Assump - LNG'!$B$5 | D24: =N(AC24)*'Assump - LNG'!$B$5 | E24: =N(AD24)*'Assump - LNG'!$B$5 | F24: 0 | G24: 0 | H24: 0 | I24: =SUM(C24:H24) | J24: =C24 | K24: =D24 | L24: =E24 | M24: =F24 | N24: =G24 | O24: =H24 | P24: =SUM(J24:O24) | Q24: =I24/'Assump - LNG'!$B$5 | R24: =P24/'Assump - LNG'!$B$5 | S24: 7.247 | T24: 5.3497742 | U24: 0.198 | V24: 0.38119355 | W24: 0.003483871 | X24: =SUM(S24:W24) | Y24: 2.8176774 | Z24: =X24+I24 | AA24: =X24+P24 | AB24: 2.034871
A25: 44774 | B25: Actual | C25: =N(AB25)*'Assump - LNG'!$B$5 | D25: =N(AC25)*'Assump - LNG'!$B$5 | E25: =N(AD25)*'Assump - LNG'!$B$5 | F25: 0 | G25: 0 | H25: 0 | I25: =SUM(C25:H25) | J25: =C25 | K25: =D25 | L25: =E25 | M25: =F25 | N25: =G25 | O25: =H25 | P25: =SUM(J25:O25) | Q25: =I25/'Assump - LNG'!$B$5 | R25: =P25/'Assump - LNG'!$B$5 | S25: 7.0783226 | T25: 5.3062258 | U25: 0.17312903 | V25: 0.36293548 | W25: 0.003483871 | X25: =SUM(S25:W25) | Y25: 2.7909032 | Z25: =X25+I25 | AA25: =X25+P25 | AB25: 2.0454194
A26: 44805 | B26: Actual | C26: =N(AB26)*'Assump - LNG'!$B$5 | D26: =N(AC26)*'Assump - LNG'!$B$5 | E26: =N(AD26)*'Assump - LNG'!$B$5 | F26: 0 | G26: 0 | H26: 0 | I26: =SUM(C26:H26) | J26: =C26 | K26: =D26 | L26: =E26 | M26: =F26 | N26: =G26 | O26: =H26 | P26: =SUM(J26:O26) | Q26: =I26/'Assump - LNG'!$B$5 | R26: =P26/'Assump - LNG'!$B$5 | S26: 6.03 | T26: 5.1567 | U26: 0.18896667 | V26: 0.37553333 | W26: 0.0035 | X26: =SUM(S26:W26) | Y26: 2.7599333 | Z26: =X26+I26 | AA26: =X26+P26 | AB26: 1.9937
A27: 44835 | B27: Actual | C27: =N(AB27)*'Assump - LNG'!$B$5 | D27: =N(AC27)*'Assump - LNG'!$B$5 | E27: =N(AD27)*'Assump - LNG'!$B$5 | F27: 0 | G27: 0 | H27: 0 | I27: =SUM(C27:H27) | J27: =C27 | K27: =D27 | L27: =E27 | M27: =F27 | N27: =G27 | O27: =H27 | P27: =SUM(J27:O27) | Q27: =I27/'Assump - LNG'!$B$5 | R27: =P27/'Assump - LNG'!$B$5 | S27: 4.4756774 | T27: 5.2686452 | U27: 0.29590323 | V27: 0.43377419 | W27: 0.003483871 | X27: =SUM(S27:W27) | Y27: 2.7406774 | Z27: =X27+I27 | AA27: =X27+P27 | AB27: 2.1543871
A28: 44866 | B28: Actual | C28: =N(AB28)*'Assump - LNG'!$B$5 | D28: =N(AC28)*'Assump - LNG'!$B$5 | E28: =N(AD28)*'Assump - LNG'!$B$5 | F28: 0 | G28: 0 | H28: 0 | I28: =SUM(C28:H28) | J28: =C28 | K28: =D28 | L28: =E28 | M28: =F28 | N28: =G28 | O28: =H28 | P28: =SUM(J28:O28) | Q28: =I28/'Assump - LNG'!$B$5 | R28: =P28/'Assump - LNG'!$B$5 | S28: 4.3259667 | T28: 5.4610667 | U28: 0.84973333 | V28: 0.7006 | W28: 0.0035 | X28: =SUM(S28:W28) | Y28: 2.7509667 | Z28: =X28+I28 | AA28: =X28+P28 | AB28: 1.9009333
A29: 44896 | B29: Actual | C29: =N(AB29)*'Assump - LNG'!$B$5 | D29: =N(AC29)*'Assump - LNG'!$B$5 | E29: =N(AD29)*'Assump - LNG'!$B$5 | F29: 0 | G29: 0 | H29: 0 | I29: =SUM(C29:H29) | J29: =C29 | K29: =D29 | L29: =E29 | M29: =F29 | N29: =G29 | O29: =H29 | P29: =SUM(J29:O29) | Q29: =I29/'Assump - LNG'!$B$5 | R29: =P29/'Assump - LNG'!$B$5 | S29: 4.6253871 | T29: 5.226 | U29: 1.168129 | V29: 0.74048387 | W29: 0.003483871 | X29: =SUM(S29:W29) | Y29: 2.5235161 | Z29: =X29+I29 | AA29: =X29+P29 | AB29: 2.0683548
A30: 44927 | B30: Actual | C30: =N(AB30)*'Assump - LNG'!$B$5 | D30: =N(AC30)*'Assump - LNG'!$B$5 | E30: =N(AD30)*'Assump - LNG'!$B$5 | F30: 0 | G30: 0 | H30: 0 | I30: =SUM(C30:H30) | J30: =C30 | K30: =D30 | L30: =E30 | M30: =F30 | N30: =G30 | O30: =H30 | P30: =SUM(J30:O30) | Q30: =I30/'Assump - LNG'!$B$5 | R30: =P30/'Assump - LNG'!$B$5 | S30: 4.1318065 | T30: 5.5158387 | U30: 1.2087742 | V30: 0.76067742 | W30: 0.0025483871 | X30: =SUM(S30:W30) | Y30: 2.7077419 | Z30: =X30+I30 | AA30: =X30+P30 | AB30: 2.0183226
A31: 44958 | B31: Actual | C31: =N(AB31)*'Assump - LNG'!$B$5 | D31: =N(AC31)*'Assump - LNG'!$B$5 | E31: =N(AD31)*'Assump - LNG'!$B$5 | F31: 0 | G31: 0 | H31: 0 | I31: =SUM(C31:H31) | J31: =C31 | K31: =D31 | L31: =E31 | M31: =F31 | N31: =G31 | O31: =H31 | P31: =SUM(J31:O31) | Q31: =I31/'Assump - LNG'!$B$5 | R31: =P31/'Assump - LNG'!$B$5 | S31: 4.2493571 | T31: 5.5260357 | U31: 1.2505714 | V31: 0.80060714 | W31: 0.0025357143 | X31: =SUM(S31:W31) | Y31: 2.7075714 | Z31: =X31+I31 | AA31: =X31+P31 | AB31: 2.2897857 | AC31: 0.41271429
A32: 44986 | B32: Actual | C32: =N(AB32)*'Assump - LNG'!$B$5 | D32: =N(AC32)*'Assump - LNG'!$B$5 | E32: =N(AD32)*'Assump - LNG'!$B$5 | F32: 0 | G32: 0 | H32: 0 | I32: =SUM(C32:H32) | J32: =C32 | K32: =D32 | L32: =E32 | M32: =F32 | N32: =G32 | O32: =H32 | P32: =SUM(J32:O32) | Q32: =I32/'Assump - LNG'!$B$5 | R32: =P32/'Assump - LNG'!$B$5 | S32: 3.8939032 | T32: 5.4021613 | U32: 0.69451613 | V32: 0.61522581 | W32: 0.0025483871 | X32: =SUM(S32:W32) | Y32: 2.8560645 | Z32: =X32+I32 | AA32: =X32+P32 | AB32: 2.165871 | AC32: 0.93487097
A33: 45017 | B33: Actual | C33: =N(AB33)*'Assump - LNG'!$B$5 | D33: =N(AC33)*'Assump - LNG'!$B$5 | E33: =N(AD33)*'Assump - LNG'!$B$5 | F33: 0 | G33: 0 | H33: 0 | I33: =SUM(C33:H33) | J33: =C33 | K33: =D33 | L33: =E33 | M33: =F33 | N33: =G33 | O33: =H33 | P33: =SUM(J33:O33) | Q33: =I33/'Assump - LNG'!$B$5 | R33: =P33/'Assump - LNG'!$B$5 | S33: 3.9954 | T33: 5.4704667 | U33: 0.40133333 | V33: 0.44636667 | W33: 0.0025333333 | X33: =SUM(S33:W33) | Y33: 2.7527667 | Z33: =X33+I33 | AA33: =X33+P33 | AB33: 1.8517 | AC33: 2.0839333
A34: 45047 | B34: Actual | C34: =N(AB34)*'Assump - LNG'!$B$5 | D34: =N(AC34)*'Assump - LNG'!$B$5 | E34: =N(AD34)*'Assump - LNG'!$B$5 | F34: 0 | G34: 0 | H34: 0 | I34: =SUM(C34:H34) | J34: =C34 | K34: =D34 | L34: =E34 | M34: =F34 | N34: =G34 | O34: =H34 | P34: =SUM(J34:O34) | Q34: =I34/'Assump - LNG'!$B$5 | R34: =P34/'Assump - LNG'!$B$5 | S34: 5.5814194 | T34: 5.3283871 | U34: 0.23467742 | V34: 0.41245161 | W34: 0.0025483871 | X34: =SUM(S34:W34) | Y34: 2.9399677 | Z34: =X34+I34 | AA34: =X34+P34 | AB34: 1.8625806 | AC34: 2.2066452
A35: 45078 | B35: Actual | C35: =N(AB35)*'Assump - LNG'!$B$5 | D35: =N(AC35)*'Assump - LNG'!$B$5 | E35: =N(AD35)*'Assump - LNG'!$B$5 | F35: 0 | G35: 0 | H35: 0 | I35: =SUM(C35:H35) | J35: =C35 | K35: =D35 | L35: =E35 | M35: =F35 | N35: =G35 | O35: =H35 | P35: =SUM(J35:O35) | Q35: =I35/'Assump - LNG'!$B$5 | R35: =P35/'Assump - LNG'!$B$5 | S35: 7.0149667 | T35: 5.343 | U35: 0.22566667 | V35: 0.40733333 | W35: 0.0025333333 | X35: =SUM(S35:W35) | Y35: 3.368 | Z35: =X35+I35 | AA35: =X35+P35 | AB35: 2.0816667 | AC35: 2.1095667
A36: 45108 | B36: Actual | C36: =N(AB36)*'Assump - LNG'!$B$5 | D36: =N(AC36)*'Assump - LNG'!$B$5 | E36: =N(AD36)*'Assump - LNG'!$B$5 | F36: 0 | G36: 0 | H36: 0 | I36: =SUM(C36:H36) | J36: =C36 | K36: =D36 | L36: =E36 | M36: =F36 | N36: =G36 | O36: =H36 | P36: =SUM(J36:O36) | Q36: =I36/'Assump - LNG'!$B$5 | R36: =P36/'Assump - LNG'!$B$5 | S36: 7.5775484 | T36: 5.3420645 | U36: 0.20851613 | V36: 0.40693548 | W36: 0.0025483871 | X36: =SUM(S36:W36) | Y36: 3.1230968 | Z36: =X36+I36 | AA36: =X36+P36 | AB36: 1.8915806 | AC36: 1.9200645
A37: 45139 | B37: Actual | C37: =N(AB37)*'Assump - LNG'!$B$5 | D37: =N(AC37)*'Assump - LNG'!$B$5 | E37: =N(AD37)*'Assump - LNG'!$B$5 | F37: 0 | G37: 0 | H37: 0 | I37: =SUM(C37:H37) | J37: =C37 | K37: =D37 | L37: =E37 | M37: =F37 | N37: =G37 | O37: =H37 | P37: =SUM(J37:O37) | Q37: =I37/'Assump - LNG'!$B$5 | R37: =P37/'Assump - LNG'!$B$5 | S37: 8.6564839 | T37: 5.4475806 | U37: 0.18780645 | V37: 0.38267742 | W37: 0.0025483871 | X37: =SUM(S37:W37) | Y37: 3.1732258 | Z37: =X37+I37 | AA37: =X37+P37 | AB37: 2.014 | AC37: 1.9818065
A38: 45170 | B38: Actual | C38: =N(AB38)*'Assump - LNG'!$B$5 | D38: =N(AC38)*'Assump - LNG'!$B$5 | E38: =N(AD38)*'Assump - LNG'!$B$5 | F38: 0 | G38: 0 | H38: 0 | I38: =SUM(C38:H38) | J38: =C38 | K38: =D38 | L38: =E38 | M38: =F38 | N38: =G38 | O38: =H38 | P38: =SUM(J38:O38) | Q38: =I38/'Assump - LNG'!$B$5 | R38: =P38/'Assump - LNG'!$B$5 | S38: 7.1554 | T38: 5.4454 | U38: 0.1764 | V38: 0.3765 | W38: 0.0025333333 | X38: =SUM(S38:W38) | Y38: 3.1247333 | Z38: =X38+I38 | AA38: =X38+P38 | AB38: 1.9786333 | AC38: 1.8007
A39: 45200 | B39: Actual | C39: =N(AB39)*'Assump - LNG'!$B$5 | D39: =N(AC39)*'Assump - LNG'!$B$5 | E39: =N(AD39)*'Assump - LNG'!$B$5 | F39: 0 | G39: 0 | H39: 0 | I39: =SUM(C39:H39) | J39: =C39 | K39: =D39 | L39: =E39 | M39: =F39 | N39: =G39 | O39: =H39 | P39: =SUM(J39:O39) | Q39: =I39/'Assump - LNG'!$B$5 | R39: =P39/'Assump - LNG'!$B$5 | S39: 4.9320323 | T39: 5.4348387 | U39: 0.31945161 | V39: 0.46629032 | W39: 0.0025483871 | X39: =SUM(S39:W39) | Y39: 3.0543871 | Z39: =X39+I39 | AA39: =X39+P39 | AB39: 2.0446774 | AC39: 2.0629677
A40: 45231 | B40: Actual | C40: =N(AB40)*'Assump - LNG'!$B$5 | D40: =N(AC40)*'Assump - LNG'!$B$5 | E40: =N(AD40)*'Assump - LNG'!$B$5 | F40: 0 | G40: 0 | H40: 0 | I40: =SUM(C40:H40) | J40: =C40 | K40: =D40 | L40: =E40 | M40: =F40 | N40: =G40 | O40: =H40 | P40: =SUM(J40:O40) | Q40: =I40/'Assump - LNG'!$B$5 | R40: =P40/'Assump - LNG'!$B$5 | S40: 4.6336667 | T40: 5.7127667 | U40: 0.6995 | V40: 0.6163 | W40: 0.0025333333 | X40: =SUM(S40:W40) | Y40: 2.9087667 | Z40: =X40+I40 | AA40: =X40+P40 | AB40: 2.1484333 | AC40: 2.0033667
A41: 45261 | B41: Actual | C41: =N(AB41)*'Assump - LNG'!$B$5 | D41: =N(AC41)*'Assump - LNG'!$B$5 | E41: =N(AD41)*'Assump - LNG'!$B$5 | F41: 0 | G41: 0 | H41: 0 | I41: =SUM(C41:H41) | J41: =C41 | K41: =D41 | L41: =E41 | M41: =F41 | N41: =G41 | O41: =H41 | P41: =SUM(J41:O41) | Q41: =I41/'Assump - LNG'!$B$5 | R41: =P41/'Assump - LNG'!$B$5 | S41: 4.421 | T41: 5.8175484 | U41: 1.0207742 | V41: 0.71735484 | W41: 0.0025483871 | X41: =SUM(S41:W41) | Y41: 2.7341613 | Z41: =X41+I41 | AA41: =X41+P41 | AB41: 2.0706129 | AC41: 2.2975484
A42: 45292 | B42: Actual | C42: =N(AB42)*'Assump - LNG'!$B$5 | D42: =N(AC42)*'Assump - LNG'!$B$5 | E42: =N(AD42)*'Assump - LNG'!$B$5 | F42: 0 | G42: 0 | H42: 0 | I42: =SUM(C42:H42) | J42: =C42 | K42: =D42 | L42: =E42 | M42: =F42 | N42: =G42 | O42: =H42 | P42: =SUM(J42:O42) | Q42: =I42/'Assump - LNG'!$B$5 | R42: =P42/'Assump - LNG'!$B$5 | S42: 5.5614194 | T42: 5.7379032 | U42: 1.7182903 | V42: 0.91296774 | W42: 0.0074193548 | X42: =SUM(S42:W42) | Y42: 3.0452903 | Z42: =X42+I42 | AA42: =X42+P42 | AB42: 1.9702581 | AC42: 1.702129
... A68: 46082 | B68: Actual | C68: =N(AB68)*'Assump - LNG'!$B$5 | D68: =N(AC68)*'Assump - LNG'!$B$5 | E68: =N(AD68)*'Assump - LNG'!$B$5 | F68: 0 | G68: 0 | H68: 0 | I68: =SUM(C68:H68) | J68: =C68 | K68: =D68 | L68: =E68 | M68: =F68 | N68: =G68 | O68: =H68 | P68: =SUM(J68:O68) | Q68: =I68/'Assump - LNG'!$B$5 | R68: =P68/'Assump - LNG'!$B$5 | S68: 4.129 | T68: 5.6532258 | U68: 0.53909677 | V68: 0.55183871 | W68: 0.0061935484 | X68: =SUM(S68:W68) | Y68: 2.7685806 | Z68: =X68+I68 | AA68: =X68+P68 | AB68: 3.0834516 | AC68: 2.252
A69: 46113 | B69: Actual | C69: =N(AB69)*'Assump - LNG'!$B$5 | D69: =N(AC69)*'Assump - LNG'!$B$5 | E69: =N(AD69)*'Assump - LNG'!$B$5 | F69: 0 | G69: 0 | H69: 0 | I69: =SUM(C69:H69) | J69: =C69 | K69: =D69 | L69: =E69 | M69: =F69 | N69: =G69 | O69: =H69 | P69: =SUM(J69:O69) | Q69: =I69/'Assump - LNG'!$B$5 | R69: =P69/'Assump - LNG'!$B$5 | S69: 4.8080333 | T69: 5.7195333 | U69: 0.3398 | V69: 0.47023333 | W69: 0.0062 | X69: =SUM(S69:W69) | Y69: 2.8376667 | Z69: =X69+I69 | AA69: =X69+P69 | AB69: 2.8933667 | AC69: 2.3034667 | AD69: 0.12063333
A70: 46143 | B70: Actual | C70: =N(AB70)*'Assump - LNG'!$B$5 | D70: =N(AC70)*'Assump - LNG'!$B$5 | E70: =N(AD70)*'Assump - LNG'!$B$5 | F70: 0 | G70: 0 | H70: 0 | I70: =SUM(C70:H70) | J70: =C70 | K70: =D70 | L70: =E70 | M70: =F70 | N70: =G70 | O70: =H70 | P70: =SUM(J70:O70) | Q70: =I70/'Assump - LNG'!$B$5 | R70: =P70/'Assump - LNG'!$B$5 | S70: 5.7464194 | T70: 5.6338065 | U70: 0.23090323 | V70: 0.38348387 | W70: 0.0061935484 | X70: =SUM(S70:W70) | Y70: 3.3164516 | Z70: =X70+I70 | AA70: =X70+P70 | AB70: 2.8644839 | AC70: 1.8283226 | AD70: 0.11174194
A71: 46174 | B71: Actual | C71: =N(AB71)*'Assump - LNG'!$B$5 | D71: =N(AC71)*'Assump - LNG'!$B$5 | E71: =N(AD71)*'Assump - LNG'!$B$5 | F71: 0 | G71: 0 | H71: 0 | I71: =SUM(C71:H71) | J71: =C71 | K71: =D71 | L71: =E71 | M71: =F71 | N71: =G71 | O71: =H71 | P71: =SUM(J71:O71) | Q71: =I71/'Assump - LNG'!$B$5 | R71: =P71/'Assump - LNG'!$B$5 | S71: 6.8060667 | T71: 5.6723 | U71: 0.2417 | V71: 0.4054 | W71: 0.0062 | X71: =SUM(S71:W71) | Y71: 3.3545 | Z71: =X71+I71 | AA71: =X71+P71 | AB71: 3.0009 | AC71: 1.9812667 | AD71: 0.11496667
A72: 46204 | B72: Actual | C72: =N(AB72)*'Assump - LNG'!$B$5 | D72: =N(AC72)*'Assump - LNG'!$B$5 | E72: =N(AD72)*'Assump - LNG'!$B$5 | F72: 0 | G72: 0 | H72: 0 | I72: =SUM(C72:H72) | J72: =C72 | K72: =D72 | L72: =E72 | M72: =F72 | N72: =G72 | O72: =H72 | P72: =SUM(J72:O72) | Q72: =I72/'Assump - LNG'!$B$5 | R72: =P72/'Assump - LNG'!$B$5 | S72: 7.6218065 | T72: 5.5193548 | U72: 0.21764516 | V72: 0.37412903 | W72: 0.0061935484 | X72: =SUM(S72:W72) | Y72: 3.2367742 | Z72: =X72+I72 | AA72: =X72+P72 | AB72: 3.1331935 | AC72: 1.6781613 | AD72: 0.21845161
...

Sheet LNG trains calc
A1: Feedgas by train, Bcf/d (formulas on 'Assump - LNG'; base block, then delayed block). Rows match the Forecast tab.
A3: Plant | B3: =IF('Assump - LNG'!$A12="","",'Assump - LNG'!$A12) | C3: =IF('Assump - LNG'!$A13="","",'Assump - LNG'!$A13) | D3: =IF('Assump - LNG'!$A14="","",'Assump - LNG'!$A14) | E3: =IF('Assump - LNG'!$A15="","",'Assump - LNG'!$A15) | F3: =IF('Assump - LNG'!$A16="","",'Assump - LNG'!$A16) | G3: =IF('Assump - LNG'!$A17="","",'Assump - LNG'!$A17) | H3: =IF('Assump - LNG'!$A18="","",'Assump - LNG'!$A18) | I3: =IF('Assump - LNG'!$A19="","",'Assump - LNG'!$A19) | J3: =IF('Assump - LNG'!$A20="","",'Assump - LNG'!$A20) | K3: =IF('Assump - LNG'!$A21="","",'Assump - LNG'!$A21) | L3: =IF('Assump - LNG'!$A22="","",'Assump - LNG'!$A22) | M3: =IF('Assump - LNG'!$A23="","",'Assump - LNG'!$A23) | N3: =IF('Assump - LNG'!$A24="","",'Assump - LNG'!$A24) | O3: =IF('Assump - LNG'!$A25="","",'Assump - LNG'!$A25) | P3: =IF('Assump - LNG'!$A26="","",'Assump - LNG'!$A26) | Q3: =IF('Assump - LNG'!$A27="","",'Assump - LNG'!$A27) | R3: =IF('Assump - LNG'!$A28="","",'Assump - LNG'!$A28) | S3: =IF('Assump - LNG'!$A29="","",'Assump - LNG'!$A29) | T3: =IF('Assump - LNG'!$A30="","",'Assump - LNG'!$A30) | U3: =IF('Assump - LNG'!$A31="","",'Assump - LNG'!$A31) | V3: =IF('Assump - LNG'!$A12="","",'Assump - LNG'!$A12) | W3: =IF('Assump - LNG'!$A13="","",'Assump - LNG'!$A13) | X3: =IF('Assump - LNG'!$A14="","",'Assump - LNG'!$A14) | Y3: =IF('Assump - LNG'!$A15="","",'Assump - LNG'!$A15) | Z3: =IF('Assump - LNG'!$A16="","",'Assump - LNG'!$A16) | AA3: =IF('Assump - LNG'!$A17="","",'Assump - LNG'!$A17) | AB3: =IF('Assump - LNG'!$A18="","",'Assump - LNG'!$A18) | AC3: =IF('Assump - LNG'!$A19="","",'Assump - LNG'!$A19) | AD3: =IF('Assump - LNG'!$A20="","",'Assump - LNG'!$A20) | AE3: =IF('Assump - LNG'!$A21="","",'Assump - LNG'!$A21) | AF3: =IF('Assump - LNG'!$A22="","",'Assump - LNG'!$A22) | AG3: =IF('Assump - LNG'!$A23="","",'Assump - LNG'!$A23) | AH3: =IF('Assump - LNG'!$A24="","",'Assump - LNG'!$A24) | AI3: =IF('Assump - LNG'!$A25="","",'Assump - LNG'!$A25) | AJ3: =IF('Assump - LNG'!$A26="","",'Assump - LNG'!$A26) | AK3: =IF('Assump - LNG'!$A27="","",'Assump - LNG'!$A27) | AL3: =IF('Assump - LNG'!$A28="","",'Assump - LNG'!$A28) | AM3: =IF('Assump - LNG'!$A29="","",'Assump - LNG'!$A29) | AN3: =IF('Assump - LNG'!$A30="","",'Assump - LNG'!$A30) | AO3: =IF('Assump - LNG'!$A31="","",'Assump - LNG'!$A31)
A4: Train | B4: =IF('Assump - LNG'!$B12="","",'Assump - LNG'!$B12) | C4: =IF('Assump - LNG'!$B13="","",'Assump - LNG'!$B13) | D4: =IF('Assump - LNG'!$B14="","",'Assump - LNG'!$B14) | E4: =IF('Assump - LNG'!$B15="","",'Assump - LNG'!$B15) | F4: =IF('Assump - LNG'!$B16="","",'Assump - LNG'!$B16) | G4: =IF('Assump - LNG'!$B17="","",'Assump - LNG'!$B17) | H4: =IF('Assump - LNG'!$B18="","",'Assump - LNG'!$B18) | I4: =IF('Assump - LNG'!$B19="","",'Assump - LNG'!$B19) | J4: =IF('Assump - LNG'!$B20="","",'Assump - LNG'!$B20) | K4: =IF('Assump - LNG'!$B21="","",'Assump - LNG'!$B21) | L4: =IF('Assump - LNG'!$B22="","",'Assump - LNG'!$B22) | M4: =IF('Assump - LNG'!$B23="","",'Assump - LNG'!$B23) | N4: =IF('Assump - LNG'!$B24="","",'Assump - LNG'!$B24) | O4: =IF('Assump - LNG'!$B25="","",'Assump - LNG'!$B25) | P4: =IF('Assump - LNG'!$B26="","",'Assump - LNG'!$B26) | Q4: =IF('Assump - LNG'!$B27="","",'Assump - LNG'!$B27) | R4: =IF('Assump - LNG'!$B28="","",'Assump - LNG'!$B28) | S4: =IF('Assump - LNG'!$B29="","",'Assump - LNG'!$B29) | T4: =IF('Assump - LNG'!$B30="","",'Assump - LNG'!$B30) | U4: =IF('Assump - LNG'!$B31="","",'Assump - LNG'!$B31) | V4: =IF('Assump - LNG'!$B12="","",'Assump - LNG'!$B12) | W4: =IF('Assump - LNG'!$B13="","",'Assump - LNG'!$B13) | X4: =IF('Assump - LNG'!$B14="","",'Assump - LNG'!$B14) | Y4: =IF('Assump - LNG'!$B15="","",'Assump - LNG'!$B15) | Z4: =IF('Assump - LNG'!$B16="","",'Assump - LNG'!$B16) | AA4: =IF('Assump - LNG'!$B17="","",'Assump - LNG'!$B17) | AB4: =IF('Assump - LNG'!$B18="","",'Assump - LNG'!$B18) | AC4: =IF('Assump - LNG'!$B19="","",'Assump - LNG'!$B19) | AD4: =IF('Assump - LNG'!$B20="","",'Assump - LNG'!$B20) | AE4: =IF('Assump - LNG'!$B21="","",'Assump - LNG'!$B21) | AF4: =IF('Assump - LNG'!$B22="","",'Assump - LNG'!$B22) | AG4: =IF('Assump - LNG'!$B23="","",'Assump - LNG'!$B23) | AH4: =IF('Assump - LNG'!$B24="","",'Assump - LNG'!$B24) | AI4: =IF('Assump - LNG'!$B25="","",'Assump - LNG'!$B25) | AJ4: =IF('Assump - LNG'!$B26="","",'Assump - LNG'!$B26) | AK4: =IF('Assump - LNG'!$B27="","",'Assump - LNG'!$B27) | AL4: =IF('Assump - LNG'!$B28="","",'Assump - LNG'!$B28) | AM4: =IF('Assump - LNG'!$B29="","",'Assump - LNG'!$B29) | AN4: =IF('Assump - LNG'!$B30="","",'Assump - LNG'!$B30) | AO4: =IF('Assump - LNG'!$B31="","",'Assump - LNG'!$B31)
A5: Month | B5: base | C5: base | D5: base | E5: base | F5: base | G5: base | H5: base | I5: base | J5: base | K5: base | L5: base | M5: base | N5: base | O5: base | P5: base | Q5: base | R5: base | S5: base | T5: base | U5: base | V5: delayed | W5: delayed | X5: delayed | Y5: delayed | Z5: delayed | AA5: delayed | AB5: delayed | AC5: delayed | AD5: delayed | AE5: delayed | AF5: delayed | AG5: delayed | AH5: delayed | AI5: delayed | AJ5: delayed | AK5: delayed | AL5: delayed | AM5: delayed | AN5: delayed | AO5: delayed
