Workbook

Sheet Units
A1: Notes
A2: Notes
A4: UNITS
A5: All flows are Bcf/d (billion cubic feet per day), monthly averages. Texas marketed production, consumption, Mexico and LNG history come from texas_gas_monthly.xlsx (EIA).
A7: METHOD
A8: Forecast base: EIA STEO (live). Series: NGMPPM (Permian), NGMPEF (Eagle Ford), NGMPHA (Haynesville), regional marketed production. STEO ends Dec 2027; 2028 extends 2027 by the STEO 2027/2026 annual growth per region (stated, not an EIA forecast).
A9: Texas = 85% Permian + 100% Eagle Ford + 30% Haynesville + 'Other Texas' calibration (-1.39 Bcf/d, mean gap to Texas history over the last 6 overlapping months, held flat). Shares are editable assumptions.
A10: STEO regional series are already marketed, so no dry-to-marketed conversion is applied; the last-12-month extraction-loss share used in TEXAS_GAS.py is 16.4% of marketed (dry equivalent = marketed x 0.836).
A11: Permian cap: production = min(STEO Permian, existing takeaway + new pipelines in service + local demand) from the Takeaway tab. Delayed scenario shifts every pipeline not yet in service by the delay on the Assumptions tab.
A12: Takeaway table: only Matterhorn (in service) is firm; every other capacity and date is UNVERIFIED (company announcements, from memory) and the existing-takeaway aggregate is a calibration. Edit the tab and re-run to update.
A13: Net interstate outflow = DRY production (marketed x (1 - extraction-loss share); EIA dry history) + storage withdrawal - demand incl. LNG (five EIA consumption sectors + LNG feedgas + Mexico pipeline exports) - storage injection. Marketed gas includes NGLs removed at plants, which never reach a pipeline, so the earlier marketed-based outflow (before Oct 2026) ran about 6 Bcf/d too high. It also includes fuel EIA withholds (lease/plant, pipeline).
A14: CHANGE (Oct 2026): storage is now in the outflow. Before, outflow = dry production - demand and ignored storage, so its seasonality carried the storage cycle (higher in summer when gas is injected, lower in winter when withdrawn). Gross EIA injections (demand side) and withdrawals (supply side) are now separate series; the old no-storage outflow is kept as the 'before storage' memo columns of the 'Supply and demand' and 'Demand to 2033' tabs.
... A29: Sanity checks of the last run: model run to 2033 reproduces the 2028 workbook: max |LNG diff| 5.3e-15, sectors 1.8e-15 Bcf/d; data centres LOW: US 262 TWh in 2028 (LBNL 2028 range 325-580), Texas 7.8 / 9.5 / 10.0 GW energised at Dec/28 / Dec/30 / Dec/33 (ERCOT CDR 2030: 22.2 GW requested); data centres BASE: US 345 TWh in 2028 (LBNL 2028 range 325-580), Texas 15.1 / 20.5 / 24.9 GW energised at Dec/28 / Dec/30 / Dec/33 (ERCOT CDR 2030: 22.2 GW requested); data centres HIGH: US 440 TWh in 2028 (LBNL 2028 range 325-580), Texas 27.2 / 38.7 / 49.6 GW energised at Dec/28 / Dec/30 / Dec/33 (ERCOT CDR 2030: 22.2 GW requested); data-centre gas burn LOW: Dec/28 0.30, Dec/30 0.37, Dec/33 0.39 Bcf/d (below the 10 Bcf/d flag); data-centre gas burn BASE: Dec/28 0.59, Dec/30 0.81, Dec/33 0.98 Bcf/d (below the 10 Bcf/d flag); data-centre gas burn HIGH: Dec/28 1.29, Dec/30 1.83, Dec/33 2.34 Bcf/d (below the 10 Bcf/d flag); implied outflow LOW: Dec/28 9.9, Dec/30 10.7, Dec/33 9.6, min 7.5 (Sep/31); implied outflow BASE: Dec/28 9.7, Dec/30 10.4, Dec/33 9.1, min 7.2 (Sep/31); implied outflow HIGH: Dec/28 9.3, Dec/30 9.7, Dec/33 8.0, min 6.2 (Sep/33); join Dec/28 -> Jan/29 (BASE): total demand +1.62 (median monthly step 2027-28 1.06), dry production +0.12, outflow +1.16 Bcf/d (the same Dec -> Jan step a year earlier was +0.32: winter demand) - no jump beyond the seasonal step

Sheet Chart
A1: Date | B1: Electric power | C1: Industrial | D1: Residential | E1: Commercial | F1: Vehicle fuel | G1: LNG feedgas (base case) | H1: Pipeline exports to Mexico | I1: Storage injection (demand) | J1: Dry production (base) | K1: Dry prod. + storage withdrawal (base) | L1: Dry prod. + storage withdrawal (takeaway delayed)
A2: 44197 | B2: 3.6716129 | C2: 5.7480968 | D2: 1.4571935 | E2: 0.79477419 | F2: 0.0025806452 | G2: 4.1602487 | H2: 2.5524839 | I2: 0.51964516 | J2: 22.103839 | K2: 24.663839
A3: 44228 | B3: 4.4955 | C3: 4.7495714 | D3: 1.7995 | E3: 0.92478571 | F3: 0.0025714286 | G3: 2.4836818 | H3: 2.2524286 | I3: 1.2721071 | J3: 18.401 | K3: 22.81375
A4: 44256 | B4: 2.8735806 | C4: 4.8493871 | D4: 0.85125806 | E4: 0.54774194 | F4: 0.0025806452 | G4: 4.4379174 | H4: 2.6439355 | I4: 1.7623548 | J4: 22.992581 | K4: 24.136935
A5: 44287 | B5: 3.7462333 | C5: 5.2871667 | D5: 0.41103333 | E5: 0.47443333 | F5: 0.0025666667 | G5: 4.377658 | H5: 2.6702333 | I5: 1.559 | J5: 23.712233 | K5: 24.4791
A6: 44317 | B6: 3.8437742 | C6: 5.2347742 | D6: 0.28316129 | E6: 0.35129032 | F6: 0.0025806452 | G6: 4.2890445 | H6: 2.7663226 | I6: 2.0602903 | J6: 23.58771 | K6: 23.958548
A7: 44348 | B7: 5.7511667 | C7: 5.2962667 | D7: 0.2299 | E7: 0.3627 | F7: 0.0025666667 | G7: 4.362725 | H7: 2.9299333 | I7: 1.1406 | J7: 23.521167 | K7: 24.8605
A8: 44378 | B8: 6.234871 | C8: 5.4228387 | D8: 0.21525806 | E8: 0.37116129 | F8: 0.0025806452 | G8: 4.2678071 | H8: 2.8761935 | I8: 0.93870968 | J8: 23.997032 | K8: 25.252903
A9: 44409 | B9: 6.3270968 | C9: 5.4585161 | D9: 0.19941935 | E9: 0.36603226 | F9: 0.0025806452 | G9: 4.4786694 | H9: 2.8028065 | I9: 1.0414516 | J9: 24.04129 | K9: 25.729065
A10: 44440 | B10: 5.2986667 | C10: 5.5180667 | D10: 0.20026667 | E10: 0.37056667 | F10: 0.0025666667 | G10: 4.103632 | H10: 2.6138 | I10: 2.1608667 | J10: 24.821433 | K10: 25.496767
A11: 44470 | B11: 4.4126129 | C11: 5.2626774 | D11: 0.25693548 | E11: 0.38735484 | F11: 0.0025806452 | G11: 4.3906958 | H11: 2.767871 | I11: 2.1540323 | J11: 24.748484 | K11: 25.337774
A12: 44501 | B12: 3.4576 | C12: 5.6497 | D12: 0.53843333 | E12: 0.51293333 | F12: 0.0025666667 | G12: 3.903508 | H12: 2.5575667 | I12: 1.2943667 | J12: 24.641967 | K12: 25.756833
A13: 44531 | B13: 3.3782903 | C13: 5.7833226 | D13: 0.58916129 | E13: 0.53209677 | F13: 0.0025806452 | G13: 4.6144974 | H13: 2.4057419 | I13: 1.3879677 | J13: 24.995 | K13: 26.362516
... A67: 46174 | B67: 6.8060667 | C67: 5.6723 | D67: 0.2417 | E67: 0.4054 | F67: 0.0062 | G67: 5.5558753 | H67: 3.3545 | I67: 1.9443667 | J67: 30.448165 | K67: 31.768398
A68: 46204 | B68: 7.6218065 | C68: 5.5193548 | D68: 0.21764516 | E68: 0.37412903 | F68: 0.0061935484 | G68: 5.482489 | H68: 3.2367742 | I68: 1.5230323 | J68: 31.235564 | K68: 32.678048 | L68: 32.678048
A69: 46235 | B69: 8.2263576 | C69: 5.6214854 | D69: 0.17794869 | E69: 0.36099472 | F69: 0.0052481374 | G69: 5.8878318 | H69: 3.173173 | I69: 1.7417634 | J69: 31.281098 | K69: 34.164646 | L69: 33.759443
A70: 46266 | B70: 6.9728812 | C70: 5.5964561 | D70: 0.17504687 | E70: 0.36980399 | F70: 0.0052254119 | G70: 6.1961079 | H70: 2.9870729 | I70: 2.4121333 | J70: 31.317247 | K70: 33.422103 | L70: 33.016899
A71: 46296 | B71: 5.4794114 | C71: 5.4490224 | D71: 0.24294985 | E71: 0.40489795 | F71: 0.0052215626 | G71: 6.3967772 | H71: 2.8493584 | I71: 2.5234946 | J71: 31.536417 | K71: 32.593202 | L71: 32.001504
A72: 46327 | B72: 4.681837 | C72: 5.8335977 | D72: 0.46735723 | E72: 0.507368 | F72: 0.0051989521 | G72: 6.5643737 | H72: 2.7849505 | I72: 1.8817889 | J72: 31.648602 | K72: 32.93628 | L72: 32.258413
A73: 46357 | B73: 4.625126 | C73: 6.0318405 | D73: 0.86189287 | E73: 0.64677959 | F73: 0.0051951223 | G73: 6.644037 | H73: 2.6581154 | I73: 1.3792043 | J73: 31.822032 | K73: 33.980806 | L73: 33.211562
A74: 46388 | B74: 5.6015213 | C74: 5.8936863 | D74: 1.5346367 | E74: 0.9017584 | F74: 0.0066322591 | G74: 6.4743652 | H74: 2.928315 | I74: 0.99531183 | J74: 31.344803 | K74: 35.780147 | L74: 35.722053
A75: 46419 | B75: 4.5916658 | C75: 5.7716835 | D75: 1.0717534 | E75: 0.70967394 | F75: 0.0066262794 | G75: 6.4572245 | H75: 2.8787615 | I75: 1.6379409 | J75: 32.149746 | K75: 35.002649 | L75: 34.361387
A76: 46447 | B76: 4.0843027 | C76: 5.7448506 | D76: 0.49155077 | E76: 0.48832721 | F76: 0.0065986755 | G76: 6.475046 | H76: 2.7740886 | I76: 2.392172 | J76: 32.326306 | K76: 33.513575 | L76: 32.725042
A77: 46478 | B77: 4.5135499 | C77: 5.6806081 | D77: 0.31908161 | E77: 0.44408902 | F77: 0.006578774 | G77: 6.537793 | H77: 2.986666 | I77: 2.2719222 | J77: 32.512422 | K77: 33.672089 | L77: 33.672089
A78: 46508 | B78: 5.8158872 | C78: 5.5529935 | D78: 0.22098632 | E78: 0.37307427 | F78: 0.006565262 | G78: 6.9909379 | H78: 3.2461318 | I78: 2.1792473 | J78: 32.716243 | K78: 33.839275 | L78: 33.839275
A79: 46539 | B79: 6.7069187 | C79: 5.6145799 | D79: 0.21021394 | E79: 0.37587896 | F79: 0.0065454613 | G79: 7.3172938 | H79: 3.1831636 | I79: 1.8354667 | J79: 32.934512 | K79: 34.083723 | L79: 34.083723
... A97: 47088 | B97: 4.5887427 | C97: 6.1278077 | D97: 0.810955 | E97: 0.60855491 | F97: 0.0048880906 | G97: 13.047025 | H97: 2.5515278 | I97: 1.3792043 | J97: 36.933949 | K97: 39.092724 | L97: 39.092724

Sheet Chart - Demand to 2033
A1: Date | B1: Electric power | C1: Industrial | D1: Res., comm., vehicle | E1: LNG feedgas (base case) | F1: Pipeline exports to Mexico | G1: Data centres (BASE, gas burn added after Jul/26) | H1: Storage injection (demand) | I1: Total demand, BASE (top of stack) | J1: Total, LOW data centres | K1: Total, HIGH data centres | L1: Dry production (base) | M1: Dry prod. + storage withdrawal (base)
A2: 45292 | B2: 5.5614194 | C2: 5.7379032 | D2: 2.6386774 | E2: 4.0029019 | F2: 3.0452903 | G2: 0 | H2: 0.91774194 | I2: 21.903934 | J2: 21.903934 | K2: 21.903934 | L2: 25.127 | M2: 29.081419
A3: 45323 | B3: 4.008069 | C3: 5.5365862 | D3: 1.8695517 | E3: 3.6544317 | F3: 2.8811379 | G3: 0 | H3: 2.0079655 | I3: 19.957742 | J3: 19.957742 | K3: 19.957742 | L3: 26.471655 | M3: 28.072759
A4: 45352 | B4: 4.4758065 | C4: 5.56 | D4: 1.1774516 | E4: 3.0774568 | F4: 2.9665484 | G4: 0 | H4: 2.3155484 | I4: 19.572812 | J4: 19.572812 | K4: 19.572812 | L4: 26.711839 | M4: 27.842
A5: 45383 | B5: 4.5075333 | C5: 5.455 | D5: 0.78406667 | E5: 2.2114283 | F5: 3.1878 | G5: 0 | H5: 2.3053 | I5: 18.451128 | J5: 18.451128 | K5: 18.451128 | L5: 26.687633 | M5: 28.0144
A6: 45413 | B6: 6.0100645 | C6: 5.2321613 | D6: 0.67119355 | E6: 4.10494 | F6: 3.2576774 | G6: 0 | H6: 1.9052581 | I6: 21.181295 | J6: 21.181295 | K6: 21.181295 | L6: 27.57171 | M6: 28.814935
A7: 45444 | B7: 6.9767333 | C7: 5.4126333 | D7: 0.66076667 | E7: 4.706075 | F7: 3.1171333 | G7: 0 | H7: 1.5503667 | I7: 22.423708 | J7: 22.423708 | K7: 22.423708 | L7: 27.7913 | M7: 29.1215
A8: 45474 | B8: 7.2613226 | C8: 5.5117419 | D8: 0.65383871 | E8: 2.8885352 | F8: 3.1470968 | G8: 0 | H8: 1.1359032 | I8: 20.598438 | J8: 20.598438 | K8: 20.598438 | L8: 27.729065 | M8: 29.399839
A9: 45505 | B9: 8.3584839 | C9: 5.6377419 | D9: 0.61125806 | E9: 4.4457935 | F9: 3.1935484 | G9: 0 | H9: 1.8753226 | I9: 24.122148 | J9: 24.122148 | K9: 24.122148 | L9: 27.919806 | M9: 31.394548
A10: 45536 | B10: 6.8978667 | C10: 5.5316 | D10: 0.6315 | E10: 4.6369327 | F10: 3.0912 | G10: 0 | H10: 2.5233 | I10: 23.312399 | J10: 23.312399 | K10: 23.312399 | L10: 28.2645 | M10: 30.491867
A11: 45566 | B11: 5.9251613 | C11: 5.3037097 | D11: 0.67880645 | E11: 4.77529 | F11: 2.8693871 | G11: 0 | H11: 2.7849355 | I11: 22.33729 | J11: 22.33729 | K11: 22.33729 | L11: 28.559 | M11: 29.548355
A12: 45597 | B12: 4.8063333 | C12: 5.7018667 | D12: 0.94066667 | E12: 4.40033 | F12: 2.7428 | G12: 0 | H12: 1.8167667 | I12: 20.408763 | J12: 20.408763 | K12: 20.408763 | L12: 28.285367 | M12: 29.5422
A13: 45627 | B13: 4.6534194 | C13: 6.0434839 | D13: 1.5876452 | E13: 4.7596081 | F13: 2.6976452 | G13: 0 | H13: 1.4490323 | I13: 21.190834 | J13: 21.190834 | K13: 21.190834 | L13: 28.499452 | M13: 30.373516
... A121: 48914 | B121: 4.5887427 | C121: 6.374459 | D121: 1.223179 | E121: 16.017198 | F121: 2.303385 | G121: 0.64504812 | H121: 1.3792043 | I121: 32.531216 | J121: 32.055262 | K121: 33.600127 | L121: 39.479282 | M121: 41.638056

Sheet Chart - Outflow to 2033
A1: Date | B1: LOW data-centre case | C1: BASE data-centre case | D1: HIGH data-centre case | E1: BASE before storage (memo: old definition)
A2: 45292 | B2: 7.1774852 | C2: 7.1774852 | D2: 7.1774852 | E2: 4.1408077
A3: 45323 | B3: 8.1150166 | C3: 8.1150166 | D3: 8.1150166 | E3: 8.5218786
A4: 45352 | B4: 8.2691884 | C4: 8.2691884 | D4: 8.2691884 | E4: 9.4545755
A5: 45383 | B5: 9.5632717 | C5: 9.5632717 | D5: 9.5632717 | E5: 10.541805
A6: 45413 | B6: 7.6336406 | C6: 7.6336406 | D6: 7.6336406 | E6: 8.2956729
A7: 45444 | B7: 6.6977917 | C7: 6.6977917 | D7: 6.6977917 | E7: 6.9179583
A8: 45474 | B8: 8.8014003 | C8: 8.8014003 | D8: 8.8014003 | E8: 8.2665294
A9: 45505 | B9: 7.2724 | C9: 7.2724 | D9: 7.2724 | E9: 5.6729806
A10: 45536 | B10: 7.1794673 | C10: 7.1794673 | D10: 7.1794673 | E10: 7.4754007
A11: 45566 | B11: 7.2110648 | C11: 7.2110648 | D11: 7.2110648 | E11: 9.0066455
A12: 45597 | B12: 9.1334367 | C12: 9.1334367 | D12: 9.1334367 | E12: 9.69337
A13: 45627 | B13: 9.1826823 | C13: 9.1826823 | D13: 9.1826823 | E13: 8.75765
... A121: 48914 | B121: 9.582794 | C121: 9.1068404 | D121: 8.0379294 | E121: 8.3272705

Sheet Chart - Production
A1: Date | B1: History | C1: Forecast - base | D1: Forecast - takeaway delayed 6 months
A2: 44562 | B2: 27.343387
A3: 44593 | B3: 28.543429
A4: 44621 | B4: 29.152194
A5: 44652 | B5: 29.6837
A6: 44682 | B6: 29.069161
A7: 44713 | B7: 28.8727
A8: 44743 | B8: 28.845548
A9: 44774 | B9: 29.415387
A10: 44805 | B10: 30.112733
A11: 44835 | B11: 29.785194
A12: 44866 | B12: 29.8353
A13: 44896 | B13: 29.945129
... A55: 46174 | B55: 36.406767
A56: 46204 | B56: 37.348258 | C56: 37.348258 | D56: 37.348258
A57: 46235 | C57: 37.402702 | D57: 36.918202
A58: 46266 | C58: 37.445926 | D58: 36.961426
A59: 46296 | C59: 37.707986 | D59: 37.000496
A60: 46327 | C60: 37.842126 | D60: 37.031603
A61: 46357 | C61: 38.049495 | D61: 37.129713
A62: 46388 | C62: 37.478874 | D62: 37.409412
A63: 46419 | C63: 38.441341 | D63: 37.674586
A64: 46447 | C64: 38.652455 | D64: 37.709608
A65: 46478 | C65: 38.874993 | D65: 38.874993
A66: 46508 | C66: 39.1187 | D66: 39.1187
A67: 46539 | C67: 39.379684 | D67: 39.379684
A68: 46569 | C68: 39.654544 | D68: 39.654544
... A85: 47088 | C85: 44.161798 | D85: 44.161798

Sheet Chart - Net outflow
A1: Date | B1: Base (base production, base LNG) | C1: Delayed (takeaway delayed 6 months, LNG delayed 6 months) | D1: Base before storage (memo: old definition)
A2: 44197 | B2: 5.7572029 | C2: 5.7572029 | D2: 3.7168481
A3: 44228 | B3: 4.8336039 | C3: 4.8336039 | D3: 1.6929611
A4: 44256 | B4: 6.1681794 | C4: 6.1681794 | D4: 6.7861794
A5: 44287 | B5: 5.9507753 | C5: 5.9507753 | D5: 6.7429087
A6: 44317 | B6: 5.1273103 | C6: 5.1273103 | D6: 6.8167619
A7: 44348 | B7: 4.7846417 | C7: 4.7846417 | D7: 4.5859083
A8: 44378 | B8: 4.9234832 | C8: 4.9234832 | D8: 4.6063219
A9: 44409 | B9: 5.0524919 | C9: 5.0524919 | D9: 4.4061694
A10: 44440 | B10: 5.2283347 | C10: 5.2283347 | D10: 6.713868
A11: 44470 | B11: 5.7030139 | C11: 5.7030139 | D11: 7.2677558
A12: 44501 | B12: 7.8401587 | C12: 7.8401587 | D12: 8.0196587
A13: 44531 | B13: 7.6688574 | C13: 7.6688574 | D13: 7.689309
... A97: 47088 | B97: 9.9740185 | C97: 11.350848 | D97: 9.1944486

Sheet Chart - Storage
A1: Date | B1: Injection (demand side) | C1: Withdrawal (supply side, shown negative) | D1: Net injection (+) / withdrawal (-)
A2: 44197 | B2: 0.51964516 | C2: -2.56 | D2: -2.0403548
A3: 44228 | B3: 1.2721071 | C3: -4.41275 | D3: -3.1406429
A4: 44256 | B4: 1.7623548 | C4: -1.1443548 | D4: 0.618
A5: 44287 | B5: 1.559 | C5: -0.76686667 | D5: 0.79213333
A6: 44317 | B6: 2.0602903 | C6: -0.37083871 | D6: 1.6894516
A7: 44348 | B7: 1.1406 | C7: -1.3393333 | D7: -0.19873333
A8: 44378 | B8: 0.93870968 | C8: -1.255871 | D8: -0.31716129
A9: 44409 | B9: 1.0414516 | C9: -1.6877742 | D9: -0.64632258
A10: 44440 | B10: 2.1608667 | C10: -0.67533333 | D10: 1.4855333
A11: 44470 | B11: 2.1540323 | C11: -0.58929032 | D11: 1.5647419
A12: 44501 | B12: 1.2943667 | C12: -1.1148667 | D12: 0.1795
A13: 44531 | B13: 1.3879677 | C13: -1.3675161 | D13: 0.020451613
... A157: 48914 | B157: 1.3792043 | C157: -2.1587742 | D157: -0.77956989

Sheet Chart - Permian cap
A1: Date | B1: STEO Permian marketed | C1: Takeaway + local demand, base | D1: Takeaway + local demand, delayed
A2: 45658 | B2: 25.862857 | C2: 29.5 | D2: 29.5
A3: 45689 | B3: 26.242166 | C3: 29.5 | D3: 29.5
A4: 45717 | B4: 26.900119 | C4: 29.5 | D4: 29.5
A5: 45748 | B5: 26.862717 | C5: 29.5 | D5: 29.5
A6: 45778 | B6: 26.87354 | C6: 29.5 | D6: 29.5
A7: 45809 | B7: 27.442882 | C7: 29.5 | D7: 29.5
A8: 45839 | B8: 28.102135 | C8: 29.5 | D8: 29.5
A9: 45870 | B9: 28.369864 | C9: 29.5 | D9: 29.5
A10: 45901 | B10: 28.567493 | C10: 29.5 | D10: 29.5
A11: 45931 | B11: 27.71589 | C11: 29.5 | D11: 29.5
A12: 45962 | B12: 28.672036 | C12: 29.5 | D12: 29.5
A13: 45992 | B13: 28.959106 | C13: 29.5 | D13: 29.5
... A49: 47088 | B49: 36.324099 | C49: 39.02 | D49: 36.52

Sheet Summary
B1: Month | C1: Base Bcf/d | D1: Delayed Bcf/d | E1: Dry production base Bcf/d | F1: Dry production delayed Bcf/d | G1: Demand incl. LNG base Bcf/d | H1: Demand incl. LNG delayed Bcf/d | I1: Base net outflow Bcf/d | J1: Delayed net outflow Bcf/d
A2: 0 | B2: Dec 2026 | C2: 38.049495 | D2: 37.129713 | E2: 31.822032 | F2: 31.052788 | G2: 21.472986 | H2: 21.335715 | I2: 11.128615 | J2: 10.496643
A3: 1 | B3: Dec 2027 | C3: 41.028589 | D3: 41.028589 | E3: 34.313545 | F3: 34.313545 | G3: 24.94187 | H3: 22.837157 | I3: 10.151245 | J3: 12.255958
A4: 2 | B4: Dec 2028 | C4: 44.161798 | D4: 44.161798 | E4: 36.933949 | F4: 36.933949 | G4: 27.739501 | H4: 26.362671 | I4: 9.9740185 | J4: 11.350848

Sheet Assumptions
B1: Assumption | C1: Value | D1: Unit | E1: Note
A2: 0 | B2: Permian Texas share of STEO Permian | C2: 0.85 | D2: share | E2: STEO Permian = Texas + southeast New Mexico (NM about 13-15%). Assumption.
A3: 1 | B3: Haynesville Texas share of STEO Haynesville | C3: 0.3 | D3: share | E3: STEO Haynesville = East Texas + Louisiana. Assumption (unverified).
A4: 2 | B4: Eagle Ford Texas share | C4: 1 | D4: share | E4: Eagle Ford is in Texas.
A5: 3 | B5: Local Permian demand (power, industrial, Mexico-bound not included) | C5: 3 | D5: Bcf/d | E5: Gas consumed in the basin, adds to takeaway in the cap. Unverified.
A6: 4 | B6: Takeaway delay in the delayed scenario | C6: 6 | D6: months | E6: Every pipeline with status not 'in service' slips by this many months.
A7: 5 | B7: Net storage change override (Bcf/d average, + = net injection; blank = last-3-year mean) | D7: Bcf/d | E7: ASSUMPTION (editable; blank = use the last-3-year mean). Texas working-gas capacity additions are NOT assumed.
A8: 6 | B8: Net storage change used (Bcf/d average, + = net injection) | C8: -0.018744468 | D8: Bcf/d | E8: mean of EIA months Aug/23-Jul/26 (last-3-year mean -0.019); applied to the forecast months by holding the annual mean net injection there.

Sheet Takeaway
B1: Unnamed: 0.6 | C1: Unnamed: 0.5 | D1: Unnamed: 0.4 | E1: Unnamed: 0.3 | F1: Unnamed: 0.2 | G1: Unnamed: 0.1 | H1: Unnamed: 0 | I1: Pipeline | J1: Capacity Bcf/d | K1: In-service month | L1: Status | M1: Source / verification
A2: 0 | B2: 0 | C2: 0 | D2: 0 | E2: 0 | F2: 0 | G2: 0 | H2: 0 | I2: Existing Permian takeaway (aggregate, Waha-bound + Midland/Eagle Ford routes incl. Matterhorn) | J2: 26.5 | K2: 2025-01 | L2: In service | M2: Calibration: with local demand it brackets STEO Permian marketed in 2026. Total is unverified.
A3: 1 | B3: 1 | C3: 1 | D3: 1 | E3: 1 | F3: 1 | G3: 1 | H3: 1 | I3: Matterhorn Express (Kinder/WhiteWater/EnLink/Devon, Waha-Katy) | J3: 2.5 | K3: 2024-10 | L3: In service | M3: Already inside the existing aggregate above (shown for reference, not added).
A4: 2 | B4: 2 | C4: 2 | D4: 2 | E4: 2 | F4: 2 | G4: 2 | H4: 2 | I4: Gulf Coast Express expansion (Kinder Morgan) | J4: 0.57 | K4: 2026-07 | L4: Under construction | M4: unverified - company announcement, date from memory
A5: 3 | B5: 3 | C5: 3 | D5: 3 | E5: 3 | F5: 3 | G5: 3 | H5: 3 | I5: Blackcomb Pipeline (WhiteWater/Targa/MPLX/Enterprise) | J5: 2.5 | K5: 2026-10 | L5: Under construction | M5: unverified - company announcement, date from memory
A6: 4 | B6: 4 | C6: 4 | D6: 4 | E6: 4 | F6: 4 | G6: 4 | H6: 4 | I6: Hugh Brinson Pipeline (Energy Transfer, phase 1) | J6: 1.5 | K6: 2026-12 | L6: Under construction | M6: unverified - company announcement, date from memory
A7: 5 | B7: 5 | C7: 5 | D7: 5 | E7: 5 | F7: 5 | G7: 5 | H7: 5 | I7: Hugh Brinson Pipeline (Energy Transfer, phase 2 expansion) | J7: 0.7 | K7: 2027-07 | L7: Under construction | M7: unverified - company announcement, date from memory
A8: 6 | B8: 6 | C8: 6 | D8: 6 | E8: 6 | F8: 6 | G8: 6 | H8: 6 | I8: Eiger Express (WhiteWater/Targa/MPLX/Enterprise) | J8: 2.5 | K8: 2028-07 | L8: Planned | M8: unverified - company announcement, date from memory
A9: 7 | B9: 7 | C9: 7 | D9: 7 | E9: 7 | F9: 7 | G9: 7 | H9: 7 | I9: Traverse Pipeline (WhiteWater, Agua Dulce) | J9: 1.75 | K9: 2027-10 | L9: Planned | M9: unverified - company announcement, date from memory

Sheet Forecast
B1: Month | C1: Type | D1: Texas marketed production (history) | E1: STEO Permian marketed (Bcf/d) | F1: STEO Eagle Ford marketed (Bcf/d) | G1: STEO Haynesville marketed (Bcf/d) | H1: STEO source | I1: Permian takeaway + local demand, base (Bcf/d) | J1: Permian takeaway + local demand, delayed (Bcf/d) | K1: Permian marketed capped, base | L1: Permian marketed capped, delayed | M1: Permian capped by takeaway (base) | N1: Other Texas / calibration (held flat) | O1: Texas production forecast, base | P1: Texas production forecast, delayed | Q1: Dry production, base | R1: Dry production, takeaway delayed | S1: Demand incl. LNG, base | T1: Demand incl. LNG, LNG delayed | U1: LNG feedgas (base) | V1: LNG feedgas (delayed) | W1: Texas consumption, published sectors (history EIA; forecast = TEXAS_GAS_FORECAST) | X1: Pipeline exports to Mexico (history EIA; forecast = TEXAS_GAS_FORECAST) | Y1: Texas storage injection (demand; EIA, forecast = seasonal pattern) | Z1: Texas storage withdrawal (supply; EIA, forecast = seasonal pattern) | AA1: Implied net interstate outflow, base | AB1: Implied net interstate outflow, delayed
A2: 0 | B2: 42005 | C2: History | D2: 21.509419 | H2: STEO | I2: 29.5 | J2: 29.5 | K2: 29.5 | L2: 29.5 | M2: FALSE | N2: -1.3945905
A3: 1 | B3: 42036 | C3: History | D3: 21.973286 | H3: STEO | I3: 29.5 | J3: 29.5 | K3: 29.5 | L3: 29.5 | M3: FALSE | N3: -1.3945905
A4: 2 | B4: 42064 | C4: History | H4: STEO | I4: 29.5 | J4: 29.5 | K4: 29.5 | L4: 29.5 | M4: FALSE | N4: -1.3945905
A5: 3 | B5: 42095 | C5: History | H5: STEO | I5: 29.5 | J5: 29.5 | K5: 29.5 | L5: 29.5 | M5: FALSE | N5: -1.3945905
A6: 4 | B6: 42125 | C6: History | H6: STEO | I6: 29.5 | J6: 29.5 | K6: 29.5 | L6: 29.5 | M6: FALSE | N6: -1.3945905
A7: 5 | B7: 42156 | C7: History | H7: STEO | I7: 29.5 | J7: 29.5 | K7: 29.5 | L7: 29.5 | M7: FALSE | N7: -1.3945905
A8: 6 | B8: 42186 | C8: History | H8: STEO | I8: 29.5 | J8: 29.5 | K8: 29.5 | L8: 29.5 | M8: FALSE | N8: -1.3945905
A9: 7 | B9: 42217 | C9: History | H9: STEO | I9: 29.5 | J9: 29.5 | K9: 29.5 | L9: 29.5 | M9: FALSE | N9: -1.3945905
A10: 8 | B10: 42248 | C10: History | H10: STEO | I10: 29.5 | J10: 29.5 | K10: 29.5 | L10: 29.5 | M10: FALSE | N10: -1.3945905
A11: 9 | B11: 42278 | C11: History | D11: 21.303129 | H11: STEO | I11: 29.5 | J11: 29.5 | K11: 29.5 | L11: 29.5 | M11: FALSE | N11: -1.3945905
A12: 10 | B12: 42309 | C12: History | D12: 21.0325 | H12: STEO | I12: 29.5 | J12: 29.5 | K12: 29.5 | L12: 29.5 | M12: FALSE | N12: -1.3945905
A13: 11 | B13: 42339 | C13: History | D13: 20.829613 | H13: STEO | I13: 29.5 | J13: 29.5 | K13: 29.5 | L13: 29.5 | M13: FALSE | N13: -1.3945905
A14: 12 | B14: 42370 | C14: History | H14: STEO | I14: 29.5 | J14: 29.5 | K14: 29.5 | L14: 29.5 | M14: FALSE | N14: -1.3945905
A15: 13 | B15: 42401 | C15: History | D15: 20.562724 | H15: STEO | I15: 29.5 | J15: 29.5 | K15: 29.5 | L15: 29.5 | M15: FALSE | N15: -1.3945905
A16: 14 | B16: 42430 | C16: History | D16: 20.090613 | H16: STEO | I16: 29.5 | J16: 29.5 | K16: 29.5 | L16: 29.5 | M16: FALSE | N16: -1.3945905
A17: 15 | B17: 42461 | C17: History | D17: 20.419967 | H17: STEO | I17: 29.5 | J17: 29.5 | K17: 29.5 | L17: 29.5 | M17: FALSE | N17: -1.3945905
A18: 16 | B18: 42491 | C18: History | D18: 19.950935 | H18: STEO | I18: 29.5 | J18: 29.5 | K18: 29.5 | L18: 29.5 | M18: FALSE | N18: -1.3945905
A19: 17 | B19: 42522 | C19: History | D19: 20.052933 | H19: STEO | I19: 29.5 | J19: 29.5 | K19: 29.5 | L19: 29.5 | M19: FALSE | N19: -1.3945905
A20: 18 | B20: 42552 | C20: History | D20: 20.147323 | H20: STEO | I20: 29.5 | J20: 29.5 | K20: 29.5 | L20: 29.5 | M20: FALSE | N20: -1.3945905
A21: 19 | B21: 42583 | C21: History | D21: 19.666323 | H21: STEO | I21: 29.5 | J21: 29.5 | K21: 29.5 | L21: 29.5 | M21: FALSE | N21: -1.3945905
A22: 20 | B22: 42614 | C22: History | D22: 19.390567 | H22: STEO | I22: 29.5 | J22: 29.5 | K22: 29.5 | L22: 29.5 | M22: FALSE | N22: -1.3945905
A23: 21 | B23: 42644 | C23: History | D23: 19.186194 | H23: STEO | I23: 29.5 | J23: 29.5 | K23: 29.5 | L23: 29.5 | M23: FALSE | N23: -1.3945905
A24: 22 | B24: 42675 | C24: History | D24: 18.962567 | H24: STEO | I24: 29.5 | J24: 29.5 | K24: 29.5 | L24: 29.5 | M24: FALSE | N24: -1.3945905
A25: 23 | B25: 42705 | C25: History | D25: 18.424677 | H25: STEO | I25: 29.5 | J25: 29.5 | K25: 29.5 | L25: 29.5 | M25: FALSE | N25: -1.3945905
A26: 24 | B26: 42736 | C26: History | D26: 18.238129 | H26: STEO | I26: 29.5 | J26: 29.5 | K26: 29.5 | L26: 29.5 | M26: FALSE | N26: -1.3945905
... A73: 71 | B73: 44166 | C73: History | D73: 25.961516 | H73: STEO | I73: 29.5 | J73: 29.5 | K73: 29.5 | L73: 29.5 | M73: FALSE | N73: -1.3945905
A74: 72 | B74: 44197 | C74: History | D74: 25.786581 | H74: STEO | I74: 29.5 | J74: 29.5 | K74: 29.5 | L74: 29.5 | M74: FALSE | N74: -1.3945905 | Q74: 22.103839 | R74: 22.103839 | S74: 18.386991 | T74: 18.386991 | U74: 4.1602487 | V74: 4.1602487 | W74: 11.674258 | X74: 2.5524839 | Y74: 0.51964516 | Z74: 2.56 | AA74: 5.7572029 | AB74: 5.7572029
A75: 73 | B75: 44228 | C75: History | D75: 21.810893 | H75: STEO | I75: 29.5 | J75: 29.5 | K75: 29.5 | L75: 29.5 | M75: FALSE | N75: -1.3945905 | Q75: 18.401 | R75: 18.401 | S75: 16.708039 | T75: 16.708039 | U75: 2.4836818 | V75: 2.4836818 | W75: 11.971929 | X75: 2.2524286 | Y75: 1.2721071 | Z75: 4.41275 | AA75: 4.8336039 | AB75: 4.8336039
A76: 74 | B76: 44256 | C76: History | D76: 26.711452 | H76: STEO | I76: 29.5 | J76: 29.5 | K76: 29.5 | L76: 29.5 | M76: FALSE | N76: -1.3945905 | Q76: 22.992581 | R76: 22.992581 | S76: 16.206401 | T76: 16.206401 | U76: 4.4379174 | V76: 4.4379174 | W76: 9.1245484 | X76: 2.6439355 | Y76: 1.7623548 | Z76: 1.1443548 | AA76: 6.1681794 | AB76: 6.1681794
A77: 75 | B77: 44287 | C77: History | D77: 27.460233 | H77: STEO | I77: 29.5 | J77: 29.5 | K77: 29.5 | L77: 29.5 | M77: FALSE | N77: -1.3945905 | Q77: 23.712233 | R77: 23.712233 | S77: 16.969325 | T77: 16.969325 | U77: 4.377658 | V77: 4.377658 | W77: 9.9214333 | X77: 2.6702333 | Y77: 1.559 | Z77: 0.76686667 | AA77: 5.9507753 | AB77: 5.9507753
A78: 76 | B78: 44317 | C78: History | D78: 27.33271 | H78: STEO | I78: 29.5 | J78: 29.5 | K78: 29.5 | L78: 29.5 | M78: FALSE | N78: -1.3945905 | Q78: 23.58771 | R78: 23.58771 | S78: 16.770948 | T78: 16.770948 | U78: 4.2890445 | V78: 4.2890445 | W78: 9.7155806 | X78: 2.7663226 | Y78: 2.0602903 | Z78: 0.37083871 | AA78: 5.1273103 | AB78: 5.1273103
A79: 77 | B79: 44348 | C79: History | D79: 27.252733 | H79: STEO | I79: 29.5 | J79: 29.5 | K79: 29.5 | L79: 29.5 | M79: FALSE | N79: -1.3945905 | Q79: 23.521167 | R79: 23.521167 | S79: 18.935258 | T79: 18.935258 | U79: 4.362725 | V79: 4.362725 | W79: 11.6426 | X79: 2.9299333 | Y79: 1.1406 | Z79: 1.3393333 | AA79: 4.7846417 | AB79: 4.7846417
A80: 78 | B80: 44378 | C80: History | D80: 27.763871 | H80: STEO | I80: 29.5 | J80: 29.5 | K80: 29.5 | L80: 29.5 | M80: FALSE | N80: -1.3945905 | Q80: 23.997032 | R80: 23.997032 | S80: 19.39071 | T80: 19.39071 | U80: 4.2678071 | V80: 4.2678071 | W80: 12.24671 | X80: 2.8761935 | Y80: 0.93870968 | Z80: 1.255871 | AA80: 4.9234832 | AB80: 4.9234832
A81: 79 | B81: 44409 | C81: History | D81: 27.81929 | H81: STEO | I81: 29.5 | J81: 29.5 | K81: 29.5 | L81: 29.5 | M81: FALSE | N81: -1.3945905 | Q81: 24.04129 | R81: 24.04129 | S81: 19.635121 | T81: 19.635121 | U81: 4.4786694 | V81: 4.4786694 | W81: 12.353645 | X81: 2.8028065 | Y81: 1.0414516 | Z81: 1.6877742 | AA81: 5.0524919 | AB81: 5.0524919
A82: 80 | B82: 44440 | C82: History | D82: 28.625067 | H82: STEO | I82: 29.5 | J82: 29.5 | K82: 29.5 | L82: 29.5 | M82: FALSE | N82: -1.3945905 | Q82: 24.821433 | R82: 24.821433 | S82: 18.107565 | T82: 18.107565 | U82: 4.103632 | V82: 4.103632 | W82: 11.390133 | X82: 2.6138 | Y82: 2.1608667 | Z82: 0.67533333 | AA82: 5.2283347 | AB82: 5.2283347
A83: 81 | B83: 44470 | C83: History | D83: 28.612516 | H83: STEO | I83: 29.5 | J83: 29.5 | K83: 29.5 | L83: 29.5 | M83: FALSE | N83: -1.3945905 | Q83: 24.748484 | R83: 24.748484 | S83: 17.480728 | T83: 17.480728 | U83: 4.3906958 | V83: 4.3906958 | W83: 10.322161 | X83: 2.767871 | Y83: 2.1540323 | Z83: 0.58929032 | AA83: 5.7030139 | AB83: 5.7030139
A84: 82 | B84: 44501 | C84: History | D84: 28.5496 | H84: STEO | I84: 29.5 | J84: 29.5 | K84: 29.5 | L84: 29.5 | M84: FALSE | N84: -1.3945905 | Q84: 24.641967 | R84: 24.641967 | S84: 16.622308 | T84: 16.622308 | U84: 3.903508 | V84: 3.903508 | W84: 10.161233 | X84: 2.5575667 | Y84: 1.2943667 | Z84: 1.1148667 | AA84: 7.8401587 | AB84: 7.8401587
A85: 83 | B85: 44531 | C85: History | D85: 28.935581 | H85: STEO | I85: 29.5 | J85: 29.5 | K85: 29.5 | L85: 29.5 | M85: FALSE | N85: -1.3945905 | Q85: 24.995 | R85: 24.995 | S85: 17.305691 | T85: 17.305691 | U85: 4.6144974 | V85: 4.6144974 | W85: 10.285452 | X85: 2.4057419 | Y85: 1.3879677 | Z85: 1.3675161 | AA85: 7.6688574 | AB85: 7.6688574
... A109: 107 | B109: 45261 | C109: History | D109: 32.01571 | H109: STEO | I109: 29.5 | J109: 29.5 | K109: 29.5 | L109: 29.5 | M109: FALSE | N109: -1.3945905 | Q109: 27.04571 | R109: 27.04571 | S109: 19.474683 | T109: 19.474683 | U109: 4.7612958 | V109: 4.7612958 | W109: 11.979226 | X109: 2.7341613 | Y109: 1.3472903 | Z109: 1.4364516 | AA109: 7.6601881 | AB109: 7.6601881
...

Sheet Supply and demand
B1: Month | C1: Type | D1: Electric power | E1: Industrial | F1: Residential | G1: Commercial | H1: Vehicle fuel | I1: LNG feedgas (base) | J1: Pipeline exports to Mexico | K1: Demand incl. LNG, base | L1: LNG feedgas (delayed) | M1: Demand incl. LNG, LNG delayed | N1: Dry production, base | O1: Dry production, takeaway delayed | P1: Implied net outflow before storage, base | Q1: Implied net outflow before storage, delayed | R1: Storage injection (demand) | S1: Storage withdrawal (supply) | T1: Storage basis | U1: Dry production + storage withdrawal, base | V1: Dry production + storage withdrawal, takeaway delayed | W1: Implied net outflow, base | X1: Implied net outflow, delayed (production and LNG both delayed)
A2: 0 | B2: 44197 | C2: Actual | D2: 3.6716129 | E2: 5.7480968 | F2: 1.4571935 | G2: 0.79477419 | H2: 0.0025806452 | I2: 4.1602487 | J2: 2.5524839 | K2: 18.386991 | L2: 4.1602487 | M2: 18.386991 | N2: 22.103839 | O2: 22.103839 | P2: 3.7168481 | Q2: 3.7168481 | R2: 0.51964516 | S2: 2.56 | T2: EIA | U2: 24.663839 | V2: 24.663839 | W2: 5.7572029 | X2: 5.7572029
A3: 1 | B3: 44228 | C3: Actual | D3: 4.4955 | E3: 4.7495714 | F3: 1.7995 | G3: 0.92478571 | H3: 0.0025714286 | I3: 2.4836818 | J3: 2.2524286 | K3: 16.708039 | L3: 2.4836818 | M3: 16.708039 | N3: 18.401 | O3: 18.401 | P3: 1.6929611 | Q3: 1.6929611 | R3: 1.2721071 | S3: 4.41275 | T3: EIA | U3: 22.81375 | V3: 22.81375 | W3: 4.8336039 | X3: 4.8336039
A4: 2 | B4: 44256 | C4: Actual | D4: 2.8735806 | E4: 4.8493871 | F4: 0.85125806 | G4: 0.54774194 | H4: 0.0025806452 | I4: 4.4379174 | J4: 2.6439355 | K4: 16.206401 | L4: 4.4379174 | M4: 16.206401 | N4: 22.992581 | O4: 22.992581 | P4: 6.7861794 | Q4: 6.7861794 | R4: 1.7623548 | S4: 1.1443548 | T4: EIA | U4: 24.136935 | V4: 24.136935 | W4: 6.1681794 | X4: 6.1681794
A5: 3 | B5: 44287 | C5: Actual | D5: 3.7462333 | E5: 5.2871667 | F5: 0.41103333 | G5: 0.47443333 | H5: 0.0025666667 | I5: 4.377658 | J5: 2.6702333 | K5: 16.969325 | L5: 4.377658 | M5: 16.969325 | N5: 23.712233 | O5: 23.712233 | P5: 6.7429087 | Q5: 6.7429087 | R5: 1.559 | S5: 0.76686667 | T5: EIA | U5: 24.4791 | V5: 24.4791 | W5: 5.9507753 | X5: 5.9507753
A6: 4 | B6: 44317 | C6: Actual | D6: 3.8437742 | E6: 5.2347742 | F6: 0.28316129 | G6: 0.35129032 | H6: 0.0025806452 | I6: 4.2890445 | J6: 2.7663226 | K6: 16.770948 | L6: 4.2890445 | M6: 16.770948 | N6: 23.58771 | O6: 23.58771 | P6: 6.8167619 | Q6: 6.8167619 | R6: 2.0602903 | S6: 0.37083871 | T6: EIA | U6: 23.958548 | V6: 23.958548 | W6: 5.1273103 | X6: 5.1273103
A7: 5 | B7: 44348 | C7: Actual | D7: 5.7511667 | E7: 5.2962667 | F7: 0.2299 | G7: 0.3627 | H7: 0.0025666667 | I7: 4.362725 | J7: 2.9299333 | K7: 18.935258 | L7: 4.362725 | M7: 18.935258 | N7: 23.521167 | O7: 23.521167 | P7: 4.5859083 | Q7: 4.5859083 | R7: 1.1406 | S7: 1.3393333 | T7: EIA | U7: 24.8605 | V7: 24.8605 | W7: 4.7846417 | X7: 4.7846417
A8: 6 | B8: 44378 | C8: Actual | D8: 6.234871 | E8: 5.4228387 | F8: 0.21525806 | G8: 0.37116129 | H8: 0.0025806452 | I8: 4.2678071 | J8: 2.8761935 | K8: 19.39071 | L8: 4.2678071 | M8: 19.39071 | N8: 23.997032 | O8: 23.997032 | P8: 4.6063219 | Q8: 4.6063219 | R8: 0.93870968 | S8: 1.255871 | T8: EIA | U8: 25.252903 | V8: 25.252903 | W8: 4.9234832 | X8: 4.9234832
A9: 7 | B9: 44409 | C9: Actual | D9: 6.3270968 | E9: 5.4585161 | F9: 0.19941935 | G9: 0.36603226 | H9: 0.0025806452 | I9: 4.4786694 | J9: 2.8028065 | K9: 19.635121 | L9: 4.4786694 | M9: 19.635121 | N9: 24.04129 | O9: 24.04129 | P9: 4.4061694 | Q9: 4.4061694 | R9: 1.0414516 | S9: 1.6877742 | T9: EIA | U9: 25.729065 | V9: 25.729065 | W9: 5.0524919 | X9: 5.0524919
A10: 8 | B10: 44440 | C10: Actual | D10: 5.2986667 | E10: 5.5180667 | F10: 0.20026667 | G10: 0.37056667 | H10: 0.0025666667 | I10: 4.103632 | J10: 2.6138 | K10: 18.107565 | L10: 4.103632 | M10: 18.107565 | N10: 24.821433 | O10: 24.821433 | P10: 6.713868 | Q10: 6.713868 | R10: 2.1608667 | S10: 0.67533333 | T10: EIA | U10: 25.496767 | V10: 25.496767 | W10: 5.2283347 | X10: 5.2283347
A11: 9 | B11: 44470 | C11: Actual | D11: 4.4126129 | E11: 5.2626774 | F11: 0.25693548 | G11: 0.38735484 | H11: 0.0025806452 | I11: 4.3906958 | J11: 2.767871 | K11: 17.480728 | L11: 4.3906958 | M11: 17.480728 | N11: 24.748484 | O11: 24.748484 | P11: 7.2677558 | Q11: 7.2677558 | R11: 2.1540323 | S11: 0.58929032 | T11: EIA | U11: 25.337774 | V11: 25.337774 | W11: 5.7030139 | X11: 5.7030139
A12: 10 | B12: 44501 | C12: Actual | D12: 3.4576 | E12: 5.6497 | F12: 0.53843333 | G12: 0.51293333 | H12: 0.0025666667 | I12: 3.903508 | J12: 2.5575667 | K12: 16.622308 | L12: 3.903508 | M12: 16.622308 | N12: 24.641967 | O12: 24.641967 | P12: 8.0196587 | Q12: 8.0196587 | R12: 1.2943667 | S12: 1.1148667 | T12: EIA | U12: 25.756833 | V12: 25.756833 | W12: 7.8401587 | X12: 7.8401587
A13: 11 | B13: 44531 | C13: Actual | D13: 3.3782903 | E13: 5.7833226 | F13: 0.58916129 | G13: 0.53209677 | H13: 0.0025806452 | I13: 4.6144974 | J13: 2.4057419 | K13: 17.305691 | L13: 4.6144974 | M13: 17.305691 | N13: 24.995 | O13: 24.995 | P13: 7.689309 | Q13: 7.689309 | R13: 1.3879677 | S13: 1.3675161 | T13: EIA | U13: 26.362516 | V13: 26.362516 | W13: 7.6688574 | X13: 7.6688574
... A97: 95 | B97: 47088 | C97: Forecast | D97: 4.5887427 | E97: 6.1278077 | F97: 0.810955 | G97: 0.60855491 | H97: 0.0048880906 | I97: 13.047025 | J97: 2.5515278 | K97: 27.739501 | L97: 11.670195 | M97: 26.362671 | N97: 36.933949 | O97: 36.933949 | P97: 9.1944486 | Q97: 10.571278 | R97: 1.3792043 | S97: 2.1587742 | T97: seasonal pattern of Aug/23-Jul/26 | U97: 39.092724 | V97: 39.092724 | W97: 9.9740185 | X97: 11.350848

Sheet Assump - Data centres
A1: Texas data-centre assumptions (yellow cells are editable; 'Data centres' recalculates in Excel, 'Demand to 2033' and the charts follow on the next run)
A2: Every input has a STATUS: SOURCED = a published figure (publisher, document, as-of, URL in the Sources block below); DERIVED = arithmetic on sourced figures; PROXY = an observed number used for something it does not strictly measure; ASSUMPTION = no source, a pure scenario input. Count: 10 of 17 sourced, 3 derived, 1 proxy, 3 assumption. Forecasts are labelled as forecasts: none of the sourced US figures is observed Texas load.
A3: layout v2 (sourced anchors, Oct 2026)
A4: Input | B4: LOW | C4: BASE | D4: HIGH | E4: Unit | F4: Status | G4: Source | H4: Note
A5: US data-centre electricity, 2024 | B5: 183 | C5: 183 | D5: 183 | E5: TWh | F5: SOURCED | G5: S1 | H5: IEA Base Case estimate (the text rounds to 'around 180'); LBNL has 176 TWh for 2023, IEA 154
A6: US data-centre electricity, 2030, IEA Base Case | B6: 426 | C6: 426 | D6: 426 | E6: TWh | F6: SOURCED | G6: S1 | H6: the IEA publishes the US only for its Base Case
A7: IEA WORLD data-centre electricity 2030 by case (LOW = Headwinds, BASE = Base, HIGH = Lift-Off) | B7: 669 | C7: 946 | D7: 1264 | E7: TWh | F7: SOURCED | G7: S2 | H7: used only as a ratio to the Base Case. High Efficiency (792) not used
A8: IEA WORLD data-centre electricity 2035 by case | B8: 707 | C8: 1193 | D8: 1719 | E8: TWh | F8: SOURCED | G8: S2 | H8: IEA calls the 2035 numbers 'exploratory scenarios'
A9: US data-centre installed capacity, 2024 | B9: 42 | C9: 42 | D9: 42 | E9: GW | F9: SOURCED | G9: S3 | H9: IEA convention: includes cooling and other overhead (PUE)
A10: US data-centre installed capacity, 2030, IEA Base Case | B10: 100 | C10: 100 | D10: 100 | E10: GW | F10: SOURCED | G10: S3
A11: Load factor (average load / installed capacity) | B11: 0.49 | C11: 0.49 | D11: 0.49 | E11: ratio | F11: SOURCED | G11: S4 | H11: IEA US value for 2030 (50% in 2024); LBNL uses 50% for its GW range
A12: ERCOT data-centre forecast, summer 2030 (TSP-reported contracts + officer letters) | B12: 22.175 | C12: 22.175 | D12: 22.175 | E12: GW | F12: SOURCED | G12: S6 | H12: a FORECAST of requested MW, not observed load; ERCOT's own scaled variants are 2.4x higher and are not used
A13: Realisation ratio applied to the ERCOT forecast | B13: 0.498 | C13: 0.749 | D13: 1 | E13: ratio | F13: ASSUMPTION | G13: S7 | H13: LOW = ERCOT's observed site peak / requested MW (S7); HIGH = the ERCOT forecast at face value; BASE = midpoint of the two: a judgement, not a measurement
A14: Texas share of the US 2024 data-centre stock | B14: 0.1 | C14: 0.1 | D14: 0.1 | E14: share | F14: ASSUMPTION | G14: S5 | H14: only the rank is published (LBNL: third after Virginia and California); the number is a guess. It does NOT affect the charts (only the burn ADDED after the last EIA actual month is stacked)
A15: Gas share of the extra load (proxy: ERCOT gas share of generation) | B15: 0.39588033 | C15: 0.39786205 | D15: 0.47757284 | E15: share | F15: PROXY | G15: S11 | H15: set by the script: LOW / HIGH = lowest / highest rolling 12-month gas share of ERCOT generation since 2019, BASE = last 12 months. An AVERAGE-mix share standing in for the marginal one; EIA-930 ERCOT, 365-day windows Jan/19-01 Oct 2026: lowest 39.6% (to Sep/26), last 39.8%, highest 47.8% (to Apr/20)
A16: Effective heat rate | B16: 8.54345 | C16: 8.54345 | D16: 8.54345 | E16: MMBtu/MWh | F16: SOURCED | G16: S12 | H16: set by the script: mean of the last 12 calibrated months (EIA-923 basis); Aug/25-Jul/26 (12 months)
A17: MMBtu per Mcf | B17: 1.015425 | C17: 1.015425 | D17: 1.015425 | E17: MMBtu/Mcf | F17: SOURCED | G17: S12 | H17: set by the script: mean of the same months (EIA-923 fuel heat content); Aug/25-Jul/26 (12 months)
A19: Derived (live formulas, not editable)
A20: US data-centre electricity, 2030, by case | B20: =B6*B7/$C$7 | C20: =C6*C7/$C$7 | D20: =D6*D7/$C$7 | E20: TWh | F20: DERIVED | G20: S1, S2, S3, S6, S7 | H20: IEA US Base x (case world / Base world): the US share of the world is held at its Base value
A21: US data-centre electricity, 2035, by case | B21: =B6*B8/$C$7 | C21: =C6*C8/$C$7 | D21: =D6*D8/$C$7 | E21: TWh | F21: DERIVED | G21: S1, S2, S3, S6, S7 | H21: IEA US Base 2030 x (case world 2035 / Base world 2030)
A22: Texas share of US data-centre GROWTH | B22: =B12*B13/(B10-B9) | C22: =C12*C13/(C10-C9) | D22: =D12*D13/(D10-D9) | E22: share | F22: DERIVED | G22: S1, S2, S3, S6, S7 | H22: ERCOT summer-2030 data-centre forecast x realisation / IEA US capacity addition 2024-30; BASE uses the ASSUMED midpoint realisation
A23: Gas burn per GW of energised load (formula) | B23: =1000*B11*B15*B16*24/B17/1000000 | C23: =1000*C11*C15*C16*24/C17/1000000 | D23: =1000*D11*D15*D16*24/D17/1000000 | E23: Bcf/d per GW | H23: =1000 MW/GW x load factor x gas share x heat rate x 24 h / (MMBtu per Mcf) / 1e6
A24: Linear interpolation of US TWh 2024->2030 and 2030->2035 (and so 2025-29, 2031-34) | F24: ASSUMPTION | H24: the IEA gives 2024, 2030 and (exploratory) 2035 only; real build-out is lumpy, so intermediate years are a convenience, not data
A25: Other inputs (not data-centre anchors, not counted)
A26: Electric-power sector underlying growth after Dec 2028 | B26: 0 | E26: per year | F26: ASSUMPTION | H26: 0 = flat: data centres are the explicit power-demand growth layer, so EIA's trend growth is not extended (avoids double counting)
A27: Production extension after 2028: growth multiplier per year | B27: 0.5 | E27: x | F27: ASSUMPTION | H27: STEO regional growth of 2027/2026 is damped by this factor each year after 2028 (0.5 = halves every year). 'Extension, not STEO'
A29: Cross-checks (published figures that are NOT anchors, set against this model)
A30: Item | B30: LOW / low end | C30: BASE | D30: HIGH / high end | E30: Unit | F30: Type | G30: Source | H30: Note
A31: US data centres 2028: LBNL range | B31: 325 | D31: 580 | E31: TWh | F31: forecast range | G31: S5 | H31: LBNL scenarios for 2028 (6.7-12.0% of US electricity); 176 TWh in 2023
A32: US data centres 2028: this model | B32: ='Data centres'!C11 | C32: ='Data centres'!H11 | D32: ='Data centres'!M11 | E32: TWh | F32: model | H32: BASE sits near the low end of LBNL's range: the IEA Base path is the more modest one; HIGH is below LBNL's 580
A33: US data centres 2030: IEA Base Case | C33: 426 | E33: TWh | F33: forecast | G33: S1
A34: US data centres 2030: this model | B34: ='Data centres'!C13 | C34: ='Data centres'!H13 | D34: ='Data centres'!M13 | E34: TWh | F34: model | H34: LOW / HIGH = IEA Headwinds / Lift-Off scaled to the US (derived)
A35: EIA AEO2026 'Data Center Servers' electricity 2025 (min / max of scenarios) | B35: 104.82886 | D35: 104.83091 | E35: TWh | F35: forecast | G35: S10 | H35: servers only, so well below IEA / LBNL totals (coverage differs): NOT used as an anchor; live from the EIA API, 11 scenarios
A36: EIA AEO2026 'Data Center Servers' electricity 2028 (min / max of scenarios) | B36: 147.28986 | D36: 153.31482 | E36: TWh | F36: forecast | G36: S10 | H36: see 2025 row
A37: EIA AEO2026 'Data Center Servers' electricity 2030 (min / max of scenarios) | B37: 176.8493 | D37: 190.7394 | E37: TWh | F37: forecast | G37: S10 | H37: see 2025 row
A38: EIA AEO2026 'Data Center Servers' electricity 2033 (min / max of scenarios) | B38: 221.95967 | D38: 254.26547 | E38: TWh | F38: forecast | G38: S10 | H38: see 2025 row
A39: ERCOT data-centre forecast, summer 2030 (requested MW) | C39: 22.175 | E39: GW | F39: forecast | G39: S6 | H39: yearly path on the 'Data centres' tab
A40: this model: Texas energised data-centre GW, Dec 2030 | B40: ='Data centres'!E13 | C40: ='Data centres'!J13 | D40: ='Data centres'!O13 | E40: GW | F40: model | H40: BASE is built from the ERCOT forecast and the IEA US capacity addition, so agreement with S6 is by construction, not independent confirmation
A41: ERCOT large-load queue, data centres (410 GW x 87%) | C41: =410*0.87 | E41: GW | F41: queue (requests) | G41: S8 | H41: requests under study, not load; ERCOT says ~410 GW of large loads seeking interconnection, ~87% data centres (26 Mar 2026)
A42: this model BASE Texas GW 2030 as a share of that queue | C42: ='Data centres'!J13/(410*0.87) | E42: share | F42: model | H42: queues are speculative; a small share is plausible
...

Sheet Data centres
A1: Texas data-centre load (year-end energised GW) and gas burn, LOW / BASE / HIGH - live formulas on 'Assump - Data centres'
A2: US TWh: IEA anchors 2024 / 2030 / 2035 (Base Case; LOW and HIGH scaled by the IEA's world Headwinds / Lift-Off ratio), linear in between. Texas TWh = US 2024 TWh x Texas stock share (ASSUMPTION) + Texas share of growth (DERIVED from ERCOT's CDR forecast) x (US TWh - US 2024 TWh); energised GW = TWh / 8.76 / load factor (IEA 49%); gas Bcf/d = GW x gas burn per GW (assumption tab).
A3: Data-centre inputs: 10 of 17 sourced, 3 derived, 1 proxy, 3 assumption. EIA's electric-power history already contains the 2024-26 data-centre burn: the charts stack only the burn ADDED after the last EIA actual month (see 'Demand to 2033'); this tab shows the total. Last column = ERCOT's own data-centre forecast (requested MW, FORECAST) for comparison.
A6: Year (year-end) | B6: Basis | C6: LOW: US TWh | D6: LOW: Texas TWh | E6: LOW: Texas energised GW | F6: LOW: gas burn Bcf/d | G6: LOW: added since Dec 2025, Bcf/d | H6: BASE: US TWh | I6: BASE: Texas TWh | J6: BASE: Texas energised GW | K6: BASE: gas burn Bcf/d | L6: BASE: added since Dec 2025, Bcf/d | M6: HIGH: US TWh | N6: HIGH: Texas TWh | O6: HIGH: Texas energised GW | P6: HIGH: gas burn Bcf/d | Q6: HIGH: added since Dec 2025, Bcf/d | R6: ERCOT CDR Dec 2025: data centres, summer peak, GW (FORECAST, S6)
A7: 2024 | B7: IEA US estimate (S1) | C7: =IF($A7<=2030,'Assump - Data centres'!$B$5+('Assump - Data centres'!$B$20-'Assump - Data centres'!$B$5)*($A7-2024)/6,'Assump - Data centres'!$B$20+('Assump - Data centres'!$B$21-'Assump - Data centres'!$B$20)*($A7-2030)/5) | D7: ='Assump - Data centres'!$B$5*'Assump - Data centres'!$B$14+'Assump - Data centres'!$B$22*(C7-'Assump - Data centres'!$B$5) | E7: =D7/8.76/'Assump - Data centres'!$B$11 | F7: =E7*'Assump - Data centres'!$B$23 | G7: =F7-F$8 | H7: =IF($A7<=2030,'Assump - Data centres'!$C$5+('Assump - Data centres'!$C$20-'Assump - Data centres'!$C$5)*($A7-2024)/6,'Assump - Data centres'!$C$20+('Assump - Data centres'!$C$21-'Assump - Data centres'!$C$20)*($A7-2030)/5) | I7: ='Assump - Data centres'!$C$5*'Assump - Data centres'!$C$14+'Assump - Data centres'!$C$22*(H7-'Assump - Data centres'!$C$5) | J7: =I7/8.76/'Assump - Data centres'!$C$11 | K7: =J7*'Assump - Data centres'!$C$23 | L7: =K7-K$8 | M7: =IF($A7<=2030,'Assump - Data centres'!$D$5+('Assump - Data centres'!$D$20-'Assump - Data centres'!$D$5)*($A7-2024)/6,'Assump - Data centres'!$D$20+('Assump - Data centres'!$D$21-'Assump - Data centres'!$D$20)*($A7-2030)/5) | N7: ='Assump - Data centres'!$D$5*'Assump - Data centres'!$D$14+'Assump - Data centres'!$D$22*(M7-'Assump - Data centres'!$D$5) | O7: =N7/8.76/'Assump - Data centres'!$D$11 | P7: =O7*'Assump - Data centres'!$D$23 | Q7: =P7-P$8
A8: 2025 | B8: interpolated 2024-30 (ASSUMPTION) | C8: =IF($A8<=2030,'Assump - Data centres'!$B$5+('Assump - Data centres'!$B$20-'Assump - Data centres'!$B$5)*($A8-2024)/6,'Assump - Data centres'!$B$20+('Assump - Data centres'!$B$21-'Assump - Data centres'!$B$20)*($A8-2030)/5) | D8: ='Assump - Data centres'!$B$5*'Assump - Data centres'!$B$14+'Assump - Data centres'!$B$22*(C8-'Assump - Data centres'!$B$5) | E8: =D8/8.76/'Assump - Data centres'!$B$11 | F8: =E8*'Assump - Data centres'!$B$23 | G8: =F8-F$8 | H8: =IF($A8<=2030,'Assump - Data centres'!$C$5+('Assump - Data centres'!$C$20-'Assump - Data centres'!$C$5)*($A8-2024)/6,'Assump - Data centres'!$C$20+('Assump - Data centres'!$C$21-'Assump - Data centres'!$C$20)*($A8-2030)/5) | I8: ='Assump - Data centres'!$C$5*'Assump - Data centres'!$C$14+'Assump - Data centres'!$C$22*(H8-'Assump - Data centres'!$C$5) | J8: =I8/8.76/'Assump - Data centres'!$C$11 | K8: =J8*'Assump - Data centres'!$C$23 | L8: =K8-K$8 | M8: =IF($A8<=2030,'Assump - Data centres'!$D$5+('Assump - Data centres'!$D$20-'Assump - Data centres'!$D$5)*($A8-2024)/6,'Assump - Data centres'!$D$20+('Assump - Data centres'!$D$21-'Assump - Data centres'!$D$20)*($A8-2030)/5) | N8: ='Assump - Data centres'!$D$5*'Assump - Data centres'!$D$14+'Assump - Data centres'!$D$22*(M8-'Assump - Data centres'!$D$5) | O8: =N8/8.76/'Assump - Data centres'!$D$11 | P8: =O8*'Assump - Data centres'!$D$23 | Q8: =P8-P$8
A9: 2026 | B9: interpolated 2024-30 (ASSUMPTION) | C9: =IF($A9<=2030,'Assump - Data centres'!$B$5+('Assump - Data centres'!$B$20-'Assump - Data centres'!$B$5)*($A9-2024)/6,'Assump - Data centres'!$B$20+('Assump - Data centres'!$B$21-'Assump - Data centres'!$B$20)*($A9-2030)/5) | D9: ='Assump - Data centres'!$B$5*'Assump - Data centres'!$B$14+'Assump - Data centres'!$B$22*(C9-'Assump - Data centres'!$B$5) | E9: =D9/8.76/'Assump - Data centres'!$B$11 | F9: =E9*'Assump - Data centres'!$B$23 | G9: =F9-F$8 | H9: =IF($A9<=2030,'Assump - Data centres'!$C$5+('Assump - Data centres'!$C$20-'Assump - Data centres'!$C$5)*($A9-2024)/6,'Assump - Data centres'!$C$20+('Assump - Data centres'!$C$21-'Assump - Data centres'!$C$20)*($A9-2030)/5) | I9: ='Assump - Data centres'!$C$5*'Assump - Data centres'!$C$14+'Assump - Data centres'!$C$22*(H9-'Assump - Data centres'!$C$5) | J9: =I9/8.76/'Assump - Data centres'!$C$11 | K9: =J9*'Assump - Data centres'!$C$23 | L9: =K9-K$8 | M9: =IF($A9<=2030,'Assump - Data centres'!$D$5+('Assump - Data centres'!$D$20-'Assump - Data centres'!$D$5)*($A9-2024)/6,'Assump - Data centres'!$D$20+('Assump - Data centres'!$D$21-'Assump - Data centres'!$D$20)*($A9-2030)/5) | N9: ='Assump - Data centres'!$D$5*'Assump - Data centres'!$D$14+'Assump - Data centres'!$D$22*(M9-'Assump - Data centres'!$D$5) | O9: =N9/8.76/'Assump - Data centres'!$D$11 | P9: =O9*'Assump - Data centres'!$D$23 | Q9: =P9-P$8 | R9: 2.433
A10: 2027 | B10: interpolated 2024-30 (ASSUMPTION) | C10: =IF($A10<=2030,'Assump - Data centres'!$B$5+('Assump - Data centres'!$B$20-'Assump - Data centres'!$B$5)*($A10-2024)/6,'Assump - Data centres'!$B$20+('Assump - Data centres'!$B$21-'Assump - Data centres'!$B$20)*($A10-2030)/5) | D10: ='Assump - Data centres'!$B$5*'Assump - Data centres'!$B$14+'Assump - Data centres'!$B$22*(C10-'Assump - Data centres'!$B$5) | E10: =D10/8.76/'Assump - Data centres'!$B$11 | F10: =E10*'Assump - Data centres'!$B$23 | G10: =F10-F$8 | H10: =IF($A10<=2030,'Assump - Data centres'!$C$5+('Assump - Data centres'!$C$20-'Assump - Data centres'!$C$5)*($A10-2024)/6,'Assump - Data centres'!$C$20+('Assump - Data centres'!$C$21-'Assump - Data centres'!$C$20)*($A10-2030)/5) | I10: ='Assump - Data centres'!$C$5*'Assump - Data centres'!$C$14+'Assump - Data centres'!$C$22*(H10-'Assump - Data centres'!$C$5) | J10: =I10/8.76/'Assump - Data centres'!$C$11 | K10: =J10*'Assump - Data centres'!$C$23 | L10: =K10-K$8 | M10: =IF($A10<=2030,'Assump - Data centres'!$D$5+('Assump - Data centres'!$D$20-'Assump - Data centres'!$D$5)*($A10-2024)/6,'Assump - Data centres'!$D$20+('Assump - Data centres'!$D$21-'Assump - Data centres'!$D$20)*($A10-2030)/5) | N10: ='Assump - Data centres'!$D$5*'Assump - Data centres'!$D$14+'Assump - Data centres'!$D$22*(M10-'Assump - Data centres'!$D$5) | O10: =N10/8.76/'Assump - Data centres'!$D$11 | P10: =O10*'Assump - Data centres'!$D$23 | Q10: =P10-P$8 | R10: 6.66
A11: 2028 | B11: interpolated 2024-30 (ASSUMPTION) | C11: =IF($A11<=2030,'Assump - Data centres'!$B$5+('Assump - Data centres'!$B$20-'Assump - Data centres'!$B$5)*($A11-2024)/6,'Assump - Data centres'!$B$20+('Assump - Data centres'!$B$21-'Assump - Data centres'!$B$20)*($A11-2030)/5) | D11: ='Assump - Data centres'!$B$5*'Assump - Data centres'!$B$14+'Assump - Data centres'!$B$22*(C11-'Assump - Data centres'!$B$5) | E11: =D11/8.76/'Assump - Data centres'!$B$11 | F11: =E11*'Assump - Data centres'!$B$23 | G11: =F11-F$8 | H11: =IF($A11<=2030,'Assump - Data centres'!$C$5+('Assump - Data centres'!$C$20-'Assump - Data centres'!$C$5)*($A11-2024)/6,'Assump - Data centres'!$C$20+('Assump - Data centres'!$C$21-'Assump - Data centres'!$C$20)*($A11-2030)/5) | I11: ='Assump - Data centres'!$C$5*'Assump - Data centres'!$C$14+'Assump - Data centres'!$C$22*(H11-'Assump - Data centres'!$C$5) | J11: =I11/8.76/'Assump - Data centres'!$C$11 | K11: =J11*'Assump - Data centres'!$C$23 | L11: =K11-K$8 | M11: =IF($A11<=2030,'Assump - Data centres'!$D$5+('Assump - Data centres'!$D$20-'Assump - Data centres'!$D$5)*($A11-2024)/6,'Assump - Data centres'!$D$20+('Assump - Data centres'!$D$21-'Assump - Data centres'!$D$20)*($A11-2030)/5) | N11: ='Assump - Data centres'!$D$5*'Assump - Data centres'!$D$14+'Assump - Data centres'!$D$22*(M11-'Assump - Data centres'!$D$5) | O11: =N11/8.76/'Assump - Data centres'!$D$11 | P11: =O11*'Assump - Data centres'!$D$23 | Q11: =P11-P$8 | R11: 13.903
A12: 2029 | B12: interpolated 2024-30 (ASSUMPTION) | C12: =IF($A12<=2030,'Assump - Data centres'!$B$5+('Assump - Data centres'!$B$20-'Assump - Data centres'!$B$5)*($A12-2024)/6,'Assump - Data centres'!$B$20+('Assump - Data centres'!$B$21-'Assump - Data centres'!$B$20)*($A12-2030)/5) | D12: ='Assump - Data centres'!$B$5*'Assump - Data centres'!$B$14+'Assump - Data centres'!$B$22*(C12-'Assump - Data centres'!$B$5) | E12: =D12/8.76/'Assump - Data centres'!$B$11 | F12: =E12*'Assump - Data centres'!$B$23 | G12: =F12-F$8 | H12: =IF($A12<=2030,'Assump - Data centres'!$C$5+('Assump - Data centres'!$C$20-'Assump - Data centres'!$C$5)*($A12-2024)/6,'Assump - Data centres'!$C$20+('Assump - Data centres'!$C$21-'Assump - Data centres'!$C$20)*($A12-2030)/5) | I12: ='Assump - Data centres'!$C$5*'Assump - Data centres'!$C$14+'Assump - Data centres'!$C$22*(H12-'Assump - Data centres'!$C$5) | J12: =I12/8.76/'Assump - Data centres'!$C$11 | K12: =J12*'Assump - Data centres'!$C$23 | L12: =K12-K$8 | M12: =IF($A12<=2030,'Assump - Data centres'!$D$5+('Assump - Data centres'!$D$20-'Assump - Data centres'!$D$5)*($A12-2024)/6,'Assump - Data centres'!$D$20+('Assump - Data centres'!$D$21-'Assump - Data centres'!$D$20)*($A12-2030)/5) | N12: ='Assump - Data centres'!$D$5*'Assump - Data centres'!$D$14+'Assump - Data centres'!$D$22*(M12-'Assump - Data centres'!$D$5) | O12: =N12/8.76/'Assump - Data centres'!$D$11 | P12: =O12*'Assump - Data centres'!$D$23 | Q12: =P12-P$8 | R12: 17.995
A13: 2030 | B13: IEA anchor 2030 (S1, S2) | C13: =IF($A13<=2030,'Assump - Data centres'!$B$5+('Assump - Data centres'!$B$20-'Assump - Data centres'!$B$5)*($A13-2024)/6,'Assump - Data centres'!$B$20+('Assump - Data centres'!$B$21-'Assump - Data centres'!$B$20)*($A13-2030)/5) | D13: ='Assump - Data centres'!$B$5*'Assump - Data centres'!$B$14+'Assump - Data centres'!$B$22*(C13-'Assump - Data centres'!$B$5) | E13: =D13/8.76/'Assump - Data centres'!$B$11 | F13: =E13*'Assump - Data centres'!$B$23 | G13: =F13-F$8 | H13: =IF($A13<=2030,'Assump - Data centres'!$C$5+('Assump - Data centres'!$C$20-'Assump - Data centres'!$C$5)*($A13-2024)/6,'Assump - Data centres'!$C$20+('Assump - Data centres'!$C$21-'Assump - Data centres'!$C$20)*($A13-2030)/5) | I13: ='Assump - Data centres'!$C$5*'Assump - Data centres'!$C$14+'Assump - Data centres'!$C$22*(H13-'Assump - Data centres'!$C$5) | J13: =I13/8.76/'Assump - Data centres'!$C$11 | K13: =J13*'Assump - Data centres'!$C$23 | L13: =K13-K$8 | M13: =IF($A13<=2030,'Assump - Data centres'!$D$5+('Assump - Data centres'!$D$20-'Assump - Data centres'!$D$5)*($A13-2024)/6,'Assump - Data centres'!$D$20+('Assump - Data centres'!$D$21-'Assump - Data centres'!$D$20)*($A13-2030)/5) | N13: ='Assump - Data centres'!$D$5*'Assump - Data centres'!$D$14+'Assump - Data centres'!$D$22*(M13-'Assump - Data centres'!$D$5) | O13: =N13/8.76/'Assump - Data centres'!$D$11 | P13: =O13*'Assump - Data centres'!$D$23 | Q13: =P13-P$8 | R13: 22.175
A14: 2031 | B14: interpolated 2030-35 (ASSUMPTION) | C14: =IF($A14<=2030,'Assump - Data centres'!$B$5+('Assump - Data centres'!$B$20-'Assump - Data centres'!$B$5)*($A14-2024)/6,'Assump - Data centres'!$B$20+('Assump - Data centres'!$B$21-'Assump - Data centres'!$B$20)*($A14-2030)/5) | D14: ='Assump - Data centres'!$B$5*'Assump - Data centres'!$B$14+'Assump - Data centres'!$B$22*(C14-'Assump - Data centres'!$B$5) | E14: =D14/8.76/'Assump - Data centres'!$B$11 | F14: =E14*'Assump - Data centres'!$B$23 | G14: =F14-F$8 | H14: =IF($A14<=2030,'Assump - Data centres'!$C$5+('Assump - Data centres'!$C$20-'Assump - Data centres'!$C$5)*($A14-2024)/6,'Assump - Data centres'!$C$20+('Assump - Data centres'!$C$21-'Assump - Data centres'!$C$20)*($A14-2030)/5) | I14: ='Assump - Data centres'!$C$5*'Assump - Data centres'!$C$14+'Assump - Data centres'!$C$22*(H14-'Assump - Data centres'!$C$5) | J14: =I14/8.76/'Assump - Data centres'!$C$11 | K14: =J14*'Assump - Data centres'!$C$23 | L14: =K14-K$8 | M14: =IF($A14<=2030,'Assump - Data centres'!$D$5+('Assump - Data centres'!$D$20-'Assump - Data centres'!$D$5)*($A14-2024)/6,'Assump - Data centres'!$D$20+('Assump - Data centres'!$D$21-'Assump - Data centres'!$D$20)*($A14-2030)/5) | N14: ='Assump - Data centres'!$D$5*'Assump - Data centres'!$D$14+'Assump - Data centres'!$D$22*(M14-'Assump - Data centres'!$D$5) | O14: =N14/8.76/'Assump - Data centres'!$D$11 | P14: =O14*'Assump - Data centres'!$D$23 | Q14: =P14-P$8
A15: 2032 | B15: interpolated 2030-35 (ASSUMPTION) | C15: =IF($A15<=2030,'Assump - Data centres'!$B$5+('Assump - Data centres'!$B$20-'Assump - Data centres'!$B$5)*($A15-2024)/6,'Assump - Data centres'!$B$20+('Assump - Data centres'!$B$21-'Assump - Data centres'!$B$20)*($A15-2030)/5) | D15: ='Assump - Data centres'!$B$5*'Assump - Data centres'!$B$14+'Assump - Data centres'!$B$22*(C15-'Assump - Data centres'!$B$5) | E15: =D15/8.76/'Assump - Data centres'!$B$11 | F15: =E15*'Assump - Data centres'!$B$23 | G15: =F15-F$8 | H15: =IF($A15<=2030,'Assump - Data centres'!$C$5+('Assump - Data centres'!$C$20-'Assump - Data centres'!$C$5)*($A15-2024)/6,'Assump - Data centres'!$C$20+('Assump - Data centres'!$C$21-'Assump - Data centres'!$C$20)*($A15-2030)/5) | I15: ='Assump - Data centres'!$C$5*'Assump - Data centres'!$C$14+'Assump - Data centres'!$C$22*(H15-'Assump - Data centres'!$C$5) | J15: =I15/8.76/'Assump - Data centres'!$C$11 | K15: =J15*'Assump - Data centres'!$C$23 | L15: =K15-K$8 | M15: =IF($A15<=2030,'Assump - Data centres'!$D$5+('Assump - Data centres'!$D$20-'Assump - Data centres'!$D$5)*($A15-2024)/6,'Assump - Data centres'!$D$20+('Assump - Data centres'!$D$21-'Assump - Data centres'!$D$20)*($A15-2030)/5) | N15: ='Assump - Data centres'!$D$5*'Assump - Data centres'!$D$14+'Assump - Data centres'!$D$22*(M15-'Assump - Data centres'!$D$5) | O15: =N15/8.76/'Assump - Data centres'!$D$11 | P15: =O15*'Assump - Data centres'!$D$23 | Q15: =P15-P$8
